Workbook

Sheet ต.ค.68
A1: รายงานการรับชำระค่าธรรมเนียมผ่านธนาคาร เดือน ตุลาคม 2568
A3: วันที่ชำระ | B3: ข้อมูลกฎหมาย | C3: ระบบ Safety | G3: ระบบ Receipt (ใบเสร็จรับเงิน A4) | M3: รวมพรบ.42 (Safety + Receipt) | O3: ระบบ Trade | U3: รวมพรบ.2543 (Trade) | W3: นำรายได้ ส่ง คพ. พรบ.42 + พรบ.43 | Y3: หมายเหตุ | Z3: พน0401.1/ | AA3: วันที่ส่ง
B4: กฎหมาย | C4: จำนวนใบเสร็จ | D4: จำนวนเงิน | E4: ยกเลิกใบเสร็จ | G4: จาก | H4: ถึง | I4: จำนวนใบเสร็จ | J4: จำนวนเงิน | K4: ยกเลิก/ใบเสร็จเสีย | M4: รวมจำนวนใบเสร็จ | N4: รวมจำนวนเงิน | O4: จาก | P4: ถึง | Q4: จำนวนใบเสร็จ | R4: จำนวนเงิน | S4: ยกเลิกใบเสร็จ | U4: รวมจำนวนใบเสร็จ | V4: รวมจำนวนเงิน | W4: รวมจำนวนใบเสร็จ | X4: รวมจำนวนเงิน
E5: จำนวนใบเสร็จ | F5: เลขที่ใบเสร็จ | K5: จำนวนใบเสร็จ | L5: เลขที่ใบเสร็จ | S5: จำนวนใบเสร็จ | T5: เลขที่ใบเสร็จ
A6: 1-2 ต.ค. 68 | C6: 7 | D6: =450+5770 -> 6220 | G6: ธ2569/00016 | H6: ธ2569/00030 | I6: =9+6 -> 15 | J6: =3400+3800 -> 7200 | M6: =SUM(C6,I6) -> 22 | N6: =SUM(D6,J6) -> 13420 | O6: ธ69/00014 | P6: ธ69/00036 | Q6: 23 | R6: 48338.11 | U6: =#REF! -> #REF! | V6: =R6 -> 48338.11 | W6: =SUM(M6,Q6) -> 45 | X6: =SUM(N6,R6) -> 61758.11 | Z6: 1706 | AA6: 3 ต.ค.68
A7: 3-5 ต.ค. 68 | C7: 3 | D7: 41300 | G7: ธ2569/00031 | H7: ธ2569/00037 | I7: 7 | J7: 3100 | M7: =SUM(C7,I7) -> 10 | N7: =SUM(D7,J7) -> 44400 | O7: ธ69/00037 | P7: ธ69/00051 | Q7: 15 | R7: 19621.58 | U7: =#REF! -> #REF! | V7: =R7 -> 19621.58 | W7: =SUM(M7,Q7) -> 25 | X7: =SUM(N7,R7) -> 64021.58 | Z7: 1712 | AA7: 6 ต.ค. 68
A8: 6 ต.ค. 68 | C8: 2 | D8: 700 | G8: ธ2569/00038 | H8: ธ2569/00054 | I8: 17 | J8: 3400 | M8: =SUM(C8,I8) -> 19 | N8: =SUM(D8,J8) -> 4100 | O8: ธ69/00052 | P8: ธ69/00068 | Q8: 17 | R8: 34402.86 | U8: =#REF! -> #REF! | V8: =R8 -> 34402.86 | W8: =SUM(M8,Q8) -> 36 | X8: =SUM(N8,R8) -> 38502.86 | Z8: 1718 | AA8: 7 ต.ค. 68
A9: 7 ต.ค. 68 | C9: - | D9: - | G9: ธ2569/00055 | H9: ธ2569/00056 | I9: 2 | J9: 400 | M9: =SUM(C9,I9) -> 2 | N9: =SUM(D9,J9) -> 400 | O9: ธ69/00069 | P9: ธ69/00071 | Q9: 3 | R9: =112200+1216.77 -> 113416.77 | U9: =#REF! -> #REF! | V9: =R9 -> 113416.77 | W9: =SUM(M9,Q9) -> 5 | X9: =SUM(N9,R9) -> 113816.77 | Z9: 1724 | AA9: 8 ต.ค. 68
A10: 8 ต.ค. 68 | C10: 1 | D10: 3200 | G10: ธ2569/00057 | H10: ธ2569/00060 | I10: 4 | J10: 800 | M10: =SUM(C10,I10) -> 5 | N10: =SUM(D10,J10) -> 4000 | O10: ธ69/00072 | P10: ธ69/00084 | Q10: 13 | R10: =8500+11923.21 -> 20423.21 | U10: =#REF! -> #REF! | V10: =R10 -> 20423.21 | W10: =SUM(M10,Q10) -> 18 | X10: =SUM(N10,R10) -> 24423.21 | Z10: 1730 | AA10: 9 ต.ค. 68
A11: 9 ต.ค. 68 | C11: 7 | D11: 3150 | G11: ธ2569/00061 | H11: ธ2569/00064 | I11: 4 | J11: 2800 | M11: =SUM(C11,I11) -> 11 | N11: =SUM(D11,J11) -> 5950 | O11: ธ69/00085 | P11: ธ69/00101 | Q11: =8+9 -> 17 | R11: =19000+14208.39 -> 33208.39 | U11: =#REF! -> #REF! | V11: =R11 -> 33208.39 | W11: =SUM(M11,Q11) -> 28 | X11: =SUM(N11,R11) -> 39158.39 | Z11: 1737 | AA11: 10 ต.ค. 68
A12: 10-13 ต.ค. 68 | C12: 1 | D12: 800 | G12: ธ2569/00065 | H12: ธ2569/00071 | I12: 7 | J12: =4200+500 -> 4700 | M12: =SUM(C12,I12) -> 8 | N12: =SUM(D12,J12) -> 5500 | O12: ธ69/00102 | P12: ธ69/00115 | Q12: 14 | R12: 21737.15 | U12: =#REF! -> #REF! | V12: =R12 -> 21737.15 | W12: =SUM(M12,Q12) -> 22 | X12: =SUM(N12,R12) -> 27237.15 | Z12: 1743 | AA12: 14 ต.ค. 68
A13: 14 ต.ค. 68 | C13: - | D13: - | G13: ธ2569/00072 | H13: ธ2569/00073 | I13: 2 | J13: 1200 | M13: =SUM(C13,I13) -> 2 | N13: =SUM(D13,J13) -> 1200 | O13: ธ69/00116 | P13: ธ69/00124 | Q13: =6+3 -> 9 | R13: =12600+4030.65 -> 16630.65 | U13: =#REF! -> #REF! | V13: =R13 -> 16630.65 | W13: =SUM(M13,Q13) -> 11 | X13: =SUM(N13,R13) -> 17830.65 | Z13: 1751 | AA13: 15 ต.ค. 68
A14: 15 ต.ค. 68 | C14: 2 | D14: 4700 | G14: ธ2569/00074 | H14: - | I14: 1 | J14: 500 | M14: =SUM(C14,I14) -> 3 | N14: =SUM(D14,J14) -> 5200 | O14: ธ69/00125 | P14: ธ69/00131 | Q14: 7 | R14: =8600+2449.04 -> 11049.04 | U14: =#REF! -> #REF! | V14: =R14 -> 11049.04 | W14: =SUM(M14,Q14) -> 10 | X14: =SUM(N14,R14) -> 16249.04 | Z14: 1758 | AA14: 16 ต.ค. 68
A15: 16 ต.ค. 68 | C15: - | D15: - | G15: ธ2569/00075 | H15: ธ2569/00080 | I15: 6 | J15: 3800 | M15: =SUM(C15,I15) -> 6 | N15: =SUM(D15,J15) -> 3800 | O15: ธ69/00132 | P15: ธ69/00140 | Q15: =5+4 -> 9 | R15: =10500+5981.92 -> 16481.92 | U15: =#REF! -> #REF! | V15: =R15 -> 16481.92 | W15: =SUM(M15,Q15) -> 15 | X15: =SUM(N15,R15) -> 20281.92 | Z15: 1765 | AA15: 17 ต.ค. 68
A16: 17-19 ต.ค. 68 | C16: 2 | D16: 2000 | G16: ธ2569/00081 | H16: ธ2569/00084 | I16: 4 | J16: =1100+200 -> 1300 | M16: =SUM(C16,I16) -> 6 | N16: =SUM(D16,J16) -> 3300 | O16: ธ69/00141 | P16: ธ69/00148 | Q16: 8 | R16: 18222.71 | U16: =#REF! -> #REF! | V16: =R16 -> 18222.71 | W16: =SUM(M16,Q16) -> 14 | X16: =SUM(N16,R16) -> 21522.71 | Z16: 1771 | AA16: 20 ต.ค. 68
A17: 20 ต.ค. 68 | C17: 1 | D17: 3200 | G17: ธ2569/00085 | H17: ธ2569/00088 | I17: 4 | J17: 2320 | M17: =SUM(C17,I17) -> 5 | N17: =SUM(D17,J17) -> 5520 | O17: ธ69/00149. | P17: ธ69/00161 | Q17: 13 | R17: =9400+13154.06 -> 22554.06 | U17: =#REF! -> #REF! | V17: =R17 -> 22554.06 | W17: =SUM(M17,Q17) -> 18 | X17: =SUM(N17,R17) -> 28074.06 | Z17: 1777 | AA17: 21 ต.ค. 68
A18: 21 ต.ค. 68 | C18: - | D18: - | G18: ธ2569/00089 | H18: ธ2569/00096 | I18: 8 | J18: 4600 | M18: =SUM(C18,I18) -> 8 | N18: =SUM(D18,J18) -> 4600 | O18: ธ69/00162 | P18: ธ69/00183 | Q18: 22 | R18: 42161.53 | U18: =#REF! -> #REF! | V18: =R18 -> 42161.53 | W18: =SUM(M18,Q18) -> 30 | X18: =SUM(N18,R18) -> 46761.53 | Z18: 1782 | AA18: 22 ต.ค. 68
A19: 22-23 ต.ค. 68 | C19: - | D19: - | G19: ธ2569/00098 | H19: ธ2569/00104 | I19: 7 | J19: 4420 | M19: =SUM(C19,I19) -> 7 | N19: =SUM(D19,J19) -> 4420 | O19: ธ69/00184 | P19: ธ69/00202 | Q19: 19 | R19: 41399.2 | U19: =#REF! -> #REF! | V19: =R19 -> 41399.2 | W19: =SUM(M19,Q19) -> 26 | X19: =SUM(N19,R19) -> 45819.2 | Y19: ธ2569/00097 ไม่พบในระบบเนื่องจากระบบขัดข้อง | Z19: 1791 | AA19: 24 ต.ค. 68
A20: 24-26ต.ค. 68 | C20: 1 | D20: 450 | G20: ธ2569/00104 | H20: ธ2569/00109 | I20: 5 | J20: =800+500 -> 1300 | M20: =SUM(C20,I20) -> 6 | N20: =SUM(D20,J20) -> 1750 | O20: ธ69/00203 | P20: ธ69/00210 | Q20: =5+2+1 -> 8 | R20: =7900+2466.46+6170.97 -> 16537.43 | U20: =#REF! -> #REF! | V20: =R20 -> 16537.43 | W20: =SUM(M20,Q20) -> 14 | X20: =SUM(N20,R20) -> 18287.43 | Z20: 1798 | AA20: 27 ต.ค. 68
A21: 27 ต.ค. 68 | C21: 3 | D21: 2780 | G21: ธ2569/00110 | H21: ธ2569/00113 | I21: 4 | J21: 800 | M21: =SUM(C21,I21) -> 7 | N21: =SUM(D21,J21) -> 3580 | O21: ธ69/00211 | P21: ธ69/00219 | Q21: 9 | R21: 18551.49 | U21: =#REF! -> #REF! | V21: =R21 -> 18551.49 | W21: =SUM(M21,Q21) -> 16 | X21: =SUM(N21,R21) -> 22131.49 | Z21: 1806 | AA21: 28 ต.ค. 68
A22: 28 ต.ค. 68 | C22: 2 | D22: 700 | G22: ธ2569/00114 | H22: ธ2569/00117 | I22: 4 | J22: 3800 | M22: =SUM(C22,I22) -> 6 | N22: =SUM(D22,J22) -> 4500 | O22: ธ69/00220 | P22: ธ69/00231 | Q22: 12 | R22: 23705.5 | U22: =#REF! -> #REF! | V22: =R22 -> 23705.5 | W22: =SUM(M22,Q22) -> 18 | X22: =SUM(N22,R22) -> 28205.5 | Z22: 1812 | AA22: 29 ต.ค. 68
A23: 29 ต.ค. 68 | C23: 1 | D23: 1000 | G23: ธ2569/00118 | H23: ธ2569/00119 | I23: 2 | J23: 700 | M23: =SUM(C23,I23) -> 3 | N23: =SUM(D23,J23) -> 1700 | O23: ธ69/00232 | P23: ธ69/00237 | Q23: 6 | R23: 12974.18 | U23: =#REF! -> #REF! | V23: =R23 -> 12974.18 | W23: =SUM(M23,Q23) -> 9 | X23: =SUM(N23,R23) -> 14674.18 | Z23: 1819 | AA23: 30 ต.ค. 68
A24: 30 ต.ค. 68 | C24: 1 | D24: 200 | G24: ธ2569/00120 | H24: ธ2569/00126 | I24: 7 | J24: 1950 | M24: =SUM(C24,I24) -> 8 | N24: =SUM(D24,J24) -> 2150 | O24: ธ69/00238 | P24: ธ69/00245 | Q24: 8 | R24: 17288.35 | U24: =#REF! -> #REF! | V24: =R24 -> 17288.35 | W24: =SUM(M24,Q24) -> 16 | X24: =SUM(N24,R24) -> 19438.35 | Z24: 1822 | AA24: 31 ต.ค. 68
M25: =SUM(C25,I25) -> 0 | N25: =SUM(D25,J25) -> 0 | U25: =#REF! -> #REF! | V25: =R25 -> 0 | W25: =SUM(M25,Q25) -> 0 | X25: =SUM(N25,R25) -> 0
M26: =SUM(C26,I26) -> 0 | N26: =SUM(D26,J26) -> 0 | W26: =SUM(M26,Q26) -> 0 | X26: =SUM(N26,R26) -> 0
M27: =SUM(C27,I27) -> 0 | N27: =SUM(D27,J27) -> 0 | W27: =SUM(M27,Q27) -> 0 | X27: =SUM(N27,R27) -> 0
M28: =SUM(C28,I28) -> 0 | N28: =SUM(D28,J28) -> 0 | W28: =SUM(M28,Q28) -> 0 | X28: =SUM(N28,R28) -> 0
M29: =SUM(C29,I29) -> 0 | N29: =SUM(D29,J29) -> 0 | W29: =SUM(M29,Q29) -> 0 | X29: =SUM(N29,R29) -> 0
M30: =SUM(C30,I30) -> 0 | N30: =SUM(D30,J30) -> 0 | W30: =SUM(M30,Q30) -> 0 | X30: =SUM(N30,R30) -> 0
M31: =SUM(C31,I31) -> 0 | N31: =SUM(D31,J31) -> 0 | W31: =SUM(M31,Q31) -> 0 | X31: =SUM(N31,R31) -> 0
M32: =SUM(C32,I32) -> 0 | N32: =SUM(D32,J32) -> 0 | W32: =SUM(M32,Q32) -> 0 | X32: =SUM(N32,R32) -> 0
M33: =SUM(C33,I33) -> 0 | N33: =SUM(D33,J33) -> 0 | W33: =SUM(M33,Q33) -> 0 | X33: =SUM(N33,R33) -> 0
M34: =SUM(C34,I34) -> 0 | N34: =SUM(D34,J34) -> 0 | W34: =SUM(M34,Q34) -> 0 | X34: =SUM(N34,R34) -> 0
A35: รวม | C35: =SUM(C6:C25) -> 34 | D35: =SUM(D6:D25) -> 70400 | E35: =SUM(E6:E25) -> 0 | F35: =SUM(F6:F25) -> 0 | G35: รวม | I35: =SUM(I6:I25) -> 110 | J35: =SUM(J6:J25) -> 49090 | K35: =SUM(K6:K25) -> 0 | L35: =SUM(L6:L25) -> 0 | M35: =SUM(M6:M25) -> 144 | N35: =SUM(N6:N25) -> 119490 | O35: รวม | Q35: =SUM(Q6:Q25) -> 232 | R35: =SUM(R6:R25) -> 548704.13 | S35: =SUM(S6:S25) -> 0 | T35: =SUM(T6:T25) -> 0 | U35: =SUM(U6:U25) -> #REF! | V35: =SUM(V6:V25) -> 548704.13 | W35: =SUM(W6:W25) -> 376 | X35: =SUM(X6:X25) -> 668194.13

Sheet พ.ย.68
A1: รายงานการรับชำระค่าธรรมเนียมผ่านธนาคาร เดือน พฤศจิกายน 2568
A3: วันที่ชำระ | B3: ข้อมูลกฎหมาย | C3: ระบบ Safety | G3: ระบบ Receipt (ใบเสร็จรับเงิน A4) | M3: รวมพรบ.42 (Safety + Receipt) | O3: ระบบ Trade | U3: รวมพรบ.2543 (Trade) | W3: นำรายได้ ส่ง คพ. พรบ.42 + พรบ.43 | Y3: หมายเหตุ | Z3: พน0401.1/ | AA3: วันที่ส่ง
B4: กฎหมาย | C4: จำนวนใบเสร็จ | D4: จำนวนเงิน | E4: ยกเลิกใบเสร็จ | G4: จาก | H4: ถึง | I4: จำนวนใบเสร็จ | J4: จำนวนเงิน | K4: ยกเลิก/ใบเสร็จเสีย | M4: รวมจำนวนใบเสร็จ | N4: รวมจำนวนเงิน | O4: จาก | P4: ถึง | Q4: จำนวนใบเสร็จ | R4: จำนวนเงิน | S4: ยกเลิกใบเสร็จ | U4: รวมจำนวนใบเสร็จ | V4: รวมจำนวนเงิน | W4: รวมจำนวนใบเสร็จ | X4: รวมจำนวนเงิน
E5: จำนวนใบเสร็จ | F5: เลขที่ใบเสร็จ | K5: จำนวนใบเสร็จ | L5: เลขที่ใบเสร็จ | S5: จำนวนใบเสร็จ | T5: เลขที่ใบเสร็จ
A6: 31 ต.ค.-2 พ.ย.. 68 | C6: 1 | D6: 200 | G6: ธ2569/00127 | H6: ธ2569/00136 | I6: 10 | J6: =2700+500 -> 3200 | M6: =SUM(C6,I6) -> 11 | N6: =SUM(D6,J6) -> 3400 | O6: ธ69/00246 | P6: ธ69/00267 | Q6: =11+7+1+2+1 -> 22 | R6: =22100+9164+4000+2854.3+2100 -> 40218.3 | U6: =#REF! -> #REF! | V6: =R6 -> 40218.3 | W6: =SUM(M6,Q6) -> 33 | X6: =SUM(N6,R6) -> 43618.3 | Z6: 1835 | AA6: 3 พ.ย.68
A7: 3 พ.ย. 68 | C7: 284 | D7: =226150-400 -> 225750 | G7: ธ2569/00137 | H7: - | I7: 1 | J7: 200 | M7: =SUM(C7,I7) -> 285 | N7: =SUM(D7,J7) -> 225950 | O7: ธ69/00268 | P7: ธ69/00278 | Q7: 11 | R7: 25657.1 | U7: =#REF! -> #REF! | V7: =R7 -> 25657.1 | W7: =SUM(M7,Q7) -> 296 | X7: =SUM(N7,R7) -> 251607.1 | Z7: 1844 | AA7: 4 พ.ย.68
A8: 4 พ.ย. 68 | C8: 456 | D8: 331280 | G8: ธ2569/00138 | H8: ธ2569/00145 | I8: 8 | J8: 2150 | M8: =SUM(C8,I8) -> 464 | N8: =SUM(D8,J8) -> 333430 | O8: ธ69/00279 | P8: ธ69/00287 | Q8: =7+2 -> 9 | R8: =16852.4+8100 -> 24952.4 | U8: =#REF! -> #REF! | V8: =R8 -> 24952.4 | W8: =SUM(M8,Q8) -> 473 | X8: =SUM(N8,R8) -> 358382.4 | Z8: 1852 | AA8: 5 พ.ย.68
A9: 5 พ.ย. 68 | C9: 249 | D9: 199500 | G9: - | H9: - | I9: - | J9: - | M9: =SUM(C9,I9) -> 249 | N9: =SUM(D9,J9) -> 199500 | O9: ธ69/00287 | P9: ธ69/00299 | Q9: 12 | R9: 22735 | U9: =#REF! -> #REF! | V9: =R9 -> 22735 | W9: =SUM(M9,Q9) -> 261 | X9: =SUM(N9,R9) -> 222235 | Z9: 1858 | AA9: 6 พ.ย.68
A10: 6 พ.ย. 68 | C10: 494 | D10: 353560 | G10: ธ2569/00146 | H10: ธ2569/00147 | I10: 2 | J10: 400 | M10: =SUM(C10,I10) -> 496 | N10: =SUM(D10,J10) -> 353960 | O10: ธ69/00300 | P10: ธ69/00313 | Q10: 14 | R10: 25175.6 | U10: =#REF! -> #REF! | V10: =R10 -> 25175.6 | W10: =SUM(M10,Q10) -> 510 | X10: =SUM(N10,R10) -> 379135.6 | Z10: 1866 | AA10: 7 พ.ย.68
A11: 7 - 9 พ.ย. 68 | C11: 819 | D11: 566250 | G11: ธ2569/00148 | H11: ธ2569/00154 | I11: 7 | J11: 11400 | M11: =SUM(C11,I11) -> 826 | N11: =SUM(D11,J11) -> 577650 | O11: ธ69/00314 | P11: ธ69/00330 | Q11: 17 | R11: 29788 | U11: =#REF! -> #REF! | V11: =R11 -> 29788 | W11: =SUM(M11,Q11) -> 843 | X11: =SUM(N11,R11) -> 607438 | Z11: 1873 | AA11: 10 พ.ย.68
A12: 10 พ.ย. 68 | C12: 429 | D12: 387851 | G12: ธ2569/00155 | H12: ธ2569/00156 | I12: 2 | J12: 400 | M12: =SUM(C12,I12) -> 431 | N12: =SUM(D12,J12) -> 388251 | O12: ธ69/00331 | P12: ธ69/00341 | Q12: 11 | R12: 21500 | U12: =#REF! -> #REF! | V12: =R12 -> 21500 | W12: =SUM(M12,Q12) -> 442 | X12: =SUM(N12,R12) -> 409751 | Z12: 1890 | AA12: 11 พ.ย.68
A13: 11 พ.ย. 68 | C13: 370 | D13: 298390 | G13: - | H13: - | I13: - | J13: - | M13: =SUM(C13,I13) -> 370 | N13: =SUM(D13,J13) -> 298390 | O13: ธ69/00342 | P13: ธ69/00349 | Q13: 8 | R13: 18902 | U13: =#REF! -> #REF! | V13: =R13 -> 18902 | W13: =SUM(M13,Q13) -> 378 | X13: =SUM(N13,R13) -> 317292 | Z13: 1888 | AA13: 12 พ.ย.68
A14: 12 พ.ย. 68 | C14: 388 | D14: 401410 | G14: ธ2569/00157 | H14: ธ2569/00164 | I14: 8 | J14: 1600 | M14: =SUM(C14,I14) -> 396 | N14: =SUM(D14,J14) -> 403010 | O14: ธ69/00350 | P14: ธ69/00359 | Q14: 10 | R14: 16485.2 | U14: =#REF! -> #REF! | V14: =R14 -> 16485.2 | W14: =SUM(M14,Q14) -> 406 | X14: =SUM(N14,R14) -> 419495.2 | Z14: 1895 | AA14: 13 พ.ย.68
A15: 13 พ.ย. 68 | C15: 799 | D15: 671150 | G15: ธ2569/00165 | H15: ธ2569/00168 | I15: 4 | J15: 4640 | M15: =SUM(C15,I15) -> 803 | N15: =SUM(D15,J15) -> 675790 | O15: ธ69/00360 | P15: ธ69/00368 | Q15: 9 | R15: 16712 | U15: =#REF! -> #REF! | V15: =R15 -> 16712 | W15: =SUM(M15,Q15) -> 812 | X15: =SUM(N15,R15) -> 692502 | Z15: 1903 | AA15: 14 พ.ย.68
A16: 14 - 16 พ.ย. 68 | C16: 908 | D16: 615490 | G16: ธ2569/00169 | H16: ธ2569/00172 | I16: 4 | J16: 1600 | M16: =SUM(C16,I16) -> 912 | N16: =SUM(D16,J16) -> 617090 | O16: ธ69/00369 | P16: ธ69/00389 | Q16: 21 | R16: 38354.2 | U16: =#REF! -> #REF! | V16: =R16 -> 38354.2 | W16: =SUM(M16,Q16) -> 933 | X16: =SUM(N16,R16) -> 655444.2 | Z16: 1919 | AA16: 19 พ.ย.68
A17: 17 - 18 พ.ย. 68 | C17: =433+420 -> 853 | D17: =393370+429970 -> 823340 | G17: ธ2569/00173 | H17: ธ2569/00179 | I17: =1+6 -> 7 | J17: =4200+1720+400+200+200+500+500 -> 7720 | M17: =SUM(C17,I17) -> 860 | N17: =SUM(D17,J17) -> 831060 | O17: ธ69/00390 | P17: ธ69/00418 | Q17: =9+20 -> 29 | R17: =19357+49697 -> 69054 | U17: =#REF! -> #REF! | V17: =R17 -> 69054 | W17: =SUM(M17,Q17) -> 889 | X17: =SUM(N17,R17) -> 900114 | Z17: 1923 | AA17: 19 พ.ย.68
A18: 19 - 20 พ.ย. 68 | C18: =394+698 -> 1092 | D18: 936740 | G18: ธ2569/00180 | H18: ธ2569/00199 | I18: =15+5 -> 20 | J18: =200+1000+200+200+200+200+200+200+200+200+200+200+200+200+200+200+200+500+500+200 -> 5400 | M18: =SUM(C18,I18) -> 1112 | N18: =SUM(D18,J18) -> 942140 | O18: ธ69/00419 | P18: ธ69/00438 | Q18: =9+11 -> 20 | R18: =20054.1+23860 -> 43914.1 | U18: =#REF! -> #REF! | V18: =R18 -> 43914.1 | W18: =SUM(M18,Q18) -> 1132 | X18: =SUM(N18,R18) -> 986054.1 | Y18: Safety -4 ราย 4,250 บาท | Z18: 1936 | AA18: 21 พ.ย.68
A19: 21 - 23 พ.ย. 68 | C19: 491 | D19: 700480 | G19: ธ2569/00200 | H19: ธ2569/00202 | I19: 3 | J19: =200+200+2600 -> 3000 | M19: =SUM(C19,I19) -> 494 | N19: =SUM(D19,J19) -> 703480 | O19: ธ69/00439 | P19: ธ69/00454 | Q19: 16 | R19: 35193 | U19: =#REF! -> #REF! | V19: =R19 -> 35193 | W19: =SUM(M19,Q19) -> 510 | X19: =SUM(N19,R19) -> 738673 | Z19: 1945 | AA19: 24 พ.ย.68
A20: 24 พ.ย. 68 | C20: 591 | D20: 457850 | G20: ธ2569/00203 | H20: ธ2569/00206 | I20: 4 | J20: =500+200+200+1220 -> 2120 | M20: =SUM(C20,I20) -> 595 | N20: =SUM(D20,J20) -> 459970 | O20: ธ69/00455 | P20: ธ69/00470 | Q20: 16 | R20: 32368 | U20: =#REF! -> #REF! | V20: =R20 -> 32368 | W20: =SUM(M20,Q20) -> 611 | X20: =SUM(N20,R20) -> 492338 | Z20: 1953 | AA20: 25 พ.ย.68
A21: 25 พ.ย. 68 | C21: 477 | D21: 606520 | G21: ธ2569/00207 | H21: ธ2569/00215 | I21: 9 | J21: =500+500+1800+200+200+200+200+200+200 -> 4000 | M21: =SUM(C21,I21) -> 486 | N21: =SUM(D21,J21) -> 610520 | O21: ธ69/00471 | P21: ธ69/00480 | Q21: 10 | R21: 19320 | U21: =#REF! -> #REF! | V21: =R21 -> 19320 | W21: =SUM(M21,Q21) -> 496 | X21: =SUM(N21,R21) -> 629840 | Z21: 1959 | AA21: 26 พ.ย.68
A22: 26 พ.ย. 68 | C22: 483 | D22: 773580 | G22: ธ2569/00216 | H22: ธ2569/00219 | I22: 4 | J22: 1400 | M22: =SUM(C22,I22) -> 487 | N22: =SUM(D22,J22) -> 774980 | O22: ธ69/00481 | P22: ธ69/00505 | Q22: 25 | R22: 80666 | U22: =#REF! -> #REF! | V22: =R22 -> 80666 | W22: =SUM(M22,Q22) -> 512 | X22: =SUM(N22,R22) -> 855646 | Z22: 1966 | AA22: 27 พ.ย.68
A23: 27 พ.ย. 68 | C23: 417 | D23: 501490 | G23: ธ2569/00220 | H23: ธ2569/00227 | I23: 8 | J23: 4720 | M23: =SUM(C23,I23) -> 425 | N23: =SUM(D23,J23) -> 506210 | O23: ธ69/00506 | P23: ธ69/00529 | Q23: 24 | R23: 59101.8 | U23: =#REF! -> #REF! | V23: =R23 -> 59101.8 | W23: =SUM(M23,Q23) -> 449 | X23: =SUM(N23,R23) -> 565311.8 | Z23: 1972 | AA23: 28 พ.ย.68
A24: 28 - 30 พ.ย. 68 | C24: 494 | D24: 1018320 | G24: ธ2569/00228 | H24: ธ2569/00232 | I24: 5 | J24: =200+200+200+200+500 -> 1300 | M24: =SUM(C24,I24) -> 499 | N24: =SUM(D24,J24) -> 1019620 | O24: ธ69/00530 | P24: ธ69/00547 | Q24: 18 | R24: 36341 | W24: =SUM(M24,Q24) -> 517 | X24: =SUM(N24,R24) -> 1055961 | Z24: 1981 | AA24: 1 ธ.ค. 68
A25: รวม | C25: =SUM(C6:C24) -> 10095 | D25: =SUM(D6:D24) -> 9869151 | E25: =SUM(E6:E23) -> 0 | F25: =SUM(F6:F23) -> 0 | G25: รวม | I25: =SUM(I6:I24) -> 106 | J25: =SUM(J6:J24) -> 55250 | K25: =SUM(K6:K23) -> 0 | L25: =SUM(L6:L23) -> 0 | M25: =SUM(M6:M23) -> 9702 | N25: =SUM(N6:N23) -> 8904781 | O25: รวม | Q25: =SUM(Q6:Q24) -> 302 | R25: =SUM(R6:R24) -> 656437.7 | S25: =SUM(S6:S23) -> 0 | T25: =SUM(T6:T23) -> 0 | U25: =SUM(U6:U23) -> #REF! | V25: =SUM(V6:V23) -> 620096.7 | W25: =SUM(W6:W24) -> 10503 | X25: =SUM(X6:X24) -> 10580839

Sheet ธ.ค.68
A1: รายงานการรับชำระค่าธรรมเนียมผ่านธนาคาร เดือน ธันวาคม 2568
A3: วันที่ชำระ | B3: ข้อมูลกฎหมาย | C3: ระบบ Safety | G3: ระบบ Receipt (ใบเสร็จรับเงิน A4) | M3: รวมพรบ.42 (Safety + Receipt) | O3: ระบบ Trade | U3: รวมพรบ.2543 (Trade) | W3: นำรายได้ ส่ง คพ. พรบ.42 + พรบ.43 | Y3: หมายเหตุ | Z3: พน0401.1/ | AA3: วันที่ส่ง
B4: กฎหมาย | C4: จำนวนใบเสร็จ | D4: จำนวนเงิน | E4: ยกเลิกใบเสร็จ | G4: จาก | H4: ถึง | I4: จำนวนใบเสร็จ | J4: จำนวนเงิน | K4: ยกเลิก/ใบเสร็จเสีย | M4: รวมจำนวนใบเสร็จ | N4: รวมจำนวนเงิน | O4: จาก | P4: ถึง | Q4: จำนวนใบเสร็จ | R4: จำนวนเงิน | S4: ยกเลิกใบเสร็จ | U4: รวมจำนวนใบเสร็จ | V4: รวมจำนวนเงิน | W4: รวมจำนวนใบเสร็จ | X4: รวมจำนวนเงิน
E5: จำนวนใบเสร็จ | F5: เลขที่ใบเสร็จ | K5: จำนวนใบเสร็จ | L5: เลขที่ใบเสร็จ | S5: จำนวนใบเสร็จ | T5: เลขที่ใบเสร็จ
A6: 1 ธ.ค. 68 | C6: 468 | D6: 478630 | G6: ธ2569/00233 | H6: ธ2569/00235 | I6: 3 | J6: =400+200+2600 -> 3200 | M6: =SUM(C6,I6) -> 471 | N6: =SUM(D6,J6) -> 481830 | O6: ธ69/00548 | P6: ธ69/00586 | Q6: 39 | R6: 103521.94 | U6: =SUM(Q6) -> 39 | V6: =SUM(R6) -> 103521.94 | W6: =SUM(M6,Q6) -> 510 | X6: =SUM(N6,R6) -> 585351.94 | Z6: 1985 | AA6: 2 ธ.ค. 68
A7: 2 ธ.ค. 68 | C7: 689 | D7: 570350 | G7: ธ2569/00236 | H7: ธ2569/00238 | I7: 3 | J7: =450+450+450 -> 1350 | M7: =SUM(C7,I7) -> 692 | N7: =SUM(D7,J7) -> 571700 | O7: ธ69/00587 | P7: ธ69/00691 | Q7: 105 | R7: 246371.94 | U7: =SUM(Q7) -> 105 | V7: =SUM(R7) -> 246371.94 | W7: =SUM(M7,Q7) -> 797 | X7: =SUM(N7,R7) -> 818071.94 | Z7: 1997 | AA7: 3 ธ.ค. 68
A8: 3 ธ.ค. 68 | C8: 585 | D8: 604000 | G8: ธ2569/00239 | H8: ธ2569/00249 | I8: 11 | J8: =200+200+200+200+200+200+200+200+500+1020+200 -> 3320 | M8: =SUM(C8,I8) -> 596 | N8: =SUM(D8,J8) -> 607320 | O8: ธ69/00692 | P8: ธ69/00834 | Q8: 143 | R8: 332553.09 | U8: =SUM(Q8) -> 143 | V8: =SUM(R8) -> 332553.09 | W8: =SUM(M8,Q8) -> 739 | X8: =SUM(N8,R8) -> 939873.09 | Z8: 2005 | AA8: 4 ธ.ค. 68
A9: 4 - 7 ธ.ค. 68 | C9: 749 | D9: 881330 | G9: ธ2569/00250 | H9: ธ2569/00260 | I9: 11 | J9: =1520+200+500+500+1000+200+200+200+200+1620+200 -> 6340 | M9: =SUM(C9,I9) -> 760 | N9: =SUM(D9,J9) -> 887670 | O9: ธ69/00835 | P9: ธ69/01193 | Q9: 359 | R9: 616772.7 | U9: =SUM(Q9) -> 359 | V9: =SUM(R9) -> 616772.7 | W9: =SUM(M9,Q9) -> 1119 | X9: =SUM(N9,R9) -> 1504442.7 | Z9: 2015 | AA9: 9 ธ.ค. 68
A10: 8 ธ.ค. 68 | C10: 478 | D10: 1451080 | G10: ธ2569/00261 | H10: ธ2569/00266 | I10: 6 | J10: =1220+500+500+200+200+200 -> 2820 | M10: =SUM(C10,I10) -> 484 | N10: =SUM(D10,J10) -> 1453900 | O10: ธ69/01194 | P10: ธ69/01423 | Q10: 230 | R10: 458755.48 | U10: =SUM(Q10) -> 230 | V10: =SUM(R10) -> 458755.48 | W10: =SUM(M10,Q10) -> 714 | X10: =SUM(N10,R10) -> 1912655.5 | Z10: 2021 | AA10: 11 ธ.ค. 68
A11: 9 - 10 ธ.ค. 68 | C11: 836 | D11: 1104130 | G11: ธ2569/00267 | H11: - | I11: 1 | J11: 1800 | M11: =SUM(C11,I11) -> 837 | N11: =SUM(D11,J11) -> 1105930 | O11: ธ69/01424 | P11: ธ69/01776 | Q11: 353 | R11: 657793.87 | U11: =SUM(Q11) -> 353 | V11: =SUM(R11) -> 657793.87 | W11: =SUM(M11,Q11) -> 1190 | X11: =SUM(N11,R11) -> 1763723.9 | Z11: 2026 | AA11: 12 ธ.ค. 68
A12: 11 ธ.ค. 68 | C12: 770 | D12: 787060 | G12: ธ2569/00268 | H12: ธ2569/00271 | I12: 4 | J12: =600+1220+1000+200 -> 3020 | M12: =SUM(C12,I12) -> 774 | N12: =SUM(D12,J12) -> 790080 | O12: ธ69/01777 | P12: ธ69/02001 | Q12: 225 | R12: 406368.09 | U12: =SUM(Q12) -> 225 | V12: =SUM(R12) -> 406368.09 | W12: =SUM(M12,Q12) -> 999 | X12: =SUM(N12,R12) -> 1196448.1 | Z12: 2031 | AA12: 12 ธ.ค. 68
A13: 12 - 14 ธ.ค. 68 | C13: 1146 | D13: 1347160 | G13: ธ2569/00272 | H13: ธ2569/00275 | I13: 4 | J13: =200+200+200+200 -> 800 | M13: =SUM(C13,I13) -> 1150 | N13: =SUM(D13,J13) -> 1347960 | O13: ธ69/02002 | P13: ธ69/02380 | Q13: 379 | R13: 697181.61 | U13: =SUM(Q13) -> 379 | V13: =SUM(R13) -> 697181.61 | W13: =SUM(M13,Q13) -> 1529 | X13: =SUM(N13,R13) -> 2045141.6 | Z13: 2042 | AA13: 15 ธ.ค. 68
A14: 15 ธ.ค. 68 | C14: 772 | D14: 839080 | G14: ธ2569/00276 | H14: ธ2569/00280 | I14: 5 | J14: =500+500+500+450+500 -> 2450 | M14: =SUM(C14,I14) -> 777 | N14: =SUM(D14,J14) -> 841530 | O14: ธ69/02381 | P14: ธ69/02632 | Q14: 252 | R14: 536047.45 | U14: =SUM(Q14) -> 252 | V14: =SUM(R14) -> 536047.45 | W14: =SUM(M14,Q14) -> 1029 | X14: =SUM(N14,R14) -> 1377577.4 | Z14: 2050 | AA14: 16 ธ.ค. 68
A15: 16 ธ.ค. 68 | C15: 467 | D15: 1678930 | G15: ธ2569/00281 | H15: ธ2569/00286 | I15: 6 | J15: =200+200+200+200+1620+200 -> 2620 | M15: =SUM(C15,I15) -> 473 | N15: =SUM(D15,J15) -> 1681550 | O15: ธ69/02633 | P15: ธ69/02853 | Q15: 221 | R15: 513441.92 | U15: =SUM(Q15) -> 221 | V15: =SUM(R15) -> 513441.92 | W15: =SUM(M15,Q15) -> 694 | X15: =SUM(N15,R15) -> 2194991.9 | Z15: 2057 | AA15: 17 ธ.ค. 68
A16: 17 ธ.ค. 68 | C16: 470 | D16: 793320 | G16: ธ2569/00287 | H16: ธ2569/00297 | I16: 11 | J16: =200+1520+1920+200+1800+1520+200+1020+1220+200+500 -> 10300 | M16: =SUM(C16,I16) -> 481 | N16: =SUM(D16,J16) -> 803620 | O16: ธ69/02854 | P16: ธ69/03081 | Q16: 228 | R16: 507680.9 | U16: =SUM(Q16) -> 228 | V16: =SUM(R16) -> 507680.9 | W16: =SUM(M16,Q16) -> 709 | X16: =SUM(N16,R16) -> 1311300.9 | Z16: 2067 | AA16: 18 ธ.ค. 68
A17: 18 ธ.ค. 68 | C17: 471 | D17: 508830 | G17: ธ2569/00298 | H17: ธ2569/00304 | I17: 7 | J17: =500+2200+1220+1520+450+500+1000 -> 7390 | M17: =SUM(C17,I17) -> 478 | N17: =SUM(D17,J17) -> 516220 | O17: ธ69/03082 | P17: ธ69/03348 | Q17: 267 | R17: 579454.2 | U17: =SUM(Q17) -> 267 | V17: =SUM(R17) -> 579454.2 | W17: =SUM(M17,Q17) -> 745 | X17: =SUM(N17,R17) -> 1095674.2 | Z17: 2072 | AA17: 19 ธ.ค. 68
A18: 19 - 21 ธ.ค. 68 | C18: 657 | D18: 756940 | G18: ธ2569/00305 | H18: ธ2569/00309 | I18: 5 | J18: =200+200+620+1720+450 -> 3190 | M18: =SUM(C18,I18) -> 662 | N18: =SUM(D18,J18) -> 760130 | O18: ธ69/03349 | P18: ธ69/03757 | Q18: 409 | R18: 1021700 | U18: =SUM(Q18) -> 409 | V18: =SUM(R18) -> 1021700 | W18: =SUM(M18,Q18) -> 1071 | X18: =SUM(N18,R18) -> 1781830 | Z18: 2082 | AA18: 22 ธ.ค. 68
A19: 22 ธ.ค. 68 | C19: 657 | D19: 746810 | G19: ธ2569/00310 | H19: ธ2569/00314 | I19: 5 | J19: =200+3400+1620+500+200 -> 5920 | M19: =SUM(C19,I19) -> 662 | N19: =SUM(D19,J19) -> 752730 | O19: ธ69/03758 | P19: ธ69/04007 | Q19: 250 | R19: 515093.87 | U19: =SUM(Q19) -> 250 | V19: =SUM(R19) -> 515093.87 | W19: =SUM(M19,Q19) -> 912 | X19: =SUM(N19,R19) -> 1267823.9 | Z19: 2089 | AA19: 23 ธ.ค. 68
A20: 23 ธ.ค. 68 | C20: 482 | D20: 588570 | G20: ธ2569/00315 | H20: ธ2569/00325 | I20: 11 | J20: =450+450+600+300+200+500+500+400+1000+500+1800 -> 6700 | M20: =SUM(C20,I20) -> 493 | N20: =SUM(D20,J20) -> 595270 | O20: ธ69/04008 | P20: ธ69/04245 | Q20: 238 | R20: 469670.34 | U20: =SUM(Q20) -> 238 | V20: =SUM(R20) -> 469670.34 | W20: =SUM(M20,Q20) -> 731 | X20: =SUM(N20,R20) -> 1064940.3 | Z20: 2097 | AA20: 24 ธ.ค. 68
A21: 24 ธ.ค. 68 | C21: 634 | D21: 683640 | G21: ธ2569/00326 | H21: ธ2569/00339 | I21: 14 | J21: =1720+200+200+200+200+200+1400+1920+450+2500+450+500+500+500 -> 10940 | M21: =SUM(C21,I21) -> 648 | N21: =SUM(D21,J21) -> 694580 | O21: ธ69/04246 | P21: ธ69/04471 | Q21: 226 | R21: 403046.15 | U21: =SUM(Q21) -> 226 | V21: =SUM(R21) -> 403046.15 | W21: =SUM(M21,Q21) -> 874 | X21: =SUM(N21,R21) -> 1097626.1 | Z21: 2108 | AA21: 25 ธ.ค. 68
A22: 25 ธ.ค. 68 | C22: 572 | D22: 538570 | G22: ธ2569/00340 | H22: ธ2569/00369 | I22: 30 | J22: =450+450+450+450+450+450+200+450+1000+450+450+450+1000+1000+1000+450+400+200+1800+450+450+450+450+450+450+450+450+450+500+500 -> 16600 | M22: =SUM(C22,I22) -> 602 | N22: =SUM(D22,J22) -> 555170 | O22: ธ69/04472 | P22: ธ69/04699 | Q22: 228 | R22: 424642.57 | U22: =SUM(Q22) -> 228 | V22: =SUM(R22) -> 424642.57 | W22: =SUM(M22,Q22) -> 830 | X22: =SUM(N22,R22) -> 979812.57 | Z22: 2114 | AA22: 26 ธ.ค. 68
A23: 26 - 28 ธ.ค. 68 | C23: 889 | D23: 1999770 | G23: ธ2569/00370 | H23: ธ2569/00423 | I23: 54 | J23: 58400 | M23: =SUM(C23,I23) -> 943 | N23: =SUM(D23,J23) -> 2058170 | O23: ธ69/04700 | P23: ธ69/05044 | Q23: 345 | R23: 630106.12 | U23: =SUM(Q23) -> 345 | V23: =SUM(R23) -> 630106.12 | W23: =SUM(M23,Q23) -> 1288 | X23: =SUM(N23,R23) -> 2688276.1 | Z23: 2125 | AA23: 29 ธ.ค. 68
A24: 29 ธ.ค. 68 | C24: 246 | D24: 255650 | G24: ธ2569/00424 | H24: ธ2569/00495,00566 | I24: 73 | J24: 46720 | M24: =SUM(C24,I24) -> 319 | N24: =SUM(D24,J24) -> 302370 | O24: ธ69/05045 | P24: ธ69/05214 | Q24: 170 | R24: 332696.12 | U24: =SUM(Q24) -> 170 | V24: =SUM(R24) -> 332696.12 | W24: =SUM(M24,Q24) -> 489 | X24: =SUM(N24,R24) -> 635066.12 | Y24: *เลขข้าม ระบบ Receipt | Z24: 2131 | AA24: 30 ธ.ค. 68
A25: รวม | C25: =SUM(C6:C24) -> 12038 | D25: =SUM(D6:D24) -> 16613850 | E25: =SUM(E6:E23) -> 0 | F25: =SUM(F6:F23) -> 0 | G25: รวม | I25: =SUM(I6:I24) -> 264 | J25: =SUM(J6:J24) -> 193880 | K25: =SUM(K6:K23) -> 0 | L25: =SUM(L6:L23) -> 0 | M25: =SUM(M6:M23) -> 11983 | N25: =SUM(N6:N23) -> 16505360 | O25: รวม | Q25: =SUM(Q6:Q24) -> 4667 | R25: =SUM(R6:R24) -> 9452898.4 | S25: =SUM(S6:S23) -> 0 | T25: =SUM(T6:T23) -> 0 | U25: =SUM(U6:U23) -> 4497 | V25: =SUM(V6:V23) -> 9120202.2 | W25: =SUM(W6:W24) -> 16969 | X25: =SUM(X6:X24) -> 26260628

Sheet ม.ค.69
A1: รายงานการรับชำระค่าธรรมเนียมผ่านธนาคาร เดือน มกราคม 2569
A3: วันที่ชำระ | B3: ข้อมูลกฎหมาย | C3: ระบบ Safety | G3: ระบบ Receipt (ใบเสร็จรับเงิน A4) | M3: รวมพรบ.42 (Safety + Receipt) | O3: ระบบ Trade | U3: รวมพรบ.2543 (Trade) | W3: นำรายได้ ส่ง คพ. พรบ.42 + พรบ.43 | Y3: หมายเหตุ | Z3: พน0401.1/ | AA3: วันที่ส่ง
B4: กฎหมาย | C4: จำนวนใบเสร็จ | D4: จำนวนเงิน | E4: ยกเลิกใบเสร็จ | G4: จาก | H4: ถึง | I4: จำนวนใบเสร็จ | J4: จำนวนเงิน | K4: ยกเลิก/ใบเสร็จเสีย | M4: รวมจำนวนใบเสร็จ | N4: รวมจำนวนเงิน | O4: จาก | P4: ถึง | Q4: จำนวนใบเสร็จ | R4: จำนวนเงิน | S4: ยกเลิกใบเสร็จ | U4: รวมจำนวนใบเสร็จ | V4: รวมจำนวนเงิน | W4: รวมจำนวนใบเสร็จ | X4: รวมจำนวนเงิน
E5: จำนวนใบเสร็จ | F5: เลขที่ใบเสร็จ | K5: จำนวนใบเสร็จ | L5: เลขที่ใบเสร็จ | S5: จำนวนใบเสร็จ | T5: เลขที่ใบเสร็จ
A6: 30 ธ.ค. 68 - 4 ม.ค. 69 | C6: 347 | D6: 299200 | G6: ธ2569/00496 | H6: ธ2569/00554 | I6: 59 | J6: 50320 | M6: =SUM(C6,I6) -> 406 | N6: =SUM(D6,J6) -> 349520 | O6: ธ69/05215 | P6: ธ69/05643 | Q6: 429 | R6: 675663.86 | U6: =SUM(Q6) -> 429 | V6: =SUM(R6) -> 675663.86 | W6: =SUM(M6,Q6) -> 835 | X6: =SUM(N6,R6) -> 1025183.9 | Z6: 2 | AA6: 5 ม.ค.69
A7: 5 ม.ค. 68 | C7: 68 | D7: 89280 | G7: ธ2569/00555 | H7: ธ2569/00565 | I7: 11 | J7: 6220 | M7: =SUM(C7,I7) -> 79 | N7: =SUM(D7,J7) -> 95500 | O7: ธ69/05644 | P7: ธ69/05950 | Q7: 307 | R7: 629674.52 | U7: =SUM(Q7) -> 307 | V7: =SUM(R7) -> 629674.52 | W7: =SUM(M7,Q7) -> 386 | X7: =SUM(N7,R7) -> 725174.52 | Z7: 8 | AA7: 6 ม.ค.69
A8: 6 ม.ค. 68 | C8: 103 | D8: 76720 | G8: ธ2569/00567 | H8: ธ2569/00572 | I8: 6 | J8: 2550 | M8: =SUM(C8,I8) -> 109 | N8: =SUM(D8,J8) -> 79270 | O8: ธ69/05951 | P8: ธ69/06239 | Q8: 289 | R8: 597211.62 | U8: =SUM(Q8) -> 289 | V8: =SUM(R8) -> 597211.62 | W8: =SUM(M8,Q8) -> 398 | X8: =SUM(N8,R8) -> 676481.62 | Y8: *Receipt เลขข้ามเนื่องจากวันที่ชำระ 29 ธ.ค. 68 | Z8: 14 | AA8: 7 ม.ค.69
A9: 7 ม.ค. 68 | C9: 40 | D9: 37460 | G9: ธ2569/00573 | H9: ธ2569/00577 | I9: 5 | J9: 3100 | M9: =SUM(C9,I9) -> 45 | N9: =SUM(D9,J9) -> 40560 | O9: ธ69/06240 | P9: ธ69/06553 | Q9: 314 | R9: 703324.85 | U9: =SUM(Q9) -> 314 | V9: =SUM(R9) -> 703324.85 | W9: =SUM(M9,Q9) -> 359 | X9: =SUM(N9,R9) -> 743884.85 | Z9: 22 | AA9: 8 ม.ค.69
A10: 8 ม.ค. 68 | C10: 49 | D10: 70570 | G10: ธ2569/00578 | H10: ธ2569/00588 | I10: 11 | J10: 8720 | M10: =SUM(C10,I10) -> 60 | N10: =SUM(D10,J10) -> 79290 | O10: ธ69/06554 | P10: ธ69/06839 | Q10: 286 | R10: 527907.74 | U10: =SUM(Q10) -> 286 | V10: =SUM(R10) -> 527907.74 | W10: =SUM(M10,Q10) -> 346 | X10: =SUM(N10,R10) -> 607197.74 | Z10: 28 | AA10: 9 ม.ค.69
A11: 9 - 11 ม.ค. 68 | C11: 62 | D11: 123080 | G11: ธ2569/00589 | H11: ธ2569/00600,00602 | I11: 13 | J11: 6700 | K11: 1 | L11: ธ2569/00601 | M11: =SUM(C11,I11) -> 75 | N11: =SUM(D11,J11) -> 129780 | O11: ธ69/06840 | P11: ธ69/07201 | Q11: 362 | R11: 670026.13 | U11: =SUM(Q11) -> 362 | V11: =SUM(R11) -> 670026.13 | W11: =SUM(M11,Q11) -> 437 | X11: =SUM(N11,R11) -> 799806.13 | Z11: 36 | AA11: 12 ม.ค.69
A12: 12 ม.ค. 68 | C12: 53 | D12: 58950 | G12: ธ2569/00603 | H12: ธ2569/00612 | I12: 10 | J12: 7900 | M12: =SUM(C12,I12) -> 63 | N12: =SUM(D12,J12) -> 66850 | O12: ธ69/07202 | P12: ธ69/07503 | Q12: 302 | R12: 558183.22 | U12: =SUM(Q12) -> 302 | V12: =SUM(R12) -> 558183.22 | W12: =SUM(M12,Q12) -> 365 | X12: =SUM(N12,R12) -> 625033.22 | Z12: 43 | AA12: 13 ม.ค.69
A13: 13 ม.ค. 68 | C13: 55 | D13: 244710 | G13: ธ2569/00613 | H13: ธ2569/00617 | I13: 5 | J13: 4140 | M13: =SUM(C13,I13) -> 60 | N13: =SUM(D13,J13) -> 248850 | O13: ธ69/07504 | P13: ธ69/07757 | Q13: 254 | R13: 487700 | U13: =SUM(Q13) -> 254 | V13: =SUM(R13) -> 487700 | W13: =SUM(M13,Q13) -> 314 | X13: =SUM(N13,R13) -> 736550 | Z13: 51 | AA13: 14 ม.ค.69
A14: 14 ม.ค. 68 | C14: 56 | D14: 1556290 | G14: ธ2569/00618 | H14: - | I14: 1 | J14: 500 | M14: =SUM(C14,I14) -> 57 | N14: =SUM(D14,J14) -> 1556790 | O14: ธ69/07758 | P14: ธ69/08006 | Q14: 249 | R14: 502668.26 | U14: =SUM(Q14) -> 249 | V14: =SUM(R14) -> 502668.26 | W14: =SUM(M14,Q14) -> 306 | X14: =SUM(N14,R14) -> 2059458.3 | Z14: 59 | AA14: 15 ม.ค.69
A15: 15 ม.ค. 68 | C15: 42 | D15: 41050 | G15: ธ2569/00619 | H15: ธ2569/00624 | I15: 6 | J15: 2750 | M15: =SUM(C15,I15) -> 48 | N15: =SUM(D15,J15) -> 43800 | O15: ธ69/08007 | P15: ธ69/08223 | Q15: 217 | R15: 608976.87 | U15: =SUM(Q15) -> 217 | V15: =SUM(R15) -> 608976.87 | W15: =SUM(M15,Q15) -> 265 | X15: =SUM(N15,R15) -> 652776.87 | Z15: 65 | AA15: 16 ม.ค.69
A16: 16 - 18 ม.ค. 68 | C16: 46 | D16: 54920 | G16: ธ2569/00625 | H16: ธ2569/00627 | I16: 3 | J16: 2500 | M16: =SUM(C16,I16) -> 49 | N16: =SUM(D16,J16) -> 57420 | O16: ธ69/08224 | P16: ธ69/08582 | Q16: 359 | R16: 918368.95 | U16: =SUM(Q16) -> 359 | V16: =SUM(R16) -> 918368.95 | W16: =SUM(M16,Q16) -> 408 | X16: =SUM(N16,R16) -> 975788.95 | Z16: 74 | AA16: 19 ม.ค.69
A17: 19 ม.ค. 68 | C17: 41 | D17: 78960 | G17: ธ2569/00628 | H17: ธ2569/00636 | I17: 9 | J17: 8000 | M17: =SUM(C17,I17) -> 50 | N17: =SUM(D17,J17) -> 86960 | O17: ธ69/08583 | P17: ธ69/08786 | Q17: 204 | R17: 365900 | U17: =SUM(Q17) -> 204 | V17: =SUM(R17) -> 365900 | W17: =SUM(M17,Q17) -> 254 | X17: =SUM(N17,R17) -> 452860 | Z17: 80 | AA17: 20 ม.ค.69
A18: 20 ม.ค. 68 | C18: 24 | D18: 23750 | G18: ธ2569/00637 | H18: ธ2569/00643 | I18: 7 | J18: 3620 | M18: =SUM(C18,I18) -> 31 | N18: =SUM(D18,J18) -> 27370 | O18: ธ69/08787 | P18: ธ69/08975 | Q18: 189 | R18: 415016.12 | U18: =SUM(Q18) -> 189 | V18: =SUM(R18) -> 415016.12 | W18: =SUM(M18,Q18) -> 220 | X18: =SUM(N18,R18) -> 442386.12 | Z18: 86 | AA18: 21 ม.ค.69
A19: 21 ม.ค. 68 | C19: 25 | D19: 23100 | G19: ธ2569/00644 | H19: ธ2569/00651 | I19: 8 | J19: 6450 | M19: =SUM(C19,I19) -> 33 | N19: =SUM(D19,J19) -> 29550 | O19: ธ69/08976 | P19: ธ69/09183 | Q19: 208 | R19: 662640.64 | U19: =SUM(Q19) -> 208 | V19: =SUM(R19) -> 662640.64 | W19: =SUM(M19,Q19) -> 241 | X19: =SUM(N19,R19) -> 692190.64 | Z19: 97 | AA19: 22 ม.ค.69
A20: 22 ม.ค. 68 | C20: 25 | D20: 38350 | G20: ธ2569/00652 | H20: ธ2569/00663 | I20: 12 | J20: 5700 | M20: =SUM(C20,I20) -> 37 | N20: =SUM(D20,J20) -> 44050 | O20: ธ69/09184 | P20: ธ69/09343 | Q20: 160 | R20: 294306.45 | U20: =SUM(Q20) -> 160 | V20: =SUM(R20) -> 294306.45 | W20: =SUM(M20,Q20) -> 197 | X20: =SUM(N20,R20) -> 338356.45 | Z20: 105 | AA20: 23 ม.ค.69
A21: 23 - 25 ม.ค. 68 | C21: 38 | D21: 44930 | G21: ธ2569/00664 | H21: ธ2569/00666 | I21: 3 | J21: 1420 | M21: =SUM(C21,I21) -> 41 | N21: =SUM(D21,J21) -> 46350 | O21: ธ69/09344 | P21: ธ69/09567 | Q21: 224 | R21: 498439.75 | U21: =SUM(Q21) -> 224 | V21: =SUM(R21) -> 498439.75 | W21: =SUM(M21,Q21) -> 265 | X21: =SUM(N21,R21) -> 544789.75 | Z21: 112 | AA21: 26 ม.ค.69
A22: 26 ม.ค. 68 | C22: 26 | D22: 21650 | G22: ธ2569/00667 | H22: ธ2569/00675 | I22: 9 | J22: 4350 | M22: =SUM(C22,I22) -> 35 | N22: =SUM(D22,J22) -> 26000 | O22: ธ69/09568 | P22: ธ69/09766 | Q22: 199 | R22: 418810.32 | U22: =SUM(Q22) -> 199 | V22: =SUM(R22) -> 418810.32 | W22: =SUM(M22,Q22) -> 234 | X22: =SUM(N22,R22) -> 444810.32 | Z22: 120 | AA22: 27 ม.ค.69
A23: 27 ม.ค. 68 | C23: 39 | D23: 56690 | G23: ธ2569/00676 | H23: ธ2569/00686 | I23: 11 | J23: 9100 | M23: =SUM(C23,I23) -> 50 | N23: =SUM(D23,J23) -> 65790 | O23: ธ69/09767 | P23: ธ69/09972 | Q23: 206 | R23: 386626.13 | U23: =SUM(Q23) -> 206 | V23: =SUM(R23) -> 386626.13 | W23: =SUM(M23,Q23) -> 256 | X23: =SUM(N23,R23) -> 452416.13 | Z23: 127 | AA23: 28 ม.ค.69
A24: 28 ม.ค. 68 | C24: 15 | D24: 16770 | G24: ธ2569/00687 | H24: ธ2569/00694 | I24: 8 | J24: 6050 | M24: =SUM(C24,I24) -> 23 | N24: =SUM(D24,J24) -> 22820 | O24: ธ69/09973 | P24: ธ69/10135 | Q24: 163 | R24: 352654.2 | W24: =SUM(M24,Q24) -> 186 | X24: =SUM(N24,R24) -> 375474.2 | Z24: 134 | AA24: 29 ม.ค.69
A25: 29 ม.ค. 68 | C25: 17 | D25: 21250 | G25: ธ2569/00695 | H25: ธ2569/00704 | I25: 10 | J25: 3000 | M25: =SUM(C25,I25) -> 27 | N25: =SUM(D25,J25) -> 24250 | O25: ธ69/10136 | P25: ธ69/10279 | Q25: 144 | R25: 341628.06 | W25: =SUM(M25,Q25) -> 171 | X25: =SUM(N25,R25) -> 365878.06 | Z25: 142 | AA25: 30 ม.ค.69
A26: รวม | C26: =SUM(C6:C25) -> 1171 | D26: =SUM(D6:D25) -> 2977680 | E26: =SUM(E6:E23) -> 0 | F26: =SUM(F6:F23) -> 0 | G26: รวม | I26: =SUM(I6:I25) -> 207 | J26: =SUM(J6:J25) -> 143090 | K26: =SUM(K6:K23) -> 1 | M26: =SUM(M6:M23) -> 1328 | N26: =SUM(N6:N23) -> 3073700 | O26: รวม | Q26: =SUM(Q6:Q25) -> 5065 | R26: =SUM(R6:R25) -> 10615728 | S26: =SUM(S6:S23) -> 0 | T26: =SUM(T6:T23) -> 0 | U26: =SUM(U6:U23) -> 4758 | V26: =SUM(V6:V23) -> 9921445.4 | W26: =SUM(W6:W25) -> 6443 | X26: =SUM(X6:X25) -> 13736498

Sheet ก.พ.69
A1: รายงานการรับชำระค่าธรรมเนียมผ่านธนาคาร เดือน กุมภาพันธ์ 2569
A3: วันที่ชำระ | B3: ข้อมูลกฎหมาย | C3: ระบบ Safety | G3: ระบบ Receipt (ใบเสร็จรับเงิน A4) | M3: รวมพรบ.42 (Safety + Receipt) | O3: ระบบ Trade | U3: รวมพรบ.2543 (Trade) | W3: นำรายได้ ส่ง คพ. พรบ.42 + พรบ.43 | Y3: หมายเหตุ | Z3: พน0401.1/ | AA3: วันที่ส่ง
B4: กฎหมาย | C4: จำนวนใบเสร็จ | D4: จำนวนเงิน | E4: ยกเลิกใบเสร็จ | G4: จาก | H4: ถึง | I4: จำนวนใบเสร็จ | J4: จำนวนเงิน | K4: ยกเลิก/ใบเสร็จเสีย | M4: รวมจำนวนใบเสร็จ | N4: รวมจำนวนเงิน | O4: จาก | P4: ถึง | Q4: จำนวนใบเสร็จ | R4: จำนวนเงิน | S4: ยกเลิกใบเสร็จ | U4: รวมจำนวนใบเสร็จ | V4: รวมจำนวนเงิน | W4: รวมจำนวนใบเสร็จ | X4: รวมจำนวนเงิน
E5: จำนวนใบเสร็จ | F5: เลขที่ใบเสร็จ | K5: จำนวนใบเสร็จ | L5: เลขที่ใบเสร็จ | S5: จำนวนใบเสร็จ | T5: เลขที่ใบเสร็จ
A6: 30 ม.ค. 69 - 1 ก.พ. 69 | C6: 36 | D6: 49750 | G6: ธ2569/00705 | H6: ธ2569/00715 | I6: 11 | J6: 6450 | M6: =SUM(C6,I6) -> 47 | N6: =SUM(D6,J6) -> 56200 | O6: ธ69/10280 | P6: ธ69/10546 | Q6: 267 | R6: 739000 | U6: =SUM(Q6) -> 267 | V6: =SUM(R6) -> 739000 | W6: =SUM(M6,Q6) -> 314 | X6: =SUM(N6,R6) -> 795200 | Z6: 154 | AA6: 2 ก.พ.69
A7: 2 ก.พ. 69 | C7: 19 | D7: 25830 | G7: ธ2569/00716 | H7: ธ2569/00720 | I7: 5 | J7: 2100 | M7: =SUM(C7,I7) -> 24 | N7: =SUM(D7,J7) -> 27930 | O7: ธ69/10547 | P7: ธ69/10688 | Q7: 142 | R7: 251299.93 | U7: =SUM(Q7) -> 142 | V7: =SUM(R7) -> 251299.93 | W7: =SUM(M7,Q7) -> 166 | X7: =SUM(N7,R7) -> 279229.93 | Z7: 162 | AA7: 3 ก.พ.69
A8: 3 ก.พ. 69 | C8: 9 | D8: 20860 | G8: ธ2569/00721 | H8: ธ2569/00725 | I8: 5 | J8: 2100 | M8: =SUM(C8,I8) -> 14 | N8: =SUM(D8,J8) -> 22960 | O8: ธ69/10689 | P8: ธ69/10889 | Q8: 201 | R8: 404179.64 | U8: =SUM(Q8) -> 201 | V8: =SUM(R8) -> 404179.64 | W8: =SUM(M8,Q8) -> 215 | X8: =SUM(N8,R8) -> 427139.64 | Z8: 167 | AA8: 4 ก.พ.69
A9: 4 ก.พ. 69 | C9: 33 | D9: 53850 | G9: ธ2569/00726 | H9: ธ2569/00729 | I9: 4 | J9: 4250 | M9: =SUM(C9,I9) -> 37 | N9: =SUM(D9,J9) -> 58100 | O9: ธ69/10890 | P9: ธ69/11092 | Q9: 203 | R9: 343800 | U9: =SUM(Q9) -> 203 | V9: =SUM(R9) -> 343800 | W9: =SUM(M9,Q9) -> 240 | X9: =SUM(N9,R9) -> 401900 | Z9: 173 | AA9: 5 ก.พ.69
A10: 5 ก.พ. 69 | C10: 21 | D10: 38600 | G10: ธ2569/00730 | H10: ธ2569/00734 | I10: 5 | J10: 3250 | M10: =SUM(C10,I10) -> 26 | N10: =SUM(D10,J10) -> 41850 | O10: ธ69/11093 | P10: ธ69/11252 | Q10: 160 | R10: 487356.07 | U10: =SUM(Q10) -> 160 | V10: =SUM(R10) -> 487356.07 | W10: =SUM(M10,Q10) -> 186 | X10: =SUM(N10,R10) -> 529206.07 | Z10: 182 | AA10: 6 ก.พ.69
A11: 6 - 8 ก.พ. 69 | C11: 17 | D11: 26800 | G11: ธ2569/00735 | H11: ธ2569/00741 | I11: 7 | J11: 3900 | M11: =SUM(C11,I11) -> 24 | N11: =SUM(D11,J11) -> 30700 | O11: ธ69/11253 | P11: ธ69/11597 | Q11: 305 | R11: 758469.29 | U11: =SUM(Q11) -> 305 | V11: =SUM(R11) -> 758469.29 | W11: =SUM(M11,Q11) -> 329 | X11: =SUM(N11,R11) -> 789169.29 | Z11: 187 | AA11: 9 ก.พ.69
A12: 9 ก.พ. 69 | C12: 17 | D12: 38540 | G12: ธ2569/00742 | H12: ธ2569/00744 | I12: 3 | J12: 1300 | M12: =SUM(C12,I12) -> 20 | N12: =SUM(D12,J12) -> 39840 | O12: ธ69/11598 | P12: ธ69/11753 | Q12: 196 | R12: 600239.64 | U12: =SUM(Q12) -> 196 | V12: =SUM(R12) -> 600239.64 | W12: =SUM(M12,Q12) -> 216 | X12: =SUM(N12,R12) -> 640079.64 | Z12: 199 | AA12: 10 ก.พ.69
A13: 10 ก.พ. 69 | C13: 26 | D13: 26460 | G13: ธ2569/00745 | H13: ธ2569/00751 | I13: 7 | J13: 3300 | M13: =SUM(C13,I13) -> 33 | N13: =SUM(D13,J13) -> 29760 | O13: ธ69/11754 | P13: ธ69/11983 | Q13: 230 | R13: 604424.36 | U13: =SUM(Q13) -> 230 | V13: =SUM(R13) -> 604424.36 | W13: =SUM(M13,Q13) -> 263 | X13: =SUM(N13,R13) -> 634184.36 | Z13: 208 | AA13: 11 ก.พ.69
A14: 11 ก.พ. 69 | C14: 47 | D14: 67950 | G14: ธ2569/00752 | H14: ธ2569/00760 | I14: 9 | J14: 5000 | M14: =SUM(C14,I14) -> 56 | N14: =SUM(D14,J14) -> 72950 | O14: ธ69/11984 | P14: ธ69/12170 | Q14: 187 | R14: 366541.79 | U14: =SUM(Q14) -> 187 | V14: =SUM(R14) -> 366541.79 | W14: =SUM(M14,Q14) -> 243 | X14: =SUM(N14,R14) -> 439491.79 | Z14: 214 | AA14: 12 ก.พ.69
A15: 12 ก.พ. 69 | C15: 11 | D15: 20350 | G15: ธ2569/00761 | H15: ธ2569/00773 | I15: 13 | J15: 9850 | M15: =SUM(C15,I15) -> 24 | N15: =SUM(D15,J15) -> 30200 | O15: ธ69/12171 | P15: ธ69/12326 | Q15: 156 | R15: 328634.3 | U15: =SUM(Q15) -> 156 | V15: =SUM(R15) -> 328634.3 | W15: =SUM(M15,Q15) -> 180 | X15: =SUM(N15,R15) -> 358834.3 | Z15: 220 | AA15: 13 ก.พ.69
A16: 13 - 15 ก.พ. 69 | C16: 16 | D16: 41800 | G16: ธ2569/00774 | H16: ธ2569/00782 | I16: 9 | J16: 5600 | M16: =SUM(C16,I16) -> 25 | N16: =SUM(D16,J16) -> 47400 | O16: ธ69/12327 | P16: ธ69/12601 | Q16: 275 | R16: 648800 | U16: =SUM(Q16) -> 275 | V16: =SUM(R16) -> 648800 | W16: =SUM(M16,Q16) -> 300 | X16: =SUM(N16,R16) -> 696200 | Z16: 226 | AA16: 16 ก.พ.69
A17: 16 ก.พ. 69 | C17: 18 | D17: 108110 | G17: ธ2569/00783 | H17: ธ2569/00787 | I17: 5 | J17: 5000 | M17: =SUM(C17,I17) -> 23 | N17: =SUM(D17,J17) -> 113110 | O17: ธ69/12602 | P17: ธ69/12722 | Q17: 121 | R17: 185647.14 | U17: =SUM(Q17) -> 121 | V17: =SUM(R17) -> 185647.14 | W17: =SUM(M17,Q17) -> 144 | X17: =SUM(N17,R17) -> 298757.14 | Z17: 233 | AA17: 17 ก.พ.69
... A21: 20 - 22 ก.พ. 69 | C21: 11 | D21: 1059110 | G21: ธ2569/00808 | H21: - | I21: 1 | J21: 500 | M21: =SUM(C21,I21) -> 12 | N21: =SUM(D21,J21) -> 1059610 | O21: ธ69/13189 | P21: ธ69/13430 | Q21: 242 | R21: 613522.86 | U21: =SUM(Q21) -> 242 | V21: =SUM(R21) -> 613522.86 | W21: =SUM(M21,Q21) -> 254 | X21: =SUM(N21,R21) -> 1673132.9 | Z21: 266 | AA21: 23 ก.พ.69
A22: 23 ก.พ. 69 | C22: 28 | D22: 152910 | G22: - | H22: - | I22: - | J22: - | M22: =SUM(C22,I22) -> 28 | N22: =SUM(D22,J22) -> 152910 | O22: ธ69/13431 | P22: ธ69/13644 | Q22: 214 | R22: 472483.92 | U22: =SUM(Q22) -> 214 | V22: =SUM(R22) -> 472483.92 | W22: =SUM(M22,Q22) -> 242 | X22: =SUM(N22,R22) -> 625393.92 | Z22: 271 | AA22: 24 ก.พ.69
A23: 24 ก.พ. 69 | C23: 46 | D23: 35550 | G23: ธ2569/00809 | H23: ธ2569/00820 | I23: 12 | J23: 5950 | M23: =SUM(C23,I23) -> 58 | N23: =SUM(D23,J23) -> 41500 | O23: ธ69/13645 | P23: ธ69/13877 | Q23: 233 | R23: 413200 | U23: =SUM(Q23) -> 233 | V23: =SUM(R23) -> 413200 | W23: =SUM(M23,Q23) -> 291 | X23: =SUM(N23,R23) -> 454700 | Z23: 278 | AA23: 25 ก.พ.69
A24: 25 ก.พ. 69 | C24: 12 | D24: 13150 | G24: ธ2569/00821 | H24: ธ2569/00823 | I24: 3 | J24: 1400 | M24: =SUM(C24,I24) -> 15 | N24: =SUM(D24,J24) -> 14550 | O24: ธ69/13878 | P24: ธ69/14140 | Q24: 263 | R24: 694313.58 | W24: =SUM(M24,Q24) -> 278 | X24: =SUM(N24,R24) -> 708863.58 | Z24: 286 | AA24: 26 ก.พ.69
A25: 26 ก.พ. 69 | C25: 12 | D25: 5950 | G25: ธ2569/00824 | H25: ธ2569/00832 | I25: 9 | J25: 5800 | M25: =SUM(C25,I25) -> 21 | N25: =SUM(D25,J25) -> 11750 | O25: ธ69/14141 | P25: ธ69/14457 | Q25: 317 | R25: 972975.72 | W25: =SUM(M25,Q25) -> 338 | X25: =SUM(N25,R25) -> 984725.72 | Z25: 292 | AA25: 27 ก.พ.69
A26: 30 มี.ค. 69 | M26: =SUM(C26,I26) -> 0 | N26: =SUM(D26,J26) -> 0 | W26: =SUM(M26,Q26) -> 0 | X26: =SUM(N26,R26) -> 0
A27: รวม | C27: =SUM(C6:C26) -> 442 | D27: =SUM(D6:D26) -> 2105730 | E27: =SUM(E6:E23) -> 0 | F27: =SUM(F6:F23) -> 0 | G27: รวม | I27: =SUM(I6:I26) -> 128 | J27: =SUM(J6:J26) -> 78950 | K27: =SUM(K6:K23) -> 0 | M27: =SUM(M6:M23) -> 534 | N27: =SUM(N6:N23) -> 2158380 | O27: รวม | Q27: =SUM(Q6:Q26) -> 4178 | R27: =SUM(R6:R26) -> 10014964 | S27: =SUM(S6:S23) -> 0 | T27: =SUM(T6:T23) -> 0 | U27: =SUM(U6:U23) -> 3598 | V27: =SUM(V6:V23) -> 8347675 | W27: =SUM(W6:W26) -> 4748 | X27: =SUM(X6:X26) -> 12199644

Sheet มี.ค.69
A1: รายงานการรับชำระค่าธรรมเนียมผ่านธนาคาร เดือน มีนาคม 2569
A3: วันที่ชำระ | B3: ข้อมูลกฎหมาย | C3: ระบบ Safety | G3: ระบบ Receipt (ใบเสร็จรับเงิน A4) | M3: รวมพรบ.42 (Safety + Receipt) | O3: ระบบ Trade | U3: รวมพรบ.2543 (Trade) | W3: นำรายได้ ส่ง คพ. พรบ.42 + พรบ.43 | Y3: หมายเหตุ | Z3: พน0401.1/ | AA3: วันที่ส่ง
B4: กฎหมาย | C4: จำนวนใบเสร็จ | D4: จำนวนเงิน | E4: ยกเลิกใบเสร็จ | G4: จาก | H4: ถึง | I4: จำนวนใบเสร็จ | J4: จำนวนเงิน | K4: ยกเลิก/ใบเสร็จเสีย | M4: รวมจำนวนใบเสร็จ | N4: รวมจำนวนเงิน | O4: จาก | P4: ถึง | Q4: จำนวนใบเสร็จ | R4: จำนวนเงิน | S4: ยกเลิกใบเสร็จ | U4: รวมจำนวนใบเสร็จ | V4: รวมจำนวนเงิน | W4: รวมจำนวนใบเสร็จ | X4: รวมจำนวนเงิน
E5: จำนวนใบเสร็จ | F5: เลขที่ใบเสร็จ | K5: จำนวนใบเสร็จ | L5: เลขที่ใบเสร็จ | S5: จำนวนใบเสร็จ | T5: เลขที่ใบเสร็จ
A6: 27 ก.พ. - 1 มี.ค. 69 | C6: 25 | D6: 16400 | G6: - | H6: - | I6: - | J6: - | M6: =SUM(C6,I6) -> 25 | N6: =SUM(D6,J6) -> 16400 | O6: ธ69/14458 | P6: ธ2569/15068 | Q6: 611 | R6: 1653235.6 | U6: =SUM(Q6) -> 611 | V6: =SUM(R6) -> 1653235.6 | W6: =SUM(M6,Q6) -> 636 | X6: =SUM(N6,R6) -> 1669635.6 | Z6: 300 | AA6: 2 มี.ค. 69
A7: 2 - 3 มี.ค. 69 | C7: 21 | D7: 25120 | G7: ธ2569/00833 | H7: ธ2569/00835 | I7: 3 | J7: 1500 | M7: =SUM(C7,I7) -> 24 | N7: =SUM(D7,J7) -> 26620 | O7: ธ2569/15069 | P7: ธ2569/15174 | Q7: 106 | R7: 209837.48 | U7: =SUM(Q7) -> 106 | V7: =SUM(R7) -> 209837.48 | W7: =SUM(M7,Q7) -> 130 | X7: =SUM(N7,R7) -> 236457.48 | Z7: 305 | AA7: 4 มี.ค. 69
A8: 4 มี.ค. 69 | C8: 10 | D8: 11400 | G8: ธ2569/00836 | H8: ธ2569/00841 | I8: 6 | J8: 4750 | M8: =SUM(C8,I8) -> 16 | N8: =SUM(D8,J8) -> 16150 | O8: ธ2569/15175 | P8: ธ2569/15216 | Q8: 42 | R8: 56627.46 | U8: =SUM(Q8) -> 42 | V8: =SUM(R8) -> 56627.46 | W8: =SUM(M8,Q8) -> 58 | X8: =SUM(N8,R8) -> 72777.46 | Z8: 315 | AA8: 5 มี.ค. 69
A9: 5 มี.ค. 69 | C9: 13 | D9: 21100 | G9: ธ2569/00842 | H9: ธ2569/00844 | I9: 3 | J9: 1000 | M9: =SUM(C9,I9) -> 16 | N9: =SUM(D9,J9) -> 22100 | O9: ธ2569/15217 | P9: ธ2569/15271 | Q9: 55 | R9: 89520.54 | U9: =SUM(Q9) -> 55 | V9: =SUM(R9) -> 89520.54 | W9: =SUM(M9,Q9) -> 71 | X9: =SUM(N9,R9) -> 111620.54 | Z9: 321 | AA9: 6 มี.ค. 69
A10: 6 - 8 มี.ค. 69 | C10: 10 | D10: 10650 | G10: ธ2569/00845 | H10: ธ2569/00853 | I10: 9 | J10: 1800 | M10: =SUM(C10,I10) -> 19 | N10: =SUM(D10,J10) -> 12450 | O10: ธ2569/15272 | P10: ธ2569/15343 | Q10: 72 | R10: 166386.07 | U10: =SUM(Q10) -> 72 | V10: =SUM(R10) -> 166386.07 | W10: =SUM(M10,Q10) -> 91 | X10: =SUM(N10,R10) -> 178836.07 | Z10: 326 | AA10: 9 มี.ค. 69
A11: 9 มี.ค. 69 | C11: 11 | D11: 26750 | G11: ธ2569/00854 | H11: ธ2569/00856 | I11: 3 | J11: 3300 | M11: =SUM(C11,I11) -> 14 | N11: =SUM(D11,J11) -> 30050 | O11: ธ2569/15344 | P11: ธ2569/15395 | Q11: 52 | R11: 183209.37 | U11: =SUM(Q11) -> 52 | V11: =SUM(R11) -> 183209.37 | W11: =SUM(M11,Q11) -> 66 | X11: =SUM(N11,R11) -> 213259.37 | Z11: 335 | AA11: 10 มี.ค. 69
A12: 10 มี.ค. 69 | C12: 19 | D12: 29800 | G12: ธ2569/00857 | H12: ธ2569/00858 | I12: 2 | J12: 400 | M12: =SUM(C12,I12) -> 21 | N12: =SUM(D12,J12) -> 30200 | O12: ธ2569/15396 | P12: ธ2569/15453 | Q12: 58 | R12: 159794.61 | U12: =SUM(Q12) -> 58 | V12: =SUM(R12) -> 159794.61 | W12: =SUM(M12,Q12) -> 79 | X12: =SUM(N12,R12) -> 189994.61 | Z12: 342 | AA12: 11 มี.ค. 69
A13: 11 มี.ค. 69 | C13: 5 | D13: 8800 | G13: ธ2569/00859 | H13: ธ2569/00864 | I13: 6 | J13: 2400 | M13: =SUM(C13,I13) -> 11 | N13: =SUM(D13,J13) -> 11200 | O13: ธ2569/15454 | P13: ธ2569/15507 | Q13: 54 | R13: 134123.15 | U13: =SUM(Q13) -> 54 | V13: =SUM(R13) -> 134123.15 | W13: =SUM(M13,Q13) -> 65 | X13: =SUM(N13,R13) -> 145323.15 | Z13: 347 | AA13: 12 มี.ค. 69
A14: 12 มี.ค. 69 | C14: 23 | D14: 30250 | G14: ธ2569/00865 | H14: ธ2569/00869 | I14: 5 | J14: 1600 | M14: =SUM(C14,I14) -> 28 | N14: =SUM(D14,J14) -> 31850 | O14: ธ2569/15508 | P14: ธ2569/15561 | Q14: 54 | R14: 80697.98 | U14: =SUM(Q14) -> 54 | V14: =SUM(R14) -> 80697.98 | W14: =SUM(M14,Q14) -> 82 | X14: =SUM(N14,R14) -> 112547.98 | Z14: 352 | AA14: 13 มี.ค. 69
A15: 13 - 15 มี.ค. 69 | C15: 27 | D15: 38600 | G15: ธ2569/00870 | H15: ธ2569/00879 | I15: 10 | J15: 5000 | M15: =SUM(C15,I15) -> 37 | N15: =SUM(D15,J15) -> 43600 | O15: ธ2569/15562 | P15: ธ2569/15610 | Q15: 49 | R15: 70986.78 | U15: =SUM(Q15) -> 49 | V15: =SUM(R15) -> 70986.78 | W15: =SUM(M15,Q15) -> 86 | X15: =SUM(N15,R15) -> 114586.78 | Z15: 358 | AA15: 16 มี.ค. 69
A16: 16 มี.ค. 69 | C16: 12 | D16: 28200 | G16: ธ2569/00880 | H16: - | I16: 1 | J16: 500 | M16: =SUM(C16,I16) -> 13 | N16: =SUM(D16,J16) -> 28700 | O16: ธ2569/15611 | P16: ธ2569/15653 | Q16: 43 | R16: 58249.81 | U16: =SUM(Q16) -> 43 | V16: =SUM(R16) -> 58249.81 | W16: =SUM(M16,Q16) -> 56 | X16: =SUM(N16,R16) -> 86949.81 | Z16: 367 | AA16: 17 มี.ค. 69
A17: 17 มี.ค. 69 | C17: 3 | D17: 4200 | G17: ธ2569/00881 | H17: ธ2569/00906 | I17: 26 | J17: 5750 | M17: =SUM(C17,I17) -> 29 | N17: =SUM(D17,J17) -> 9950 | O17: ธ2569/15654 | P17: ธ2569/15692 | Q17: 39 | R17: 61344.35 | U17: =SUM(Q17) -> 39 | V17: =SUM(R17) -> 61344.35 | W17: =SUM(M17,Q17) -> 68 | X17: =SUM(N17,R17) -> 71294.35 | Z17: 375 | AA17: 18 มี.ค. 69
A18: 18 มี.ค. 69 | C18: 8 | D18: 9930 | G18: ธ2569/00907 | H18: ธ2569/00916 | I18: 10 | J18: 5200 | M18: =SUM(C18,I18) -> 18 | N18: =SUM(D18,J18) -> 15130 | O18: ธ2569/15693 | P18: ธ2569/15729 | Q18: 37 | R18: 58083.76 | U18: =SUM(Q18) -> 37 | V18: =SUM(R18) -> 58083.76 | W18: =SUM(M18,Q18) -> 55 | X18: =SUM(N18,R18) -> 73213.76 | Z18: 380 | AA18: 19 มี.ค. 69
A19: 19 มี.ค. 69 | C19: 3 | D19: 6200 | G19: ธ2569/00917 | H19: ธ2569/00922 | I19: 6 | J19: 2100 | M19: =SUM(C19,I19) -> 9 | N19: =SUM(D19,J19) -> 8300 | O19: ธ2569/15730 | P19: ธ2569/15760 | Q19: 31 | R19: 41919 | U19: =SUM(Q19) -> 31 | V19: =SUM(R19) -> 41919 | W19: =SUM(M19,Q19) -> 40 | X19: =SUM(N19,R19) -> 50219 | Z19: 386 | AA19: 20 มี.ค. 69
A20: 20 - 22 มี.ค. 69 | C20: 8 | D20: 9550 | G20: - | H20: - | I20: - | J20: - | M20: =SUM(C20,I20) -> 8 | N20: =SUM(D20,J20) -> 9550 | O20: ธ2569/15761 | P20: ธ2569/15805 | Q20: 45 | R20: 78555.62 | U20: =SUM(Q20) -> 45 | V20: =SUM(R20) -> 78555.62 | W20: =SUM(M20,Q20) -> 53 | X20: =SUM(N20,R20) -> 88105.62 | Z20: 394 | AA20: 23 มี.ค. 69
A21: 23 มี.ค. 69 | C21: - | D21: - | G21: ธ2569/00923 | H21: ธ2569/00924 | I21: 2 | J21: 1720 | M21: =SUM(C21,I21) -> 2 | N21: =SUM(D21,J21) -> 1720 | O21: ธ2569/15806 | P21: ธ2569/15854 | Q21: 49 | R21: 137743.2 | U21: =SUM(Q21) -> 49 | V21: =SUM(R21) -> 137743.2 | W21: =SUM(M21,Q21) -> 51 | X21: =SUM(N21,R21) -> 139463.2 | Z21: 399 | AA21: 24 มี.ค. 69
A22: 24 มี.ค. 69 | C22: 16 | D22: 27850 | G22: ธ2569/00925 | H22: ธ2569/00926 | I22: 2 | J22: 1100 | M22: =SUM(C22,I22) -> 18 | N22: =SUM(D22,J22) -> 28950 | O22: ธ2569/15855 | P22: ธ2569/15892 | Q22: 38 | R22: 84834.66 | U22: =SUM(Q22) -> 38 | V22: =SUM(R22) -> 84834.66 | W22: =SUM(M22,Q22) -> 56 | X22: =SUM(N22,R22) -> 113784.66 | Z22: 404 | AA22: 25 มี.ค. 69
A23: 25 มี.ค. 69 | C23: 7 | D23: 5150 | G23: ธ2569/00927 | H23: ธ2569/00932 | I23: 6 | J23: 2600 | M23: =SUM(C23,I23) -> 13 | N23: =SUM(D23,J23) -> 7750 | O23: ธ2569/15893 | P23: ธ2569/15940 | Q23: 48 | R23: 95244.12 | U23: =SUM(Q23) -> 48 | V23: =SUM(R23) -> 95244.12 | W23: =SUM(M23,Q23) -> 61 | X23: =SUM(N23,R23) -> 102994.12 | Z23: 410 | AA23: 26 มี.ค. 69
A24: 26 มี.ค. 69 | C24: 3 | D24: 1950 | G24: ธ2569/00933 | H24: ธ2569/00939 | I24: 7 | J24: 6200 | M24: =SUM(C24,I24) -> 10 | N24: =SUM(D24,J24) -> 8150 | O24: ธ2569/15941 | P24: ธ2569/15981 | Q24: 41 | R24: 63017.14 | W24: =SUM(M24,Q24) -> 51 | X24: =SUM(N24,R24) -> 71167.14 | Z24: 417 | AA24: 27 มี.ค. 69
A25: 27 - 29 มี.ค. 69 | C25: 9 | D25: 26700 | G25: ธ2569/00940 | H25: ธ2569/00963 | I25: 24 | J25: 6200 | M25: =SUM(C25,I25) -> 33 | N25: =SUM(D25,J25) -> 32900 | O25: ธ2569/15982 | P25: ธ2569/16035 | Q25: 54 | R25: 120302.23 | W25: =SUM(M25,Q25) -> 87 | X25: =SUM(N25,R25) -> 153202.23 | Z25: 424 | AA25: 30 มี.ค. 69
A26: 30 มี.ค. 69 | C26: 9 | D26: 17000 | G26: ธ2569/00964 | H26: - | I26: 1 | J26: 200 | M26: =SUM(C26,I26) -> 10 | N26: =SUM(D26,J26) -> 17200 | O26: ธ2569/16036 | P26: ธ2569/16074 | Q26: 39 | R26: 63105.75 | W26: =SUM(M26,Q26) -> 49 | X26: =SUM(N26,R26) -> 80305.75 | Z26: 431 | AA26: 31 มี.ค. 69
A27: 31 มี.ค. 69 | C27: 8 | D27: 10700 | G27: ธ2569/00965 | H27: - | I27: 1 | J27: 200 | M27: =SUM(C27,I27) -> 9 | N27: =SUM(D27,J27) -> 10900 | O27: ธ2569/16075 | P27: ธ2569/16166 | Q27: 92 | R27: 173674 | W27: =SUM(M27,Q27) -> 101 | X27: =SUM(N27,R27) -> 184574 | Z27: 437 | AA27: 1 เม.ย. 69
A28: รวม | C28: =SUM(C6:C27) -> 250 | D28: =SUM(D6:D27) -> 366300 | E28: =SUM(E6:E23) -> 0 | F28: =SUM(F6:F23) -> 0 | G28: รวม | I28: =SUM(I6:I27) -> 133 | J28: =SUM(J6:J27) -> 53520 | K28: =SUM(K6:K23) -> 0 | M28: =SUM(M6:M27) -> 383 | N28: =SUM(N6:N27) -> 419820 | O28: รวม | Q28: =SUM(Q6:Q27) -> 1709 | R28: =SUM(R6:R27) -> 3840492.6 | S28: =SUM(S6:S23) -> 0 | T28: =SUM(T6:T23) -> 0 | U28: =SUM(U6:U23) -> 1483 | V28: =SUM(V6:V23) -> 3420393.5 | W28: =SUM(W6:W27) -> 2092 | X28: =SUM(X6:X27) -> 4260312.7

Sheet เม.ย.69
A1: รายงานการรับชำระค่าธรรมเนียมผ่านธนาคาร เดือน เมษายน 2569
A3: วันที่ชำระ | B3: ข้อมูลกฎหมาย | C3: ระบบ Safety | G3: ระบบ Receipt (ใบเสร็จรับเงิน A4) | M3: รวมพรบ.42 (Safety + Receipt) | O3: ระบบ Trade | U3: รวมพรบ.2543 (Trade) | W3: นำรายได้ ส่ง คพ. พรบ.42 + พรบ.43 | Y3: หมายเหตุ | Z3: พน0401.1/ | AA3: วันที่ส่ง
B4: กฎหมาย | C4: จำนวนใบเสร็จ | D4: จำนวนเงิน | E4: ยกเลิกใบเสร็จ | G4: จาก | H4: ถึง | I4: จำนวนใบเสร็จ | J4: จำนวนเงิน | K4: ยกเลิก/ใบเสร็จเสีย | M4: รวมจำนวนใบเสร็จ | N4: รวมจำนวนเงิน | O4: จาก | P4: ถึง | Q4: จำนวนใบเสร็จ | R4: จำนวนเงิน | S4: ยกเลิกใบเสร็จ | U4: รวมจำนวนใบเสร็จ | V4: รวมจำนวนเงิน | W4: รวมจำนวนใบเสร็จ | X4: รวมจำนวนเงิน
E5: จำนวนใบเสร็จ | F5: เลขที่ใบเสร็จ | K5: จำนวนใบเสร็จ | L5: เลขที่ใบเสร็จ | S5: จำนวนใบเสร็จ | T5: เลขที่ใบเสร็จ
A6: 1 เม.ย. 69 | C6: 3 | D6: 9900 | G6: ธ2569/00966 | H6: ธ2569/00968 | I6: 3 | J6: 1200 | M6: =SUM(C6,I6) -> 6 | N6: =SUM(D6,J6) -> 11100 | O6: ธ69/16167 | P6: ธ69/16210 | Q6: 44 | R6: 81599.5 | U6: =SUM(Q6) -> 44 | V6: =SUM(R6) -> 81599.5 | W6: =SUM(M6,Q6) -> 50 | X6: =SUM(N6,R6) -> 92699.5 | Z6: 444 | AA6: 2 เม.ย.69
A7: 2 เม.ย. 69 | C7: 10 | D7: 29380 | G7: ธ2569/00969 | H7: ธ2569/00972 | I7: 4 | J7: 1950 | M7: =SUM(C7,I7) -> 14 | N7: =SUM(D7,J7) -> 31330 | O7: ธ69/16211 | P7: ธ69/16259 | Q7: 49 | R7: 79030.9 | U7: =SUM(Q7) -> 49 | V7: =SUM(R7) -> 79030.9 | W7: =SUM(M7,Q7) -> 63 | X7: =SUM(N7,R7) -> 110360.9 | Z7: 451 | AA7: 3 เม.ย.69
A8: 3 - 6 เม.ย. 69 | C8: 17 | D8: 29780 | G8: ธ2569/00973 | H8: ธ2569/00986 | I8: 14 | J8: 6300 | M8: =SUM(C8,I8) -> 31 | N8: =SUM(D8,J8) -> 36080 | O8: ธ69/16260 | P8: ธ2569/163 | Q8: 58 | R8: 120250.1 | U8: =SUM(Q8) -> 58 | V8: =SUM(R8) -> 120250.1 | W8: =SUM(M8,Q8) -> 89 | X8: =SUM(N8,R8) -> 156330.1 | Z8: 457 | AA8: 7 เม.ย.69
A9: 7 เม.ย. 69 | C9: 7 | D9: 730400 | G9: ธ2569/00987 | H9: ธ2569/00989 | I9: 3 | J9: 1500 | M9: =SUM(C9,I9) -> 10 | N9: =SUM(D9,J9) -> 731900 | O9: ธ69/16318 | P9: ธ69/16369 | Q9: 52 | R9: 103869.2 | U9: =SUM(Q9) -> 52 | V9: =SUM(R9) -> 103869.2 | W9: =SUM(M9,Q9) -> 62 | X9: =SUM(N9,R9) -> 835769.2 | Z9: 463 | AA9: 8 เม.ย.69
A10: 8 เม.ย. 69 | C10: 20 | D10: 57840 | G10: ธ2569/00990 | H10: ธ2569/00997 | I10: 8 | J10: 2500 | M10: =SUM(C10,I10) -> 28 | N10: =SUM(D10,J10) -> 60340 | O10: ธ69/16370 | P10: ธ69/16455 | Q10: 86 | R10: 181451 | U10: =SUM(Q10) -> 86 | V10: =SUM(R10) -> 181451 | W10: =SUM(M10,Q10) -> 114 | X10: =SUM(N10,R10) -> 241791 | Z10: 469 | AA10: 9 เม.ย.69
A11: 9 เม.ย. 69 | C11: 18 | D11: 185760 | G11: ธ2569/00998 | H11: ธ2569/01004 | I11: 7 | J11: 1700 | M11: =SUM(C11,I11) -> 25 | N11: =SUM(D11,J11) -> 187460 | O11: ธ69/16456 | P11: ธ69/16516 | Q11: 61 | R11: 96290.6 | U11: =SUM(Q11) -> 61 | V11: =SUM(R11) -> 96290.6 | W11: =SUM(M11,Q11) -> 86 | X11: =SUM(N11,R11) -> 283750.6 | Z11: 477 | AA11: 10 เม.ย.69
A12: 10 - 15 เม.ย. 69 | C12: 23 | D12: 13900 | G12: ธ2569/01005 | H12: ธ2569/01008 | I12: 4 | J12: 1700 | M12: =SUM(C12,I12) -> 27 | N12: =SUM(D12,J12) -> 15600 | O12: ธ69/16517 | P12: ธ69/16574 | Q12: 58 | R12: 85959.8 | U12: =SUM(Q12) -> 58 | V12: =SUM(R12) -> 85959.8 | W12: =SUM(M12,Q12) -> 85 | X12: =SUM(N12,R12) -> 101559.8 | Z12: 484 | AA12: 16 เม.ย.69
A13: 16 เม.ย. 69 | C13: 3 | D13: 9340 | G13: ธ2569/01009 | H13: - | I13: 1 | J13: 200 | M13: =SUM(C13,I13) -> 4 | N13: =SUM(D13,J13) -> 9540 | O13: ธ69/16575 | P13: ธ69/16630 | Q13: 56 | R13: 94731.8 | U13: =SUM(Q13) -> 56 | V13: =SUM(R13) -> 94731.8 | W13: =SUM(M13,Q13) -> 60 | X13: =SUM(N13,R13) -> 104271.8 | Z13: 490 | AA13: 17 เม.ย.69
A14: 17 - 19 เม.ย. 69 | C14: 2 | D14: 4650 | G14: ธ2569/01010 | H14: ธ2569/01013 | I14: 4 | J14: 1400 | M14: =SUM(C14,I14) -> 6 | N14: =SUM(D14,J14) -> 6050 | O14: ธ69/16631 | P14: ธ69/16716 | Q14: 86 | R14: 162441.6 | U14: =SUM(Q14) -> 86 | V14: =SUM(R14) -> 162441.6 | W14: =SUM(M14,Q14) -> 92 | X14: =SUM(N14,R14) -> 168491.6 | Z14: 498 | AA14: 20 เม.ย.69
A15: 20 เม.ย. 69 | C15: 11 | D15: 15700 | G15: ธ2569/01014 | H15: ธ2569/01016 | I15: 3 | J15: 1200 | M15: =SUM(C15,I15) -> 14 | N15: =SUM(D15,J15) -> 16900 | O15: ธ69/16717 | P15: ธ69/16795 | Q15: 79 | R15: 158215 | U15: =SUM(Q15) -> 79 | V15: =SUM(R15) -> 158215 | W15: =SUM(M15,Q15) -> 93 | X15: =SUM(N15,R15) -> 175115 | Z15: 505 | AA15: 21 เม.ย.69
A16: 21 เม.ย. 69 | C16: 10 | D16: 11050 | G16: ธ2569/01017 | H16: ธ2569/01019 | I16: 3 | J16: 2800 | M16: =SUM(C16,I16) -> 13 | N16: =SUM(D16,J16) -> 13850 | O16: ธ69/16796 | P16: ธ69/16855 | Q16: 60 | R16: 194567.2 | U16: =SUM(Q16) -> 60 | V16: =SUM(R16) -> 194567.2 | W16: =SUM(M16,Q16) -> 73 | X16: =SUM(N16,R16) -> 208417.2 | Z16: 511 | AA16: 22 เม.ย. 69
A17: 22 เม.ย. 69 | C17: 2 | D17: 1000 | G17: ธ2569/01020 | H17: ธ2569/01030 | I17: 11 | J17: 5700 | M17: =SUM(C17,I17) -> 13 | N17: =SUM(D17,J17) -> 6700 | O17: ธ69/16856 | P17: ธ69/16916 | Q17: 61 | R17: 101732 | U17: =SUM(Q17) -> 61 | V17: =SUM(R17) -> 101732 | W17: =SUM(M17,Q17) -> 74 | X17: =SUM(N17,R17) -> 108432 | Z17: 518 | AA17: 23 เม.ย. 69
... A23: 30 เม.ย. 69 | C23: 9 | D23: 16890 | G23: ธ2569/01050 | H23: ธ2569/01056 | I23: 7 | J23: 4500 | M23: =SUM(C23,I23) -> 16 | N23: =SUM(D23,J23) -> 21390 | O23: ธ69/17298 | P23: ธ69/17386 | Q23: 89 | R23: 160273 | U23: =SUM(Q23) -> 89 | V23: =SUM(R23) -> 160273 | W23: =SUM(M23,Q23) -> 105 | X23: =SUM(N23,R23) -> 181663 | Z23: 555 | AA23: 1 พ.ค. 69
A24: รวม | C24: =SUM(C6:C23) -> 164 | D24: =SUM(D6:D23) -> 1145510 | E24: =SUM(E6:E23) -> 0 | F24: =SUM(F6:F23) -> 0 | G24: รวม | I24: =SUM(I6:I23) -> 91 | J24: =SUM(J6:J23) -> 39450 | K24: =SUM(K6:K23) -> 0 | M24: =SUM(M6:M23) -> 255 | N24: =SUM(N6:N23) -> 1184960 | O24: รวม | Q24: =SUM(Q6:Q23) -> 1220 | R24: =SUM(R6:R23) -> 2349618.3 | S24: =SUM(S6:S23) -> 0 | T24: =SUM(T6:T23) -> 0 | U24: =SUM(U6:U23) -> 1220 | V24: =SUM(V6:V23) -> 2349618.3 | W24: =SUM(W6:W23) -> 1475 | X24: =SUM(X6:X23) -> 3534578.3

Sheet พ.ค.69
A1: รายงานการรับชำระค่าธรรมเนียมผ่านธนาคาร เดือน พฤษภาคม 2569
A3: วันที่ชำระ | B3: ข้อมูลกฎหมาย | C3: ระบบ Safety | G3: ระบบ Receipt (ใบเสร็จรับเงิน A4) | M3: รวมพรบ.42 (Safety + Receipt) | O3: ระบบ Trade | U3: รวมพรบ.2543 (Trade) | W3: นำรายได้ ส่ง คพ. พรบ.42 + พรบ.43 | Y3: หมายเหตุ | Z3: พน0401.1/ | AA3: วันที่ส่ง
B4: กฎหมาย | C4: จำนวนใบเสร็จ | D4: จำนวนเงิน | E4: ยกเลิกใบเสร็จ | G4: จาก | H4: ถึง | I4: จำนวนใบเสร็จ | J4: จำนวนเงิน | K4: ยกเลิก/ใบเสร็จเสีย | M4: รวมจำนวนใบเสร็จ | N4: รวมจำนวนเงิน | O4: จาก | P4: ถึง | Q4: จำนวนใบเสร็จ | R4: จำนวนเงิน | S4: ยกเลิกใบเสร็จ | U4: รวมจำนวนใบเสร็จ | V4: รวมจำนวนเงิน | W4: รวมจำนวนใบเสร็จ | X4: รวมจำนวนเงิน
E5: จำนวนใบเสร็จ | F5: เลขที่ใบเสร็จ | K5: จำนวนใบเสร็จ | L5: เลขที่ใบเสร็จ | S5: จำนวนใบเสร็จ | T5: เลขที่ใบเสร็จ
A6: 1 - 4 พ.ค. 69 | C6: 11 | D6: 10650 | G6: ธ2569/01057 | H6: ธ2569/01058 | I6: 2 | J6: 1000 | M6: =SUM(C6,I6) -> 13 | N6: =SUM(D6,J6) -> 11650 | O6: ธ69/17387 | P6: ธ69/17430 | Q6: 44 | R6: 93314.95 | U6: =SUM(Q6) -> 44 | V6: =SUM(R6) -> 93314.95 | W6: =SUM(M6,Q6) -> 57 | X6: =SUM(N6,R6) -> 104964.95 | Z6: 562 | AA6: 5 พ.ค. 69
A7: 5 พ.ค. 69 | C7: 9 | D7: 387880 | G7: ธ2569/01059 | H7: ธ2569/01085 | I7: 27 | J7: 6100 | M7: =SUM(C7,I7) -> 36 | N7: =SUM(D7,J7) -> 393980 | O7: ธ69/17431 | P7: ธ69/17486 | Q7: 56 | R7: 112243.03 | U7: =SUM(Q7) -> 56 | V7: =SUM(R7) -> 112243.03 | W7: =SUM(M7,Q7) -> 92 | X7: =SUM(N7,R7) -> 506223.03 | Z7: 570 | AA7: 6 พ.ค. 69
A8: 6 พ.ค. 69 | C8: 10 | D8: 36600 | G8: ธ2569/01086 | H8: ธ2569/01090 | I8: 5 | J8: 1000 | M8: =SUM(C8,I8) -> 15 | N8: =SUM(D8,J8) -> 37600 | O8: ธ69/17487 | P8: ธ69/17547 | Q8: 61 | R8: 97947.23 | U8: =SUM(Q8) -> 61 | V8: =SUM(R8) -> 97947.23 | W8: =SUM(M8,Q8) -> 76 | X8: =SUM(N8,R8) -> 135547.23 | Z8: 577 | AA8: 7 พ.ค. 69
A9: 7 พ.ค. 69 | C9: 2 | D9: 40880 | G9: - | H9: - | I9: - | J9: - | M9: =SUM(C9,I9) -> 2 | N9: =SUM(D9,J9) -> 40880 | O9: ธ69/17548 | P9: ธ69/17602 | Q9: 55 | R9: 89238.18 | U9: =SUM(Q9) -> 55 | V9: =SUM(R9) -> 89238.18 | W9: =SUM(M9,Q9) -> 57 | X9: =SUM(N9,R9) -> 130118.18 | Z9: 584 | AA9: 8 พ.ค. 69
A10: 8 - 10 พ.ค. 69 | C10: 5 | D10: 3900 | G10: ธ2569/01091 | H10: - | I10: 1 | J10: 200 | M10: =SUM(C10,I10) -> 6 | N10: =SUM(D10,J10) -> 4100 | O10: ธ69/17603 | P10: ธ69/17677 | Q10: 75 | R10: 129831.57 | U10: =SUM(Q10) -> 75 | V10: =SUM(R10) -> 129831.57 | W10: =SUM(M10,Q10) -> 81 | X10: =SUM(N10,R10) -> 133931.57 | Z10: 592 | AA10: 11 พ.ค. 69
A11: 11 พ.ค. 69 | C11: 4 | D11: 2400 | G11: ธ2569/01092 | H11: ธ2569/01093 | I11: 2 | J11: 400 | M11: =SUM(C11,I11) -> 6 | N11: =SUM(D11,J11) -> 2800 | O11: ธ69/17678 | P11: ธ69/17732 | Q11: 55 | R11: 81388.06 | U11: =SUM(Q11) -> 55 | V11: =SUM(R11) -> 81388.06 | W11: =SUM(M11,Q11) -> 61 | X11: =SUM(N11,R11) -> 84188.06 | Z11: 598 | AA11: 12 พ.ค. 69
A12: 12 - 13 พ.ค. 69 | C12: 6 | D12: 6740 | G12: ธ2569/01094 | H12: ธ2569/01099 | I12: 6 | J12: 5200 | M12: =SUM(C12,I12) -> 12 | N12: =SUM(D12,J12) -> 11940 | O12: ธ69/17733 | P12: ธ69/17787 | Q12: 55 | R12: 88429.75 | U12: =SUM(Q12) -> 55 | V12: =SUM(R12) -> 88429.75 | W12: =SUM(M12,Q12) -> 67 | X12: =SUM(N12,R12) -> 100369.75 | Z12: 603 | AA12: 14 พ.ค. 69
