Workbook

Sheet ต.ค.68
A1: รายงานการรับชำระค่าธรรมเนียมผ่านไปรษณีย์ เดือน ตุลาคม 2568
A3: วันที่ชำระ | B3: ข้อมูลกฎหมาย | C3: ระบบ Receipt (ใบเสร็จรับเงิน A4) | I3: ระบบ App (ใบเสร็จรับเงิน A5) | Q3: ระบบ Trade | W3: นำรายได้ ส่ง กค. พรบ.42 + พรบ.43 | Y3: หมายเหตุ | Z3: พน0401.1/ | AA3: วันที่ส่ง
B4: กฎหมาย | C4: จาก | D4: ถึง | E4: จำนวนใบเสร็จ | F4: จำนวนเงิน | G4: ยกเลิก/ใบเสร็จเสีย | I4: หมายเลขเล่ม | K4: จาก | L4: ถึง | M4: จำนวนใบเสร็จ | N4: จำนวนเงิน | O4: ยกเลิก/ใบเสร็จเสีย | Q4: จาก | R4: ถึง | S4: จำนวนใบเสร็จ | T4: จำนวนเงิน | U4: ยกเลิกใบเสร็จ | W4: รวมจำนวนใบเสร็จ | X4: รวมจำนวนเงิน
G5: จำนวนใบเสร็จ | H5: เลขที่ใบเสร็จ | O5: จำนวนใบเสร็จ | P5: เลขที่ใบเสร็จ | U5: จำนวนใบเสร็จ | V5: เลขที่ใบเสร็จ
A6: 1-2 ต.ค. 68 | C6: ป 2569/00003 | D6: ป 2569/00011 | E6: 8 | F6: 3720 | G6: 1 | H6: ป 2569/00004 | Q6: ป 69/00009 | R6: ป 69/00019 | S6: 11 | T6: 17892.61 | W6: =SUM(E6,S6) -> 19 | X6: =SUM(F6,T6) -> 21612.61 | Z6: 1795 | AA6: 3 ต.ค. 68
A7: 3-5 ต.ค. 68 | C7: ป 2569/00012 | D7: - | E7: 1 | F7: 700 | Q7: ป 69/00020 | R7: ป 69/00022 | S7: 3 | T7: 7399.67 | W7: =SUM(E7,S7) -> 4 | X7: =SUM(F7,T7) -> 8099.67 | Z7: 1715 | AA7: 6 ต.ค. 68
A8: 6 ต.ค. 68 | C8: - | D8: - | E8: - | F8: - | Q8: ป 69/00023 | R8: - | S8: 1 | T8: 1215.81 | W8: =SUM(E8,S8) -> 1 | X8: =SUM(F8,T8) -> 1215.81 | Z8: 1722 | AA8: 7 ต.ค. 68
A9: 7 ต.ค. 68 | C9: ป 2569/00013 | D9: ป 2569/00014 | E9: 2 | F9: 2960 | Q9: ป 69/00024 | R9: - | S9: 1 | T9: 1216.77 | W9: =SUM(E9,S9) -> 3 | X9: =SUM(F9,T9) -> 4176.77 | Z9: 1728 | AA9: 8 ต.ค. 68
A10: 8 ต.ค. 68 | C10: ป 2569/00015 | D10: - | E10: 1 | F10: 500 | Q10: ป 69/00025 | R10: ป 69/00027 | S10: 3 | T10: 8904.22 | W10: =SUM(E10,S10) -> 4 | X10: =SUM(F10,T10) -> 9404.22 | Z10: 1735 | AA10: 9 ต.ค. 68
A11: 9 ต.ค. 68 | C11: - | D11: - | E11: - | F11: - | Q11: ป 69/00028 | R11: - | S11: 1 | T11: 1218.71 | W11: =SUM(E11,S11) -> 1 | X11: =SUM(F11,T11) -> 1218.71 | Z11: 1741 | AA11: 10 ต.ค. 68
A12: 10-13 ต.ค. 68 | C12: ป 2569/00016 | E12: 1 | F12: 200 | Q12: ป 69/00029 | R12: - | S12: 1 | T12: 1579.68 | W12: =SUM(E12,S12) -> 2 | X12: =SUM(F12,T12) -> 1779.68 | Z12: 1749 | AA12: 14 ต.ค. 68
A13: 14 ต.ค. 68 | C13: - | D13: - | E13: - | F13: - | Q13: ป 69/00030 | R13: ป 69/00032 | S13: 3 | T13: 4030.65 | W13: =SUM(E13,S13) -> 3 | X13: =SUM(F13,T13) -> 4030.65 | Z13: 1755 | AA13: 15 ต.ค. 68
A14: 15 ต.ค. 68 | C14: ป 2569/00017 | D14: ป 2569/00019 | E14: 3 | F14: 900 | Q14: ป 69/00033 | S14: 1 | T14: 200 | W14: =SUM(E14,S14) -> 4 | X14: =SUM(F14,T14) -> 1100 | Z14: 1761 | AA14: 16 ต.ค. 68
A15: 16 ต.ค. 68 | C15: ป 2569/00020 | D15: - | E15: 1 | F15: 620 | Q15: ป 69/00034 | S15: 1 | T15: 1225.48 | W15: =SUM(E15,S15) -> 2 | X15: =SUM(F15,T15) -> 1845.48 | Z15: 1770 | AA15: 17 ต.ค. 68
A16: 17-19 ต.ค. 68 | C16: ป 2569/00021 | D16: ป 2569/00023 | E16: 3 | F16: 4300 | Q16: - | R16: - | S16: - | T16: - | W16: =SUM(E16,S16) -> 3 | X16: =SUM(F16,T16) -> 4300 | Z16: 1774 | AA16: 20 ต.ค. 68
A17: 20 ต.ค. 68 | C17: - | D17: - | E17: - | F17: - | Q17: ป 69/00035 | R17: ป 69/00038 | S17: 4 | T17: 8974.28 | W17: =SUM(E17,S17) -> 4 | X17: =SUM(F17,T17) -> 8974.28 | Z17: 1780 | AA17: 21 ต.ค. 68
A18: 21 ต.ค. 68 | C18: ป 2569/00024 | D18: - | E18: 1 | F18: 200 | Q18: ป 69/00039 | R18: ป 69/00040 | S18: 2 | T18: 2030.32 | W18: =SUM(E18,S18) -> 3 | X18: =SUM(F18,T18) -> 2230.32 | Z18: 1787 | AA18: 22 ต.ค. 68
A19: 22-23 ต.ค. 68 | C19: - | D19: - | E19: - | F19: - | Q19: ป 69/00041 | R19: ป 69/00045 | S19: 5 | T19: 8988.42 | W19: =SUM(E19,S19) -> 5 | X19: =SUM(F19,T19) -> 8988.42 | Z19: 1795 | AA19: 24 ต.ค. 68
A20: 24-26ต.ค. 68 | C20: ป 2569/00025 | D20: ป 2569/00026 | E20: 2 | F20: 900 | Q20: ป 69/00046 | R20: ป 69/00051 | S20: 6 | T20: 8266.15 | W20: =SUM(E20,S20) -> 8 | X20: =SUM(F20,T20) -> 9166.15 | Z20: 1802 | AA20: 27 ต.ค. 68
A21: 27 ต.ค. 68 | C21: ป 2569/00027 | D21: ป 2569/00028 | E21: 2 | F21: 700 | Q21: - | R21: - | S21: - | T21: - | W21: =SUM(E21,S21) -> 2 | X21: =SUM(F21,T21) -> 700 | Z21: 1808 | AA21: 28 ต.ค. 69
A22: 28 ต.ค. 68 | C22: ป 2569/00029 | D22: - | E22: 1 | F22: 600 | Q22: - | R22: - | S22: - | T22: - | W22: =SUM(E22,S22) -> 1 | X22: =SUM(F22,T22) -> 600 | Z22: 1815 | AA22: 29 ต.ค. 69
A23: 29 ต.ค. 68 | C23: ป 2569/00030 | D23: - | E23: 1 | F23: 200 | Q23: ป 69/00052 | R23: - | S23: 1 | T23: 1238.06 | W23: =SUM(E23,S23) -> 2 | X23: =SUM(F23,T23) -> 1438.06 | Z23: 1822 | AA23: 30 ต.ค. 69
A24: 30 ต.ค. 68 | C24: ป 2569/00031 | D24: ป 2569/00033 | E24: 3 | F24: 600 | Q24: ป 69/00053 | R24: ป 69/00055 | S24: 3 | T24: 5080.03 | W24: =SUM(E24,S24) -> 6 | X24: =SUM(F24,T24) -> 5680.03 | Z24: 1830 | AA24: 31 ต.ค. 69
A25: 31 ต.ค. 68 | W25: =SUM(E25,S25) -> 0 | X25: =SUM(F25,T25) -> 0
A26: รวม | E26: =SUM(E6:E25) -> 30 | F26: =SUM(F6:F25) -> 17100 | I26: รวม | Q26: รวม | S26: =SUM(S6:S25) -> 47 | T26: =SUM(T6:T25) -> 79460.86 | U26: =SUM(U6:U25) -> 0 | V26: =SUM(V6:V25) -> 0 | W26: =SUM(W6:W25) -> 77 | X26: =SUM(X6:X25) -> 96560.86

Sheet พ.ย.68
A1: รายงานการรับชำระค่าธรรมเนียมผ่านไปรษณีย์ เดือน พฤศจิกายน 2568
A3: วันที่ชำระ | B3: ข้อมูลกฎหมาย | C3: ระบบ Receipt (ใบเสร็จรับเงิน A4) | I3: ระบบ App (ใบเสร็จรับเงิน A5) | Q3: ระบบ Trade | W3: นำรายได้ ส่ง กค. พรบ.42 + พรบ.43 | Y3: หมายเหตุ | Z3: พน0401.1/ | AA3: วันที่ส่ง
B4: กฎหมาย | C4: จาก | D4: ถึง | E4: จำนวนใบเสร็จ | F4: จำนวนเงิน | G4: ยกเลิก/ใบเสร็จเสีย | I4: หมายเลขเล่ม | K4: จาก | L4: ถึง | M4: จำนวนใบเสร็จ | N4: จำนวนเงิน | O4: ยกเลิก/ใบเสร็จเสีย | Q4: จาก | R4: ถึง | S4: จำนวนใบเสร็จ | T4: จำนวนเงิน | U4: ยกเลิกใบเสร็จ | W4: รวมจำนวนใบเสร็จ | X4: รวมจำนวนเงิน
G5: จำนวนใบเสร็จ | H5: เลขที่ใบเสร็จ | O5: จำนวนใบเสร็จ | P5: เลขที่ใบเสร็จ | U5: จำนวนใบเสร็จ | V5: เลขที่ใบเสร็จ
A6: 31 ต.ค.-2 พ.ย. 68 | C6: - | D6: - | E6: - | F6: - | Q6: ป 69/00056 | R6: ป 69/00057 | S6: 2 | T6: 5148 | W6: =SUM(E6,S6) -> 2 | X6: =SUM(F6,T6) -> 5148 | Z6: 1841 | AA6: 3 พ.ย. 68
A7: 3 พ.ย. 68 | C7: ป 2569/00038 | D7: ป 2569/00041 | E7: 4 | F7: 1400 | G7: 4 | H7: ป 2569/00034 - 00037 | Q7: - | R7: - | S7: - | T7: - | W7: =SUM(E7,S7) -> 4 | X7: =SUM(F7,T7) -> 1400 | Z7: 1847 | AA7: 4 พ.ย. 68
A8: 4 พ.ย. 68 | C8: - | D8: - | E8: - | F8: - | Q8: ป 69/00058 | R8: ป 69/00059 | S8: 2 | T8: 3704 | W8: =SUM(E8,S8) -> 2 | X8: =SUM(F8,T8) -> 3704 | Z8: 1855 | AA8: 5 พ.ย. 68
A9: 5 พ.ย. 68 | C9: - | D9: - | E9: - | F9: - | Q9: - | R9: - | S9: - | T9: - | W9: =SUM(E9,S9) -> 0 | X9: =SUM(F9,T9) -> 0 | Z9: 1862 | AA9: 6 พ.ย. 68
A10: 6 พ.ย. 68 | C10: ป 2569/00042 | D10: ป 2569/00043 | E10: 2 | F10: 1100 | Q10: ป 69/00060 | R10: - | S10: 1 | T10: 1246 | W10: =SUM(E10,S10) -> 3 | X10: =SUM(F10,T10) -> 2346 | Z10: 1867 | AA10: 7 พ.ย. 68
A11: 7 - 9 พ.ย. 68 | C11: ป 2569/00044 | D11: - | E11: 1 | F11: 200 | Q11: ป 69/00061 | R11: ป 69/00062 | S11: 2 | T11: 2619.7 | W11: =SUM(E11,S11) -> 3 | X11: =SUM(F11,T11) -> 2819.7 | Z11: 1876 | AA11: 10 พ.ย. 68
A12: 10 พ.ย. 68 | C12: ป 2569/00045 | D12: ป 2569/00046 | E12: 2 | F12: 700 | Q12: ป 69/00063 | R12: - | S12: 1 | T12: 800 | W12: =SUM(E12,S12) -> 3 | X12: =SUM(F12,T12) -> 1500 | Z12: 1883 | AA12: 11 พ.ย. 68
A13: 11 พ.ย. 68 | C13: ป 2569/00047 | D13: - | E13: 1 | F13: 200 | Q13: ป 69/00064 | R13: ป 69/00065 | S13: 2 | T13: 2502 | W13: =SUM(E13,S13) -> 3 | X13: =SUM(F13,T13) -> 2702 | Z13: 1891 | AA13: 12 พ.ย. 68
A14: 12 พ.ย. 68 | C14: ป 2569/00048 | D14: ป 2569/00052 | E14: 5 | F14: 2250 | Q14: ป 69/00066 | R14: - | S14: 1 | T14: 1252 | W14: =SUM(E14,S14) -> 6 | X14: =SUM(F14,T14) -> 3502 | Z14: 1899 | AA14: 13 พ.ย. 68
A15: 13 พ.ย. 68 | C15: - | D15: - | E15: - | F15: - | Q15: ป 69/00067 | R15: ป 69/00068 | S15: 2 | T15: 2506 | W15: =SUM(E15,S15) -> 2 | X15: =SUM(F15,T15) -> 2506 | Z15: 1905 | AA15: 14 พ.ย. 68
A16: 14 - 16 พ.ย. 68 | C16: ป 2569/00053 | D16: ป 2569/00054 | E16: 2 | F16: 1720 | Q16: ป 69/00069 | R16: ป 69/00073 | S16: 5 | T16: 6630 | W16: =SUM(E16,S16) -> 7 | X16: =SUM(F16,T16) -> 8350 | Z16: 1909 | AA16: 17 พ.ย. 68
A17: 17 พ.ย. 68 | C17: ป 2569/00055 | D17: ป 2569/00056 | E17: 2 | F17: 400 | Q17: ป 69/00074 | R17: ป 69/00077 | S17: 4 | T17: 5748 | W17: =SUM(E17,S17) -> 6 | X17: =SUM(F17,T17) -> 6148 | Z17: 1917 | AA17: 18 พ.ย. 68
A18: 18 พ.ย. 68 | C18: ป 2569/00057 | D18: ป 2569/00060 | E18: 4 | F18: 1220 | Q18: - | R18: - | S18: - | T18: - | W18: =SUM(E18,S18) -> 4 | X18: =SUM(F18,T18) -> 1220 | Z18: 1925 | AA18: 19 พ.ย. 68
A19: 19 พ.ย. 68 | C19: ป 2569/00061 | D19: ป 2569/00063 | E19: 3 | F19: 600 | Q19: - | R19: - | S19: - | T19: - | W19: =SUM(E19,S19) -> 3 | X19: =SUM(F19,T19) -> 600 | Z19: 1933 | AA19: 20 พ.ย. 68
A20: 20 พ.ย. 68 | C20: ป 2569/00064 | D20: ป 2569/00066 | E20: 3 | F20: 900 | Q20: ป 69/00078 | R20: ป 69/00079 | S20: 2 | T20: 3402 | W20: =SUM(E20,S20) -> 5 | X20: =SUM(F20,T20) -> 4302 | Z20: 1940 | AA20: 21 พ.ย. 68
A21: 21 - 23 พ.ย. 68 | C21: ป 2569/00067 | D21: - | E21: 1 | F21: 2400 | Q21: ป 69/00080 | R21: - | S21: 1 | T21: 1262 | W21: =SUM(E21,S21) -> 2 | X21: =SUM(F21,T21) -> 3662 | Z21: 1948 | AA21: 24 พ.ย. 68
A22: 24 พ.ย. 68 | C22: - | D22: - | E22: - | F22: - | Q22: ป 69/00081 | S22: 1 | T22: 1264 | W22: =SUM(E22,S22) -> 1 | X22: =SUM(F22,T22) -> 1264 | Z22: 1954 | AA22: 25 พ.ย. 68
A23: 25 พ.ย. 68 | C23: - | D23: - | E23: - | F23: - | Q23: ป 69/00082 | R23: ป 69/00084 | S23: 3 | T23: 4000 | W23: =SUM(E23,S23) -> 3 | X23: =SUM(F23,T23) -> 4000 | Z23: 1963 | AA23: 26 พ.ย. 68
A24: 26 พ.ย. 68 | C24: ป 2569/00068 | D24: - | E24: 1 | F24: 1420 | Q24: - | R24: - | S24: - | T24: - | W24: =SUM(E24,S24) -> 1 | X24: =SUM(F24,T24) -> 1420 | Z24: 1969 | AA24: 27 พ.ย. 68
A25: 27 พ.ย. 68 | C25: ป 2569/00069 | E25: 1 | F25: 1200 | Q25: - | R25: - | S25: - | T25: - | W25: =SUM(E25,S25) -> 1 | X25: =SUM(F25,T25) -> 1200 | Z25: 1976 | AA25: 28 พ.ย. 68
A26: 28 - 30 พ.ย. 68 | C26: ป 2569/00070 | D26: ป 2569/00071 | E26: 2 | F26: 3920 | Q26: ป 69/00085 | R26: ป 69/00086 | S26: 2 | T26: 2896 | W26: =SUM(E26,S26) -> 4 | X26: =SUM(F26,T26) -> 6816 | Z26: 1988 | AA26: 2 ธ.ค. 68
A27: รวม | E27: =SUM(E6:E26) -> 34 | F27: =SUM(F6:F26) -> 19630 | I27: รวม | Q27: รวม | S27: =SUM(S6:S26) -> 31 | T27: =SUM(T6:T26) -> 44979.7 | U27: =SUM(U6:U25) -> 0 | V27: =SUM(V6:V25) -> 0 | W27: =SUM(W6:W26) -> 65 | X27: =SUM(X6:X26) -> 64609.7

Sheet ธ.ค. 68
A1: รายงานการรับชำระค่าธรรมเนียมผ่านไปรษณีย์ เดือน ธันวาคม 2568
A3: วันที่ชำระ | B3: ข้อมูลกฎหมาย | C3: ระบบ Receipt (ใบเสร็จรับเงิน A4) | I3: ระบบ App (ใบเสร็จรับเงิน A5) | Q3: ระบบ Trade | W3: นำรายได้ ส่ง กค. พรบ.42 + พรบ.43 | Y3: หมายเหตุ | Z3: พน0401.1/ | AA3: วันที่ส่ง
B4: กฎหมาย | C4: จาก | D4: ถึง | E4: จำนวนใบเสร็จ | F4: จำนวนเงิน | G4: ยกเลิก/ใบเสร็จเสีย | I4: หมายเลขเล่ม | K4: จาก | L4: ถึง | M4: จำนวนใบเสร็จ | N4: จำนวนเงิน | O4: ยกเลิก/ใบเสร็จเสีย | Q4: จาก | R4: ถึง | S4: จำนวนใบเสร็จ | T4: จำนวนเงิน | U4: ยกเลิกใบเสร็จ | W4: รวมจำนวนใบเสร็จ | X4: รวมจำนวนเงิน
G5: จำนวนใบเสร็จ | H5: เลขที่ใบเสร็จ | O5: จำนวนใบเสร็จ | P5: เลขที่ใบเสร็จ | U5: จำนวนใบเสร็จ | V5: เลขที่ใบเสร็จ
A6: 1 ธ.ค. 68 | C6: ป 2569/00072 | D6: - | E6: 1 | F6: 200 | Q6: ป 69/00087 | R6: - | S6: 1 | T6: 1700 | W6: =SUM(E6,S6) -> 2 | X6: =SUM(F6,T6) -> 1900 | Z6: 1989 | AA6: 2 ธ.ค. 68
A7: 2 ธ.ค. 68 | C7: ป 2569/00073 | D7: ป 2569/00076 | E7: 4 | F7: 2420 | Q7: ป 69/00088 | R7: ป 69/00100 | S7: 13 | T7: 19100 | W7: =SUM(E7,S7) -> 17 | X7: =SUM(F7,T7) -> 21520 | Z7: 1998 | AA7: 3 ธ.ค. 68
A8: 3 ธ.ค. 68 | C8: - | D8: - | E8: - | F8: - | Q8: ป 69/00101 | R8: ป 69/00130 | S8: 30 | T8: 43445.8 | W8: =SUM(E8,S8) -> 30 | X8: =SUM(F8,T8) -> 43445.8 | Z8: 2007 | AA8: 4 ธ.ค. 68
A9: 4 - 7 ธ.ค. 68 | C9: - | D9: - | E9: - | F9: - | Q9: ป 69/00131 | R9: ป 69/00155 | S9: 25 | T9: 35733.87 | W9: =SUM(E9,S9) -> 25 | X9: =SUM(F9,T9) -> 35733.87 | Z9: 2016 | AA9: 9 ธ.ค. 68
A10: 8 ธ.ค. 68 | C10: - | D10: - | E10: - | F10: - | Q10: ป 69/00156 | R10: ป 69/00223 | S10: 68 | T10: 97408.7 | W10: =SUM(E10,S10) -> 68 | X10: =SUM(F10,T10) -> 97408.7 | Z10: 2023 | AA10: 11 ธ.ค. 68
A11: 9 - 10 ธ.ค. 68 | C11: - | D11: - | E11: - | F11: - | Q11: ป 69/00224 | R11: ป 69/00284 | S11: 61 | T11: 87900 | W11: =SUM(E11,S11) -> 61 | X11: =SUM(F11,T11) -> 87900 | Z11: 2028 | AA11: 12 ธ.ค. 68
A12: 11 ธ.ค. 68 | C12: ป 2569/00077 | D12: - | E12: 1 | F12: 500 | Q12: ป 69/00285 | R12: ป 69/00328 | S12: 44 | T12: 64400 | W12: =SUM(E12,S12) -> 45 | X12: =SUM(F12,T12) -> 64900 | Z12: 2032 | AA12: 12 ธ.ค. 68
A13: 12 - 14 ธ.ค. 68 | C13: - | D13: - | E13: - | F13: - | Q13: ป 69/00329 | R13: ป 69/00402 | S13: 74 | T13: 106223.22 | W13: =SUM(E13,S13) -> 74 | X13: =SUM(F13,T13) -> 106223.22 | Z13: 2041 | AA13: 15 ธ.ค. 68
A14: 15 ธ.ค. 68 | C14: ป 2569/00078 | E14: 1 | F14: 1720 | Q14: ป 69/00403 | R14: ป 69/00458 | S14: 56 | T14: 80413.56 | W14: =SUM(E14,S14) -> 57 | X14: =SUM(F14,T14) -> 82133.56 | Z14: 2054 | AA14: 16 ธ.ค. 68
A15: 16 ธ.ค. 68 | C15: - | D15: - | E15: - | F15: - | Q15: ป 69/00459 | R15: ป 69/00503 | S15: 45 | T15: 62730.96 | W15: =SUM(E15,S15) -> 45 | X15: =SUM(F15,T15) -> 62730.96 | Z15: 2062 | AA15: 17 ธ.ค. 68
A16: 17 ธ.ค. 68 | C16: - | D16: - | E16: - | F16: - | Q16: ป 69/00504 | R16: ป 69/00540 | S16: 37 | T16: 41572.9 | W16: =SUM(E16,S16) -> 37 | X16: =SUM(F16,T16) -> 41572.9 | Z16: 2069 | AA16: 18 ธ.ค. 68
A17: 18 ธ.ค. 68 | C17: ป 2569/00079 | D17: ป 2569/00081 | E17: 3 | F17: 600 | Q17: ป 69/00541 | R17: ป 69/00594 | S17: 54 | T17: 70887.42 | W17: =SUM(E17,S17) -> 57 | X17: =SUM(F17,T17) -> 71487.42 | Z17: 2078 | AA17: 19 ธ.ค. 68
A18: 19 - 21 ธ.ค. 68 | C18: ป 2569/00082 | D18: ป 2569/00084 | E18: 3 | F18: 2040 | Q18: ป 69/00595 | R18: ป 69/00647 | S18: 53 | T18: 82500 | W18: =SUM(E18,S18) -> 56 | X18: =SUM(F18,T18) -> 84540 | Z18: 2083 | AA18: 22 ธ.ค. 68
A19: 22 ธ.ค. 68 | C19: ป 2569/00085 | D19: - | E19: 1 | F19: 1420 | Q19: ป 69/00648 | R19: ป 69/00697 | S19: 50 | T19: 64342.58 | W19: =SUM(E19,S19) -> 51 | X19: =SUM(F19,T19) -> 65762.58 | Z19: 2093 | AA19: 23 ธ.ค. 68
A20: 23 ธ.ค. 68 | C20: ป 2569/00086 | D20: ป 2569/00087 | E20: 2 | F20: 400 | Q20: ป 69/00698 | R20: ป 69/00742 | S20: 45 | T20: 63200 | W20: =SUM(E20,S20) -> 47 | X20: =SUM(F20,T20) -> 63600 | Z20: 2101 | AA20: 24 ธ.ค. 68
A21: 24 ธ.ค. 68 | C21: ป 2569/00088 | D21: ป 2569/00089 | E21: 2 | F21: 1220 | Q21: ป 69/00743 | R21: ป 69/00789 | S21: 47 | T21: 60559.35 | W21: =SUM(E21,S21) -> 49 | X21: =SUM(F21,T21) -> 61779.35 | Z21: 2110 | AA21: 25 ธ.ค. 68
A22: 25 ธ.ค. 68 | C22: ป 2569/00090 | D22: ป 2569/00093 | E22: 4 | F22: 4440 | Q22: ป 69/00790 | R22: ป 69/00817 | S22: 28 | T22: 46700 | W22: =SUM(E22,S22) -> 32 | X22: =SUM(F22,T22) -> 51140 | Z22: 2116 | AA22: 26 ธ.ค. 68
A23: 26 - 28 ธ.ค. 68 | C23: ป 2569/00094 | D23: ป 2569/00100 | E23: 7 | F23: 9510 | Q23: ป 69/00818 | R23: ป 69/00883 | S23: 66 | T23: 75552.26 | W23: =SUM(E23,S23) -> 73 | X23: =SUM(F23,T23) -> 85062.26 | Z23: 2127 | AA23: 29 ธ.ค. 68
A24: 29 ธ.ค. 68 | C24: ป 2569/00101 | D24: ป 2569/00106 | E24: 6 | F24: 8880 | Q24: ป 69/00884 | R24: ป 69/00928 | S24: 45 | T24: 55000 | W24: =SUM(E24,S24) -> 51 | X24: =SUM(F24,T24) -> 63880 | Z24: 2135 | AA24: 30 ธ.ค. 68
A25: รวม | E25: =SUM(E6:E24) -> 35 | F25: =SUM(F6:F24) -> 33350 | I25: รวม | Q25: รวม | S25: =SUM(S6:S24) -> 842 | T25: =SUM(T6:T24) -> 1159370.6 | U25: =SUM(U6:U24) -> 0 | V25: =SUM(V6:V24) -> 0 | W25: =SUM(W6:W24) -> 877 | X25: =SUM(X6:X24) -> 1192720.6

Sheet ม.ค. 69
A1: รายงานการรับชำระค่าธรรมเนียมผ่านไปรษณีย์ เดือน มกราคม 2569
A3: วันที่ชำระ | B3: ข้อมูลกฎหมาย | C3: ระบบ Receipt (ใบเสร็จรับเงิน A4) | I3: ระบบ App (ใบเสร็จรับเงิน A5) | Q3: ระบบ Trade | W3: นำรายได้ ส่ง กค. พรบ.42 + พรบ.43 | Y3: หมายเหตุ | Z3: พน0401.1/ | AA3: วันที่ส่ง
B4: กฎหมาย | C4: จาก | D4: ถึง | E4: จำนวนใบเสร็จ | F4: จำนวนเงิน | G4: ยกเลิก/ใบเสร็จเสีย | I4: หมายเลขเล่ม | K4: จาก | L4: ถึง | M4: จำนวนใบเสร็จ | N4: จำนวนเงิน | O4: ยกเลิก/ใบเสร็จเสีย | Q4: จาก | R4: ถึง | S4: จำนวนใบเสร็จ | T4: จำนวนเงิน | U4: ยกเลิกใบเสร็จ | W4: รวมจำนวนใบเสร็จ | X4: รวมจำนวนเงิน
G5: จำนวนใบเสร็จ | H5: เลขที่ใบเสร็จ | O5: จำนวนใบเสร็จ | P5: เลขที่ใบเสร็จ | U5: จำนวนใบเสร็จ | V5: เลขที่ใบเสร็จ
A6: 30 ธ.ค. 68 - 4 ม.ค. 69 | C6: ป 2569/00107 | D6: ป 2569/00111 | E6: 5 | F6: 2200 | Q6: ป 69/00929 | R6: ป 69/00973 | S6: 45 | T6: 56899.03 | W6: =SUM(E6,S6) -> 50 | X6: =SUM(F6,T6) -> 59099.03 | Z6: 3 | AA6: 5 ม.ค.69
A7: 5 ม.ค. 69 | C7: - | D7: - | E7: - | F7: - | Q7: ป 69/00974 | R7: ป 69/01059 | S7: 86 | T7: 113004.84 | W7: =SUM(E7,S7) -> 86 | X7: =SUM(F7,T7) -> 113004.84 | Z7: 13 | AA7: 6 ม.ค.69
A8: 6 ม.ค. 69 | C8: ป 2569/00112 | D8: ป 2569/00113 | E8: 2 | F8: 800 | Q8: ป 69/01060 | R8: ป 69/01138 | S8: 79 | T8: 109611.62 | W8: =SUM(E8,S8) -> 81 | X8: =SUM(F8,T8) -> 110411.62 | Z8: 19 | AA8: 7 ม.ค.69
A9: 7 ม.ค. 69 | C9: ป 2569/00114 | D9: - | E9: 1 | F9: 200 | Q9: ป 69/01139 | R9: ป 69/01205 | S9: 67 | T9: 113506.77 | W9: =SUM(E9,S9) -> 68 | X9: =SUM(F9,T9) -> 113706.77 | Z9: 25 | AA9: 8 ม.ค.69
A10: 8 ม.ค. 69 | C10: ป 2569/00115 | D10: ป 2569/00116 | E10: 2 | F10: 5500 | Q10: ป 69/01206 | R10: ป 69/01264 | S10: 59 | T10: 81800 | W10: =SUM(E10,S10) -> 61 | X10: =SUM(F10,T10) -> 87300 | Z10: 32 | AA10: 9 ม.ค.69
A11: 9 - 11 ม.ค. 69 | C11: ป 2569/00117 | D11: ป 2569/00119 | E11: 3 | F11: 1350 | Q11: ป 69/01265 | R11: ป 69/01312 | S11: 48 | T11: 88200 | W11: =SUM(E11,S11) -> 51 | X11: =SUM(F11,T11) -> 89550 | Z11: 39 | AA11: 12 ม.ค.69
A12: 12 ม.ค. 69 | C12: ป 2569/00120 | D12: - | E12: 1 | F12: 1620 | Q12: ป 69/01313 | R12: ป 69/01362 | S12: 50 | T12: 87323.22 | W12: =SUM(E12,S12) -> 51 | X12: =SUM(F12,T12) -> 88943.22 | Z12: 46 | AA12: 13 ม.ค.69
A13: 13 ม.ค. 69 | C13: - | D13: - | E13: - | F13: - | Q13: ป 69/01363 | R13: ป 69/01418 | S13: 56 | T13: 74000 | W13: =SUM(E13,S13) -> 56 | X13: =SUM(F13,T13) -> 74000 | Z13: 56 | AA13: 14 ม.ค.69
A14: 14 ม.ค. 69 | C14: ป 2569/00121 | D14: - | E14: 1 | F14: 2500 | Q14: ป 69/01419 | R14: ป 69/01470 | S14: 52 | T14: 61913.55 | W14: =SUM(E14,S14) -> 53 | X14: =SUM(F14,T14) -> 64413.55 | Z14: 63 | AA14: 15 ม.ค.69
A15: 15 ม.ค. 69 | C15: - | D15: - | E15: - | F15: - | Q15: ป 69/01471 | R15: ป 69/01509 | S15: 39 | T15: 42500 | W15: =SUM(E15,S15) -> 39 | X15: =SUM(F15,T15) -> 42500 | Z15: 68 | AA15: 16 ม.ค.69
A16: 16 - 18 ม.ค. 69 | C16: - | D16: - | E16: - | F16: - | Q16: ป 69/01510 | R16: ป 69/01546 | S16: 37 | T16: 45816.45 | W16: =SUM(E16,S16) -> 37 | X16: =SUM(F16,T16) -> 45816.45 | Z16: 78 | AA16: 19 ม.ค.69
A17: 19 ม.ค. 69 | C17: - | D17: - | E17: - | F17: - | Q17: ป 69/01547 | R17: ป 69/01603 | S17: 57 | T17: 64718.39 | W17: =SUM(E17,S17) -> 57 | X17: =SUM(F17,T17) -> 64718.39 | Z17: 82 | AA17: 20 ม.ค.69
A18: 20 ม.ค. 69 | C18: ป 2569/00122 | D18: ป 2569/00123 | E18: 2 | F18: 2320 | Q18: ป 69/01604 | R18: ป 69/01662 | S18: 59 | T18: 109419.35 | W18: =SUM(E18,S18) -> 61 | X18: =SUM(F18,T18) -> 111739.35 | Z18: 94 | AA18: 21 ม.ค.69
A19: 21 ม.ค. 69 | C19: ป 2569/00124 | D19: ป 2569/00128 | E19: 5 | F19: 2300 | Q19: ป 69/01663 | R19: ป 69/01695 | S19: 33 | T19: 33300 | W19: =SUM(E19,S19) -> 38 | X19: =SUM(F19,T19) -> 35600 | Z19: 100 | AA19: 22 ม.ค.69
A20: 22 ม.ค. 69 | C20: ป 2569/00129 | D20: - | E20: 1 | F20: 450 | Q20: ป 69/01696 | R20: ป 69/01735 | S20: 40 | T20: 52600 | W20: =SUM(E20,S20) -> 41 | X20: =SUM(F20,T20) -> 53050 | Z20: 109 | AA20: 23 ม.ค.69
A21: 23 - 25 ม.ค. 69 | C21: - | D21: - | E21: - | F21: - | Q21: ป 69/01736 | R21: ป 69/01773 | S21: 38 | T21: 48800 | W21: =SUM(E21,S21) -> 38 | X21: =SUM(F21,T21) -> 48800 | Z21: 117 | AA21: 26 ม.ค.69
A22: 26 ม.ค. 69 | C22: ป 2569/00130 | D22: - | E22: 1 | F22: 2600 | Q22: ป 69/01774 | R22: ป 69/01824 | S22: 51 | T22: 58950.32 | W22: =SUM(E22,S22) -> 52 | X22: =SUM(F22,T22) -> 61550.32 | Z22: 125 | AA22: 27 ม.ค.69
A23: 27 ม.ค. 69 | C23: - | D23: - | E23: - | F23: - | Q23: ป 69/01825 | R23: ป 69/01863 | S23: 39 | T23: 46326.13 | W23: =SUM(E23,S23) -> 39 | X23: =SUM(F23,T23) -> 46326.13 | Z23: 131 | AA23: 28 ม.ค.69
A24: 28 ม.ค. 69 | C24: ป 2569/00131 | D24: ป 2569/00132 | E24: 2 | F24: 1540 | Q24: ป 69/01864 | R24: ป 69/01899 | S24: 36 | T24: 46300 | W24: =SUM(E24,S24) -> 38 | X24: =SUM(F24,T24) -> 47840 | Z24: 138 | AA24: 29 ม.ค.69
A25: 29 ม.ค. 69 | C25: ป 2569/00133 | D25: ป 2569/00134 | E25: 2 | F25: 2000 | Q25: ป 69/01900 | R25: ป 69/01928 | S25: 29 | T25: 41668.38 | W25: =SUM(E25,S25) -> 31 | X25: =SUM(F25,T25) -> 43668.38 | Z25: 146 | AA25: 30 ม.ค.69
A26: รวม | E26: =SUM(E6:E25) -> 28 | F26: =SUM(F6:F25) -> 25380 | I26: รวม | Q26: รวม | S26: =SUM(S6:S25) -> 1000 | T26: =SUM(T6:T25) -> 1376658.1 | U26: =SUM(U6:U25) -> 0 | V26: =SUM(V6:V25) -> 0 | W26: =SUM(W6:W25) -> 1028 | X26: =SUM(X6:X25) -> 1402038.1

Sheet ก.พ. 69
A1: รายงานการรับชำระค่าธรรมเนียมผ่านไปรษณีย์ เดือน กุมภาพันธ์ 2569
A3: วันที่ชำระ | B3: ข้อมูลกฎหมาย | C3: ระบบ Receipt (ใบเสร็จรับเงิน A4) | I3: ระบบ App (ใบเสร็จรับเงิน A5) | Q3: ระบบ Trade | W3: นำรายได้ ส่ง กค. พรบ.42 + พรบ.43 | Y3: หมายเหตุ | Z3: พน0401.1/ | AA3: วันที่ส่ง
B4: กฎหมาย | C4: จาก | D4: ถึง | E4: จำนวนใบเสร็จ | F4: จำนวนเงิน | G4: ยกเลิก/ใบเสร็จเสีย | I4: หมายเลขเล่ม | K4: จาก | L4: ถึง | M4: จำนวนใบเสร็จ | N4: จำนวนเงิน | O4: ยกเลิก/ใบเสร็จเสีย | Q4: จาก | R4: ถึง | S4: จำนวนใบเสร็จ | T4: จำนวนเงิน | U4: ยกเลิกใบเสร็จ | W4: รวมจำนวนใบเสร็จ | X4: รวมจำนวนเงิน
G5: จำนวนใบเสร็จ | H5: เลขที่ใบเสร็จ | O5: จำนวนใบเสร็จ | P5: เลขที่ใบเสร็จ | U5: จำนวนใบเสร็จ | V5: เลขที่ใบเสร็จ
A6: 30 ม.ค. 69 - 1 ก.พ. 69 | C6: ป 2569/00135 | D6: ป 2569/00136 | E6: 2 | F6: 1500 | Q6: ป 69/01929 | R6: ป 69/01984 | S6: 56 | T6: 70129.03 | W6: =SUM(E6,S6) -> 58 | X6: =SUM(F6,T6) -> 71629.03 | Z6: 157 | AA6: 2 ก.พ. 69
A7: 2 ก.พ. 69 | C7: - | D7: - | E7: - | F7: - | Q7: ป 69/01985 | R7: ป 69/02031 | S7: 47 | T7: 58532.14 | W7: =SUM(E7,S7) -> 47 | X7: =SUM(F7,T7) -> 58532.14 | Z7: 165 | AA7: 3 ก.พ. 69
A8: 3 ก.พ. 69 | C8: ป 2569/00137 | D8: ป 2569/00142 | E8: 6 | F8: 1200 | Q8: ป 69/02032 | R8: ป 69/02085 | S8: 54 | T8: 66626.42 | W8: =SUM(E8,S8) -> 60 | X8: =SUM(F8,T8) -> 67826.42 | Z8: 170 | AA8: 4 ก.พ. 69
A9: 4 ก.พ. 69 | C9: ป 2569/00143 | D9: - | E9: 1 | F9: 1000 | Q9: ป 69/02086 | R9: ป 69/02130 | S9: 45 | T9: 58734.29 | W9: =SUM(E9,S9) -> 46 | X9: =SUM(F9,T9) -> 59734.29 | Z9: 177 | AA9: 5 ก.พ. 69
A10: 5 ก.พ. 69 | C10: - | D10: - | E10: - | F10: - | Q10: ป 69/02131 | R10: ป 69/02175 | S10: 45 | T10: 47835.36 | W10: =SUM(E10,S10) -> 45 | X10: =SUM(F10,T10) -> 47835.36 | Z10: 186 | AA10: 6 ก.พ. 69
A11: 6 - 8 ก.พ. 69 | C11: ป 2569/00144 | D11: - | E11: 1 | F11: 200 | Q11: ป 69/02176 | R11: ป 69/02226 | S11: 51 | T11: 53400 | W11: =SUM(E11,S11) -> 52 | X11: =SUM(F11,T11) -> 53600 | Z11: 195 | AA11: 9 ก.พ. 69
A12: 9 ก.พ. 69 | C12: - | D12: - | E12: - | F12: - | Q12: ป 69/02227 | R12: ป 69/02273 | S12: 47 | T12: 55139.64 | W12: =SUM(E12,S12) -> 47 | X12: =SUM(F12,T12) -> 55139.64 | Z12: 206 | AA12: 10 ก.พ. 69
A13: 10 ก.พ. 69 | C13: - | D13: - | E13: - | F13: - | Q13: ป 69/02274 | R13: ป 69/02308 | S13: 35 | T13: 38940.71 | W13: =SUM(E13,S13) -> 35 | X13: =SUM(F13,T13) -> 38940.71 | Z13: 211 | AA13: 11 ก.พ. 69
A14: 11 ก.พ. 69 | C14: - | D14: - | E14: - | F14: - | Q14: ป 69/02309 | R14: ป 69/02358 | S14: 50 | T14: 59200 | W14: =SUM(E14,S14) -> 50 | X14: =SUM(F14,T14) -> 59200 | Z14: 218 | AA14: 12 ก.พ. 69
A15: 12 ก.พ. 69 | C15: - | D15: - | E15: - | F15: - | Q15: ป 69/02359 | R15: ป 69/02393 | S15: 35 | T15: 51900 | W15: =SUM(E15,S15) -> 35 | X15: =SUM(F15,T15) -> 51900 | Z15: 222 | AA15: 13 ก.พ. 69
A16: 13 - 15 ก.พ. 69 | C16: ป 2569/00145 | D16: ป 2569/00146 | E16: 2 | F16: 400 | Q16: ป 69/02394 | R16: ป 69/02429 | S16: 36 | T16: 66000 | W16: =SUM(E16,S16) -> 38 | X16: =SUM(F16,T16) -> 66400 | Z16: 231 | AA16: 16 ก.พ. 69
A17: 16 ก.พ. 69 | C17: - | D17: - | E17: - | F17: - | Q17: ป 69/02430 | R17: ป 69/02462 | S17: 33 | T17: 43247.14 | W17: =SUM(E17,S17) -> 33 | X17: =SUM(F17,T17) -> 43247.14 | Z17: 240 | AA17: 17 ก.พ. 69
A18: 17 ก.พ. 69 | C18: - | D18: - | E18: - | F18: - | Q18: ป 69/02463 | R18: ป 69/02486 | S18: 24 | T18: 29400 | W18: =SUM(E18,S18) -> 24 | X18: =SUM(F18,T18) -> 29400 | Z18: 245 | AA18: 18 ก.พ. 69
A19: 18 ก.พ. 69 | C19: - | D19: - | E19: - | F19: - | Q19: ป 69/02487 | R19: ป 69/02521 | S19: 35 | T19: 51000 | W19: =SUM(E19,S19) -> 35 | X19: =SUM(F19,T19) -> 51000 | Z19: 254 | AA19: 19 ก.พ. 69
A20: 19 ก.พ. 69 | C20: ป 2569/00147 | D20: - | E20: 1 | F20: 450 | Q20: ป 69/02522 | R20: ป 69/02540 | S20: 19 | T20: 48850.36 | W20: =SUM(E20,S20) -> 20 | X20: =SUM(F20,T20) -> 49300.36 | Z20: 264 | AA20: 20 ก.พ. 69
A21: 20 - 22 ก.พ. 69 | C21: - | D21: - | E21: - | F21: - | Q21: ป 69/02541 | R21: ป 69/02577 | S21: 37 | T21: 38351.43 | W21: =SUM(E21,S21) -> 37 | X21: =SUM(F21,T21) -> 38351.43 | Z21: 269 | AA21: 23 ก.พ. 69
A22: 23 ก.พ. 69 | C22: - | D22: - | E22: - | F22: - | Q22: ป 69/02578 | R22: ป 69/02620 | S22: 43 | T22: 58700 | W22: =SUM(E22,S22) -> 43 | X22: =SUM(F22,T22) -> 58700 | Z22: 273 | AA22: 24 ก.พ. 69
A23: 24 ก.พ. 69 | C23: - | D23: - | E23: - | F23: - | Q23: ป 69/02621 | R23: ป 69/02681 | S23: 61 | T23: 103471.42 | W23: =SUM(E23,S23) -> 61 | X23: =SUM(F23,T23) -> 103471.42 | Z23: 282 | AA23: 25 ก.พ. 69
A24: 25 ก.พ. 69 | C24: - | D24: - | E24: - | F24: - | Q24: ป 69/02682 | R24: ป 69/02724 | S24: 43 | T24: 54556.79 | W24: =SUM(E24,S24) -> 43 | X24: =SUM(F24,T24) -> 54556.79 | Z24: 290 | AA24: 26 ก.พ. 69
A25: 26 ก.พ. 69 | C25: ป 2569/00148 | D25: - | E25: 1 | F25: 200 | Q25: ป 69/02725 | R25: ป 69/02777 | S25: 53 | T25: 77257.86 | W25: =SUM(E25,S25) -> 54 | X25: =SUM(F25,T25) -> 77457.86 | Z25: 298 | AA25: 27 ก.พ. 69
A26: รวม | E26: =SUM(E6:E25) -> 14 | F26: =SUM(F6:F25) -> 4950 | I26: รวม | Q26: รวม | S26: =SUM(S6:S25) -> 849 | T26: =SUM(T6:T25) -> 1131272.6 | U26: =SUM(U6:U25) -> 0 | V26: =SUM(V6:V25) -> 0 | W26: =SUM(W6:W25) -> 863 | X26: =SUM(X6:X25) -> 1136222.6

Sheet มี.ค. 69
A1: รายงานการรับชำระค่าธรรมเนียมผ่านไปรษณีย์ เดือน มีนาคม 2569
A3: วันที่ชำระ | B3: ข้อมูลกฎหมาย | C3: ระบบ Receipt (ใบเสร็จรับเงิน A4) | I3: ระบบ App (ใบเสร็จรับเงิน A5) | Q3: ระบบ Trade | W3: นำรายได้ ส่ง กค. พรบ.42 + พรบ.43 | Y3: หมายเหตุ | Z3: พน0401.1/ | AA3: วันที่ส่ง
B4: กฎหมาย | C4: จาก | D4: ถึง | E4: จำนวนใบเสร็จ | F4: จำนวนเงิน | G4: ยกเลิก/ใบเสร็จเสีย | I4: หมายเลขเล่ม | K4: จาก | L4: ถึง | M4: จำนวนใบเสร็จ | N4: จำนวนเงิน | O4: ยกเลิก/ใบเสร็จเสีย | Q4: จาก | R4: ถึง | S4: จำนวนใบเสร็จ | T4: จำนวนเงิน | U4: ยกเลิกใบเสร็จ | W4: รวมจำนวนใบเสร็จ | X4: รวมจำนวนเงิน
G5: จำนวนใบเสร็จ | H5: เลขที่ใบเสร็จ | O5: จำนวนใบเสร็จ | P5: เลขที่ใบเสร็จ | U5: จำนวนใบเสร็จ | V5: เลขที่ใบเสร็จ
A6: 27 ก.พ. - 1 มี.ค. 69 | C6: - | D6: - | E6: - | F6: - | Q6: ป 69/02778 | R6: ป 69/02894 | S6: 117 | T6: 167958.93 | W6: =SUM(E6,S6) -> 117 | X6: =SUM(F6,T6) -> 167958.93 | Z6: 304 | AA6: 2 มี.ค. 69
A7: 2 - 3 มี.ค. 69 | C7: - | D7: - | E7: - | F7: - | Q7: ป 69/02895 | R7: ป 69/02931 | S7: 37 | T7: 39037.75 | W7: =SUM(E7,S7) -> 37 | X7: =SUM(F7,T7) -> 39037.75 | Z7: 312 | AA7: 4 มี.ค. 69
A8: 4 มี.ค. 69 | C8: - | D8: - | E8: - | F8: - | Q8: ป 69/02932 | R8: ป 69/02962 | S8: 31 | T8: 36097.78 | W8: =SUM(E8,S8) -> 31 | X8: =SUM(F8,T8) -> 36097.78 | Z8: 318 | AA8: 5 มี.ค. 69
A9: 5 มี.ค. 69 | C9: - | D9: - | E9: - | F9: - | Q9: ป 69/02963 | R9: ป 69/02979 | S9: 17 | T9: 25422.44 | W9: =SUM(E9,S9) -> 17 | X9: =SUM(F9,T9) -> 25422.44 | Z9: 324 | AA9: 6 มี.ค. 69
A10: 6 - 8 มี.ค. 69 | C10: - | D10: - | E10: - | F10: - | Q10: ป 69/02980 | R10: ป 69/03013 | S10: 34 | T10: 44260.38 | W10: =SUM(E10,S10) -> 34 | X10: =SUM(F10,T10) -> 44260.38 | Z10: 333 | AA10: 9 มี.ค. 69
A11: 9 มี.ค. 69 | C11: - | D11: - | E11: - | F11: - | Q11: ป 69/03014 | R11: ป 69/03034 | S11: 21 | T11: 27235.16 | W11: =SUM(E11,S11) -> 21 | X11: =SUM(F11,T11) -> 27235.16 | Z11: 338 | AA11: 10 มี.ค. 69
A12: 10 มี.ค. 69 | C12: - | D12: - | E12: - | F12: - | Q12: ป 69/03035 | R12: ป 69/03065 | S12: 31 | T12: 31502.01 | W12: =SUM(E12,S12) -> 31 | X12: =SUM(F12,T12) -> 31502.01 | Z12: 346 | AA12: 11 มี.ค. 69
A13: 11 มี.ค. 69 | C13: - | D13: - | E13: - | F13: - | Q13: ป 69/03066 | R13: ป 69/03081 | S13: 16 | T13: 20718.29 | W13: =SUM(E13,S13) -> 16 | X13: =SUM(F13,T13) -> 20718.29 | Z13: 350 | AA13: 12 มี.ค. 69
A14: 12 มี.ค. 69 | C14: ป 2569/00149 | D14: - | E14: 1 | F14: 200 | Q14: ป 69/03082 | R14: ป 69/03101 | S14: 20 | T14: 21806.14 | W14: =SUM(E14,S14) -> 21 | X14: =SUM(F14,T14) -> 22006.14 | Z14: 356 | AA14: 13 มี.ค. 69
A15: 13 - 15 มี.ค. 69 | C15: ป 2569/00150 | E15: 1 | F15: 500 | Q15: ป 69/03102 | R15: ป 69/03121 | S15: 20 | T15: 30675.06 | W15: =SUM(E15,S15) -> 21 | X15: =SUM(F15,T15) -> 31175.06 | Z15: 366 | AA15: 16 มี.ค. 69
A16: 16 มี.ค. 69 | C16: ป 2569/00151 | E16: 1 | F16: 200 | Q16: ป 69/03122 | R16: ป 69/03130 | S16: 9 | T16: 9850.16 | W16: =SUM(E16,S16) -> 10 | X16: =SUM(F16,T16) -> 10050.16 | Z16: 372 | AA16: 17 มี.ค. 69
A17: 17 มี.ค. 69 | C17: ป 2569/00152 | D17: ป 2569/00153 | E17: 2 | F17: 400 | Q17: ป 69/03131 | R17: ป 69/03144 | S17: 14 | T17: 16263.21 | W17: =SUM(E17,S17) -> 16 | X17: =SUM(F17,T17) -> 16663.21 | Z17: 379 | AA17: 18 มี.ค. 69
A18: 18 มี.ค. 69 | C18: - | D18: - | E18: - | F18: - | Q18: ป 69/03145 | R18: ป 69/03154 | S18: 10 | T18: 13938.65 | W18: =SUM(E18,S18) -> 10 | X18: =SUM(F18,T18) -> 13938.65 | Z18: 384 | AA18: 19 มี.ค. 69
A19: 19 มี.ค. 69 | C19: - | D19: - | E19: - | F19: - | Q19: ป 69/03155 | R19: ป 69/03161 | S19: 7 | T19: 7470.34 | W19: =SUM(E19,S19) -> 7 | X19: =SUM(F19,T19) -> 7470.34 | Z19: 392 | AA19: 20 มี.ค. 69
A20: 20 - 22 มี.ค. 69 | C20: - | D20: - | E20: - | F20: - | Q20: ป 69/03162 | R20: ป 69/03172 | S20: 11 | T20: 11212.85 | W20: =SUM(E20,S20) -> 11 | X20: =SUM(F20,T20) -> 11212.85 | Z20: 396 | AA20: 23 มี.ค. 69
A21: 23 มี.ค. 69 | C21: - | D21: - | E21: - | F21: - | Q21: ป 69/03173 | R21: ป 69/03191 | S21: 19 | T21: 21111.86 | W21: =SUM(E21,S21) -> 19 | X21: =SUM(F21,T21) -> 21111.86 | Z21: 402 | AA21: 24 มี.ค. 69
A22: 24 มี.ค. 69 | C22: - | D22: - | E22: - | F22: - | Q22: ป 69/03192 | R22: ป 69/03198 | S22: 7 | T22: 7162.61 | W22: =SUM(E22,S22) -> 7 | X22: =SUM(F22,T22) -> 7162.61 | Z22: 409 | AA22: 25 มี.ค. 69
A23: 25 มี.ค. 69 | C23: - | D23: - | E23: - | F23: - | Q23: ป 69/03199 | R23: ป 69/03203 | S23: 5 | T23: 5120.95 | W23: =SUM(E23,S23) -> 5 | X23: =SUM(F23,T23) -> 5120.95 | Z23: 414 | AA23: 26 มี.ค. 69
A24: 26 มี.ค. 69 | C24: ป 2569/00154 | D24: ป 2569/00155 | E24: 2 | F24: 1450 | Q24: ป 69/03204 | R24: ป 69/03213 | S24: 10 | T24: 15684.96 | W24: =SUM(E24,S24) -> 12 | X24: =SUM(F24,T24) -> 17134.96 | Z24: 420 | AA24: 27 มี.ค. 69
A25: 27 - 29 มี.ค. 69 | C25: ป 2569/00156 | D25: ป 2569/00157 | E25: 2 | F25: 900 | Q25: ป 69/03214 | R25: ป 69/03230 | S25: 17 | T25: 21196.02 | W25: =SUM(E25,S25) -> 19 | X25: =SUM(F25,T25) -> 22096.02 | Z25: 429 | AA25: 30 มี.ค. 69
A26: 30 มี.ค. 69 | C26: ป 2569/00158 | D26: ป 2569/00160 | E26: 3 | F26: 600 | Q26: ป 69/03231 | R26: ป 69/03247 | S26: 17 | T26: 17853.51 | W26: =SUM(E26,S26) -> 20 | X26: =SUM(F26,T26) -> 18453.51 | Z26: 434 | AA26: 31 มี.ค. 69
A27: 31 มี.ค. 69 | C27: - | D27: - | E27: - | F27: - | Q27: ป 69/03248 | R27: ป 69/03257 | S27: 10 | T27: 41086 | W27: =SUM(E27,S27) -> 10 | X27: =SUM(F27,T27) -> 41086 | Z27: 442 | AA27: 1 เม.ย. 69
A28: รวม | E28: =SUM(E6:E27) -> 12 | F28: =SUM(F6:F27) -> 4250 | I28: รวม | Q28: รวม | S28: =SUM(S6:S27) -> 480 | T28: =SUM(T6:T27) -> 632665.06 | U28: =SUM(U6:U25) -> 0 | V28: =SUM(V6:V25) -> 0 | W28: =SUM(W6:W27) -> 492 | X28: =SUM(X6:X27) -> 636915.06

Sheet เม.ย. 69
A1: รายงานการรับชำระค่าธรรมเนียมผ่านไปรษณีย์ เดือน เมษายน 2569
A3: วันที่ชำระ | B3: ข้อมูลกฎหมาย | C3: ระบบ Receipt (ใบเสร็จรับเงิน A4) | I3: ระบบ App (ใบเสร็จรับเงิน A5) | Q3: ระบบ Trade | W3: นำรายได้ ส่ง กค. พรบ.42 + พรบ.43 | Y3: หมายเหตุ | Z3: พน0401.1/ | AA3: วันที่ส่ง
B4: กฎหมาย | C4: จาก | D4: ถึง | E4: จำนวนใบเสร็จ | F4: จำนวนเงิน | G4: ยกเลิก/ใบเสร็จเสีย | I4: หมายเลขเล่ม | K4: จาก | L4: ถึง | M4: จำนวนใบเสร็จ | N4: จำนวนเงิน | O4: ยกเลิก/ใบเสร็จเสีย | Q4: จาก | R4: ถึง | S4: จำนวนใบเสร็จ | T4: จำนวนเงิน | U4: ยกเลิกใบเสร็จ | W4: รวมจำนวนใบเสร็จ | X4: รวมจำนวนเงิน
G5: จำนวนใบเสร็จ | H5: เลขที่ใบเสร็จ | O5: จำนวนใบเสร็จ | P5: เลขที่ใบเสร็จ | U5: จำนวนใบเสร็จ | V5: เลขที่ใบเสร็จ
A6: 1 เม.ย. 69 | C6: ป 2569/00161 | D6: - | E6: 1 | F6: 200 | Q6: ป 69/03258 | R6: ป 69/03271 | S6: 14 | T6: 15640.2 | W6: =SUM(E6,S6) -> 15 | X6: =SUM(F6,T6) -> 15840.2 | Z6: 448 | AA6: 2 เม.ย. 69
A7: 2 เม.ย. 69 | C7: - | D7: - | E7: - | F7: - | Q7: ป 69/03272 | R7: ป 69/03284 | S7: 13 | T7: 19092 | W7: =SUM(E7,S7) -> 13 | X7: =SUM(F7,T7) -> 19092 | Z7: 454 | AA7: 3 เม.ย. 69
A8: 3 - 6 เม.ย. 69 | C8: ป 2569/00162 | D8: ป 2569/00163 | E8: 2 | F8: 1500 | Q8: ป 69/03285 | R8: ป 69/03302 | S8: 18 | T8: 25255.3 | W8: =SUM(E8,S8) -> 20 | X8: =SUM(F8,T8) -> 26755.3 | Z8: 461 | AA8: 7 เม.ย. 69
A9: 7 เม.ย. 69 | C9: - | D9: - | E9: - | F9: - | Q9: ป 69/03303 | R9: ป 69/03322 | S9: 20 | T9: 26443.5 | W9: =SUM(E9,S9) -> 20 | X9: =SUM(F9,T9) -> 26443.5 | Z9: 467 | AA9: 8 เม.ย. 69
A10: 8 เม.ย. 69 | C10: ป 2569/00164 | D10: ป 2569/00166 | E10: 3 | F10: 2800 | Q10: ป 69/03323 | R10: ป 69/03351 | S10: 29 | T10: 38094.6 | W10: =SUM(E10,S10) -> 32 | X10: =SUM(F10,T10) -> 40894.6 | Z10: 473 | AA10: 9 เม.ย. 69
A11: 9 เม.ย. 69 | C11: ป 2569/00167 | D11: - | E11: 1 | F11: 2500 | Q11: ป 69/03352 | R11: ป 69/03374 | S11: 23 | T11: 34183.1 | W11: =SUM(E11,S11) -> 24 | X11: =SUM(F11,T11) -> 36683.1 | Z11: 481 | AA11: 10 เม.ย. 69
A12: 10 - 15 เม.ย. 69 | C12: - | D12: - | E12: - | F12: - | Q12: ป 69/03375 | R12: ป 69/03414 | S12: 40 | T12: 49358 | W12: =SUM(E12,S12) -> 40 | X12: =SUM(F12,T12) -> 49358 | Z12: 488 | AA12: 16 เม.ย. 69
A13: 16 เม.ย. 69 | C13: - | D13: - | E13: - | F13: - | Q13: ป 69/03415 | R13: ป 69/03424 | S13: 10 | T13: 12761.2 | W13: =SUM(E13,S13) -> 10 | X13: =SUM(F13,T13) -> 12761.2 | Z13: 494 | AA13: 17 เม.ย. 69
A14: 17 - 19 เม.ย. 69 | C14: - | D14: - | E14: - | F14: - | Q14: ป 69/03425 | R14: ป 69/03445 | S14: 21 | T14: 24085 | W14: =SUM(E14,S14) -> 21 | X14: =SUM(F14,T14) -> 24085 | Z14: 500 | AA14: 20 เม.ย. 69
A15: 20 เม.ย. 69 | C15: - | D15: - | E15: - | F15: - | Q15: ป 69/03446 | R15: ป 69/03460 | S15: 15 | T15: 16485 | W15: =SUM(E15,S15) -> 15 | X15: =SUM(F15,T15) -> 16485 | Z15: 508 | AA15: 21 เม.ย. 69
A16: 21 เม.ย. 69 | C16: - | D16: - | E16: - | F16: - | Q16: ป 69/03461 | R16: ป 69/03496 | S16: 36 | T16: 46814.2 | W16: =SUM(E16,S16) -> 36 | X16: =SUM(F16,T16) -> 46814.2 | Z16: 514 | AA16: 22 เม.ย. 69
A17: 22 เม.ย. 69 | C17: - | D17: - | E17: - | F17: - | Q17: ป 69/03497 | R17: ป 69/03527 | S17: 31 | T17: 36188.8 | W17: =SUM(E17,S17) -> 31 | X17: =SUM(F17,T17) -> 36188.8 | Z17: 521 | AA17: 23 เม.ย. 69
A18: 23 เม.ย. 69 | C18: - | D18: - | E18: - | F18: - | Q18: ป 69/03528 | R18: ป 69/03546 | S18: 19 | T18: 21420 | W18: =SUM(E18,S18) -> 19 | X18: =SUM(F18,T18) -> 21420 | Z18: 529 | AA18: 24 เม.ย. 69
A19: 24 - 26 เม.ย. 69 | C19: - | D19: - | E19: - | F19: - | Q19: ป 69/03547 | R19: ป 69/03570 | S19: 24 | T19: 25405.4 | W19: =SUM(E19,S19) -> 24 | X19: =SUM(F19,T19) -> 25405.4 | Z19: 532 | AA19: 27 เม.ย. 69
A20: 27 เม.ย. 69 | C20: ป 2569/00168 | D20: ป 2569/00170 | E20: 3 | F20: 600 | Q20: ป 69/03571 | R20: ป 69/03604 | S20: 34 | T20: 41934.9 | W20: =SUM(E20,S20) -> 37 | X20: =SUM(F20,T20) -> 42534.9 | Z20: 539 | AA20: 28 เม.ย. 69
A21: 28 เม.ย. 69 | C21: ป 2569/00171 | D21: - | E21: 1 | F21: 200 | Q21: ป 69/03605 | R21: ป 69/03623 | S21: 19 | T21: 22641.2 | W21: =SUM(E21,S21) -> 20 | X21: =SUM(F21,T21) -> 22841.2 | Z21: 546 | AA21: 29 เม.ย. 69
A22: 29 เม.ย. 69 | C22: - | D22: - | E22: - | F22: - | Q22: ป 69/03624 | R22: ป 69/03647 | S22: 24 | T22: 27639.9 | W22: =SUM(E22,S22) -> 24 | X22: =SUM(F22,T22) -> 27639.9 | Z22: 551 | AA22: 30 เม.ย. 69
A23: 30 เม.ย. 69 | W23: =SUM(E23,S23) -> 0 | X23: =SUM(F23,T23) -> 0
A24: รวม | E24: =SUM(E6:E23) -> 11 | F24: =SUM(F6:F23) -> 7800 | I24: รวม | Q24: รวม | S24: =SUM(S6:S23) -> 390 | T24: =SUM(T6:T23) -> 483442.3 | U24: =SUM(U6:U23) -> 0 | V24: =SUM(V6:V23) -> 0 | W24: =SUM(W6:W23) -> 401 | X24: =SUM(X6:X23) -> 491242.3

Sheet พ.ค.69
A1: รายงานการรับชำระค่าธรรมเนียมผ่านไปรษณีย์ เดือน พฤษภาคม 2569
A3: วันที่ชำระ | B3: ข้อมูลกฎหมาย | C3: ระบบ Receipt (ใบเสร็จรับเงิน A4) | I3: ระบบ App (ใบเสร็จรับเงิน A5) | Q3: ระบบ Trade | W3: นำรายได้ ส่ง กค. พรบ.42 + พรบ.43 | Y3: หมายเหตุ | Z3: พน0401.1/ | AA3: วันที่ส่ง
B4: กฎหมาย | C4: จาก | D4: ถึง | E4: จำนวนใบเสร็จ | F4: จำนวนเงิน | G4: ยกเลิก/ใบเสร็จเสีย | I4: หมายเลขเล่ม | K4: จาก | L4: ถึง | M4: จำนวนใบเสร็จ | N4: จำนวนเงิน | O4: ยกเลิก/ใบเสร็จเสีย | Q4: จาก | R4: ถึง | S4: จำนวนใบเสร็จ | T4: จำนวนเงิน | U4: ยกเลิกใบเสร็จ | W4: รวมจำนวนใบเสร็จ | X4: รวมจำนวนเงิน
G5: จำนวนใบเสร็จ | H5: เลขที่ใบเสร็จ | O5: จำนวนใบเสร็จ | P5: เลขที่ใบเสร็จ | U5: จำนวนใบเสร็จ | V5: เลขที่ใบเสร็จ
A6: 30 - 4 พ.ค. 69 | C6: ป 2569/00172 | D6: - | E6: 1 | F6: 1600 | Q6: ป 69/03653 | R6: ป 69/03685 | S6: 33 | T6: 40821.62 | U6: 5 | V6: ป 69/03648 - 03652 | W6: =SUM(E6,S6) -> 34 | X6: =SUM(F6,T6) -> 42421.62 | Y6: 1 พ.ค. 69 ปณ. หยุด | Z6: 568 | AA6: 6 พ.ค. 69
A7: 5 พ.ค. 69 | C7: ป 2569/00173 | D7: ป 2569/00175 | E7: 3 | F7: 600 | Q7: ป 69/03686 | R7: ป 69/03708 | S7: 23 | T7: 25875.61 | W7: =SUM(E7,S7) -> 26 | X7: =SUM(F7,T7) -> 26475.61 | Z7: 574 | AA7: 6 พ.ค. 69
A8: 6 พ.ค. 69 | C8: ป 2569/00176 | D8: - | E8: 1 | F8: 200 | Q8: ป 69/03709 | R8: ป 69/03727 | S8: 19 | T8: 32378.75 | W8: =SUM(E8,S8) -> 20 | X8: =SUM(F8,T8) -> 32578.75 | Z8: 581 | AA8: 7 พ.ค. 69
A9: 7 พ.ค. 69 | C9: - | D9: - | E9: - | F9: - | Q9: ป 69/03728 | R9: ป 69/03743 | S9: 16 | T9: 17495.04 | W9: =SUM(E9,S9) -> 16 | X9: =SUM(F9,T9) -> 17495.04 | Z9: 587 | AA9: 8 พ.ค. 69
A10: 8 - 10 พ.ค. 69 | C10: - | D10: - | E10: - | F10: - | Q10: ป 69/03744 | R10: ป 69/03759 | S10: 16 | T10: 22648.75 | W10: =SUM(E10,S10) -> 16 | X10: =SUM(F10,T10) -> 22648.75 | Z10: 595 | AA10: 11 พ.ค. 69
A11: 11 พ.ค. 69 | C11: - | D11: - | E11: - | F11: - | Q11: ป 69/03760 | R11: ป 69/03782 | S11: 23 | T11: 29121.64 | W11: =SUM(E11,S11) -> 23 | X11: =SUM(F11,T11) -> 29121.64 | Z11: 602 | AA11: 12 พ.ค. 69
A12: 12 - 13 พ.ค. 69 | C12: - | D12: - | E12: - | F12: - | Q12: ป 69/03783 | R12: ป 69/03797 | S12: 15 | T12: 24432.73 | W12: =SUM(E12,S12) -> 15 | X12: =SUM(F12,T12) -> 24432.73 | Z12: 608 | AA12: 14 พ.ค. 69
A13: 14 พ.ค. 69 | C13: - | D13: - | E13: - | F13: - | Q13: ป 69/03798 | R13: ป 69/03725 | S13: 28 | T13: 38793.07 | W13: =SUM(E13,S13) -> 28 | X13: =SUM(F13,T13) -> 38793.07 | Z13: 615 | AA13: 15 พ.ค. 69
A14: 15 - 17 พ.ค. 69 | C14: - | D14: - | E14: - | F14: - | Q14: ป 69/03726 | R14: ป 69/03841 | S14: 16 | T14: 19056.97 | W14: =SUM(E14,S14) -> 16 | X14: =SUM(F14,T14) -> 19056.97 | Z14: 622 | AA14: 18 พ.ค. 69
A15: 18 พ.ค. 69 | C15: - | D15: - | E15: - | F15: - | Q15: ป 69/03842 | R15: ป 69/03851 | S15: 10 | T15: 10774.2 | W15: =SUM(E15,S15) -> 10 | X15: =SUM(F15,T15) -> 10774.2 | Z15: 628 | AA15: 19 พ.ค. 69
A16: 19 พ.ค. 69 | C16: - | D16: - | E16: - | F16: - | Q16: ป 69/03852 | R16: ป 69/03869 | S16: 18 | T16: 26349.17 | W16: =SUM(E16,S16) -> 18 | X16: =SUM(F16,T16) -> 26349.17 | Z16: 631 | AA16: 20 พ.ค. 69
A17: 20 พ.ค. 69 | C17: - | D17: - | E17: - | F17: - | Q17: ป 69/03870 | R17: ป 69/03879 | S17: 10 | T17: 10793.5 | W17: =SUM(E17,S17) -> 10 | X17: =SUM(F17,T17) -> 10793.5 | Z17: 638 | AA17: 21 พ.ค. 69
A18: 21 พ.ค. 69 | C18: - | D18: - | E18: - | F18: - | Q18: ป 69/03880 | R18: ป 69/03899 | S18: 20 | T18: 24955.42 | W18: =SUM(E18,S18) -> 20 | X18: =SUM(F18,T18) -> 24955.42 | Z18: 644 | AA18: 22 พ.ค. 69
A19: 22 - 24 พ.ค. 69 | C19: - | D19: - | E19: - | F19: - | Q19: ป 69/03900 | R19: ป 69/03916 | S19: 17 | T19: 22421.75 | W19: =SUM(E19,S19) -> 17 | X19: =SUM(F19,T19) -> 22421.75 | Z19: 649 | AA19: 25 พ.ค. 69
A20: 25 พ.ค. 69 | C20: - | D20: - | E20: - | F20: - | Q20: ป 69/03917 | R20: ป 69/03942 | S20: 26 | T20: 32343.62 | W20: =SUM(E20,S20) -> 26 | X20: =SUM(F20,T20) -> 32343.62 | Z20: 657 | AA20: 26 พ.ค. 69
... A23: 28 พ.ค. 69 | C23: - | D23: - | E23: - | F23: - | Q23: ป 69/03980 | R23: ป 69/03994 | S23: 15 | T23: 18589.39 | W23: =SUM(E23,S23) -> 15 | X23: =SUM(F23,T23) -> 18589.39 | Z23: 674 | AA23: 29 พ.ค. 69
A24: รวม | E24: =SUM(E6:E23) -> 5 | F24: =SUM(F6:F23) -> 2400 | I24: รวม | Q24: รวม | S24: =SUM(S6:S23) -> 342 | T24: =SUM(T6:T23) -> 444003.56 | U24: =SUM(U6:U23) -> 5 | V24: =SUM(V6:V23) -> 0 | W24: =SUM(W6:W23) -> 347 | X24: =SUM(X6:X23) -> 446403.56

Sheet มิ.ย.69
A1: รายงานการรับชำระค่าธรรมเนียมผ่านไปรษณีย์ เดือน มิถุนายน 2569
A3: วันที่ชำระ | B3: ข้อมูลกฎหมาย | C3: ระบบ Receipt (ใบเสร็จรับเงิน A4) | I3: ระบบ App (ใบเสร็จรับเงิน A5) | Q3: ระบบ Trade | W3: นำรายได้ ส่ง กค. พรบ.42 + พรบ.43 | Y3: หมายเหตุ | Z3: พน0401.1/ | AA3: วันที่ส่ง
B4: กฎหมาย | C4: จาก | D4: ถึง | E4: จำนวนใบเสร็จ | F4: จำนวนเงิน | G4: ยกเลิก/ใบเสร็จเสีย | I4: หมายเลขเล่ม | K4: จาก | L4: ถึง | M4: จำนวนใบเสร็จ | N4: จำนวนเงิน | O4: ยกเลิก/ใบเสร็จเสีย | Q4: จาก | R4: ถึง | S4: จำนวนใบเสร็จ | T4: จำนวนเงิน | U4: ยกเลิกใบเสร็จ | W4: รวมจำนวนใบเสร็จ | X4: รวมจำนวนเงิน
G5: จำนวนใบเสร็จ | H5: เลขที่ใบเสร็จ | O5: จำนวนใบเสร็จ | P5: เลขที่ใบเสร็จ | U5: จำนวนใบเสร็จ | V5: เลขที่ใบเสร็จ
A6: 29 พ.ค. - 1 มิ.ย. 69 | C6: - | D6: - | E6: - | F6: - | Q6: ป 69/03996 | R6: ป 69/04009 | S6: 14 | T6: 15347.5 | U6: 1 | V6: ป69/0395 | W6: =SUM(E6,S6) -> 14 | X6: =SUM(F6,T6) -> 15347.5 | Z6: 678 | AA6: 2 มิ.ย. 69
A7: 2 - 3 มิ.ย. 69 | C7: ป 2569/00177 | D7: - | E7: 1 | F7: 2500 | Q7: ป 69/04010 | R7: ป 69/04024 | S7: 15 | T7: 20208.5 | W7: =SUM(E7,S7) -> 16 | X7: =SUM(F7,T7) -> 22708.5 | Z7: 686 | AA7: 4 มิ.ย. 69
A8: 4 มิ.ย. 69 | C8: ป 2569/00178 | D8: - | E8: 1 | F8: 2500 | Q8: ป 69/04025 | R8: ป 69/04032 | S8: 8 | T8: 8752 | W8: =SUM(E8,S8) -> 9 | X8: =SUM(F8,T8) -> 11252 | Z8: 694 | AA8: 5 มิ.ย. 69
A9: 5 - 7 มิ.ย. 69 | C9: - | D9: - | E9: - | F9: - | Q9: ป 69/04033 | R9: ป 69/04042 | S9: 10 | T9: 10950 | W9: =SUM(E9,S9) -> 10 | X9: =SUM(F9,T9) -> 10950 | Z9: 699 | AA9: 8 มิ.ย. 69
A10: 8 มิ.ย. 69 | C10: ป 2569/00179 | D10: - | E10: 1 | F10: 1400 | Q10: ป 69/04043 | R10: ป 69/04048 | S10: 6 | T10: 6948 | W10: =SUM(E10,S10) -> 7 | X10: =SUM(F10,T10) -> 8348 | Z10: 705 | AA10: 9 มิ.ย. 69
A11: 9 มิ.ย. 69 | C11: - | D11: - | E11: - | F11: - | Q11: ป 69/04049 | R11: ป 69/04054 | S11: 6 | T11: 9121.7 | W11: =SUM(E11,S11) -> 6 | X11: =SUM(F11,T11) -> 9121.7 | Z11: 713 | AA11: 10 มิ.ย. 69
A12: 10 มิ.ย. 69 | C12: ป 2569/00180 | D12: - | E12: 1 | F12: 200 | Q12: ป 69/04055 | R12: ป 69/04063 | S12: 9 | T12: 11590 | W12: =SUM(E12,S12) -> 10 | X12: =SUM(F12,T12) -> 11790 | Z12: 716 | AA12: 11 มิ.ย. 69
A13: 11 มิ.ย. 69 | C13: - | D13: - | E13: - | F13: - | Q13: ป 69/04064 | R13: ป 69/04070 | S13: 7 | T13: 9147 | W13: =SUM(E13,S13) -> 7 | X13: =SUM(F13,T13) -> 9147 | Z13: 723 | AA13: 12 มิ.ย. 69
A14: 12 - 14 มิ.ย. 69 | C14: ป 2569/00181 | D14: - | E14: 1 | F14: 200 | Q14: ป 69/04071 | R14: ป 69/04075 | S14: 5 | T14: 6008 | W14: =SUM(E14,S14) -> 6 | X14: =SUM(F14,T14) -> 6208 | Z14: 729 | AA14: 15 มิ.ย. 69
A15: 15 มิ.ย. 69 | C15: - | D15: - | E15: - | F15: - | Q15: ป 69/04076 | R15: ป 69/04078 | S15: 3 | T15: 3315 | W15: =SUM(E15,S15) -> 3 | X15: =SUM(F15,T15) -> 3315 | Z15: 736 | AA15: 16 มิ.ย. 69
A16: 16 มิ.ย. 69 | C16: - | D16: - | E16: - | F16: - | Q16: ป 69/04079 | R16: ป 69/04087 | S16: 9 | T16: 10424.6 | W16: =SUM(E16,S16) -> 9 | X16: =SUM(F16,T16) -> 10424.6 | Z16: 740 | AA16: 17 มิ.ย. 69
A17: 17 มิ.ย. 69 | C17: ป 2569/00182 | D17: - | E17: 1 | F17: 200 | Q17: ป 69/04088 | R17: ป 69/04093 | S17: 6 | T17: 9963 | W17: =SUM(E17,S17) -> 7 | X17: =SUM(F17,T17) -> 10163 | Z17: 748 | AA17: 18 มิ.ย. 69
A18: 18 มิ.ย. 69 | C18: - | D18: - | E18: - | F18: - | Q18: ป 69/04094 | R18: ป 69/04102 | S18: 9 | T18: 11774.8 | W18: =SUM(E18,S18) -> 9 | X18: =SUM(F18,T18) -> 11774.8 | Z18: 753 | AA18: 19 มิ.ย.69
A19: 19 - 21 มิ.ย. 69 | C19: ป 2569/00183 | D19: ป 2569/00184 | E19: 2 | F19: 4300 | Q19: ป 69/04103 | R19: ป 69/04108 | S19: 6 | T19: 6654 | W19: =SUM(E19,S19) -> 8 | X19: =SUM(F19,T19) -> 10954 | Z19: 762 | AA19: 22 มิ.ย. 69
A20: 22 มิ.ย. 69 | C20: - | D20: - | E20: - | F20: - | Q20: ป 69/04109 | R20: ป 69/04126 | S20: 18 | T20: 21364 | W20: =SUM(E20,S20) -> 18 | X20: =SUM(F20,T20) -> 21364 | Z20: 771 | AA20: 23 มิ.ย. 69
A21: 23 มิ.ย. 69 | C21: - | D21: - | E21: - | F21: - | Q21: ป 69/04127 | R21: ป 69/04137 | S21: 11 | T21: 12243 | W21: =SUM(E21,S21) -> 11 | X21: =SUM(F21,T21) -> 12243 | Z21: 779 | AA21: 24 มิ.ย. 69
A22: 24 มิ.ย. 69 | C22: ป 2569/00185 | D22: - | E22: 1 | F22: 200 | Q22: ป 69/04138 | R22: ป 69/04149 | S22: 12 | T22: 13479.4 | W22: =SUM(E22,S22) -> 13 | X22: =SUM(F22,T22) -> 13679.4 | Z22: 786 | AA22: 25 มิ.ย. 69
A23: 25 มิ.ย. 69 | C23: ป 2569/00186 | E23: 1 | F23: 200 | Q23: ป 69/04150 | R23: ป 69/04154 | S23: 5 | T23: 5575 | W23: =SUM(E23,S23) -> 6 | X23: =SUM(F23,T23) -> 5775 | Z23: 792 | AA23: 26 มิ.ย. 69
A24: 26 - 28 มิ.ย. 69 | C24: ป 2569/00187 | E24: 1 | F24: 200 | Q24: ป 69/04155 | R24: ป 69/04165 | S24: 11 | T24: 12277 | W24: =SUM(E24,S24) -> 12 | X24: =SUM(F24,T24) -> 12477 | Z24: 800 | AA24: 29 มิ.ย. 69
A25: 29 มิ.ย. 69 | C25: - | D25: - | E25: - | F25: - | Q25: ป 69/04166 | R25: ป 69/04173 | S25: 8 | T25: 8952 | W25: =SUM(E25,S25) -> 8 | X25: =SUM(F25,T25) -> 8952 | Z25: 809 | AA25: 30 มิ.ย. 69
A26: 30 มิ.ย. 69 | C26: - | D26: - | E26: - | F26: - | Q26: ป 69/04174 | R26: ป 69/04179 | S26: 6 | T26: 7700 | W26: =SUM(E26,S26) -> 6 | X26: =SUM(F26,T26) -> 7700 | Z26: 814 | AA26: 1 ก.ค. 69
A27: รวม | E27: =SUM(E6:E26) -> 11 | F27: =SUM(F6:F26) -> 11900 | I27: รวม | Q27: รวม | S27: =SUM(S6:S26) -> 184 | T27: =SUM(T6:T26) -> 221794.5 | U27: =SUM(U6:U26) -> 1 | V27: =SUM(V6:V26) -> 0 | W27: =SUM(W6:W26) -> 195 | X27: =SUM(X6:X26) -> 233694.5

Sheet ก.ค.69
A1: รายงานการรับชำระค่าธรรมเนียมผ่านไปรษณีย์ เดือน กรกฎาคม 2569
A3: วันที่ชำระ | B3: ข้อมูลกฎหมาย | C3: ระบบ Receipt (ใบเสร็จรับเงิน A4) | I3: ระบบ App (ใบเสร็จรับเงิน A5) | Q3: ระบบ Trade | W3: นำรายได้ ส่ง กค. พรบ.42 + พรบ.43 | Y3: หมายเหตุ | Z3: พน0401.1/ | AA3: วันที่ส่ง
B4: กฎหมาย | C4: จาก | D4: ถึง | E4: จำนวนใบเสร็จ | F4: จำนวนเงิน | G4: ยกเลิก/ใบเสร็จเสีย | I4: หมายเลขเล่ม | K4: จาก | L4: ถึง | M4: จำนวนใบเสร็จ | N4: จำนวนเงิน | O4: ยกเลิก/ใบเสร็จเสีย | Q4: จาก | R4: ถึง | S4: จำนวนใบเสร็จ | T4: จำนวนเงิน | U4: ยกเลิกใบเสร็จ | W4: รวมจำนวนใบเสร็จ | X4: รวมจำนวนเงิน
G5: จำนวนใบเสร็จ | H5: เลขที่ใบเสร็จ | O5: จำนวนใบเสร็จ | P5: เลขที่ใบเสร็จ | U5: จำนวนใบเสร็จ | V5: เลขที่ใบเสร็จ
A6: 1 ก.ค. 69 | C6: ป2569/00188 | D6: ป2569/00189 | E6: 2 | F6: 400 | Q6: ป69/04180 | R6: ป69/04185 | S6: 6 | T6: 6837.91 | W6: =SUM(E6,S6) -> 8 | X6: =SUM(F6,T6) -> 7237.91 | Z6: 822 | AA6: 2 ก.ค. 69
A7: 2 ก.ค. 69 | C7: ป2569/00190 | D7: ป2569/00191 | E7: 2 | F7: 400 | Q7: ป69/04186 | R7: ป69/04191 | S7: 6 | T7: 7091.64 | W7: =SUM(E7,S7) -> 8 | X7: =SUM(F7,T7) -> 7491.64 | Z7: 827 | AA7: 3 ก.ค. 69
A8: 3 - 5 ก.ค. 69 | C8: - | D8: - | E8: - | F8: - | Q8: ป69/04192 | R8: ป69/04196 | S8: 5 | T8: 5614.5 | W8: =SUM(E8,S8) -> 5 | X8: =SUM(F8,T8) -> 5614.5 | Z8: 834 | AA8: 6 ก.ค. 69
A9: 6 ก.ค. 69 | C9: - | D9: - | E9: - | F9: - | Q9: ป69/04197 | R9: ป69/04210 | S9: 14 | T9: 16999.72 | W9: =SUM(E9,S9) -> 14 | X9: =SUM(F9,T9) -> 16999.72 | Z9: 842 | AA9: 7 ก.ค. 69
A10: 7 ก.ค. 69 | C10: - | D10: - | E10: - | F10: - | Q10: ป69/04211 | R10: ป69/04214 | S10: 4 | T10: 4507.08 | W10: =SUM(E10,S10) -> 4 | X10: =SUM(F10,T10) -> 4507.08 | Z10: 846 | AA10: 8 ก.ค. 69
A11: 8 ก.ค. 69 | C11: ป2569/00192 | D11: - | E11: 1 | F11: 2500 | Q11: ป69/04215 | R11: ป69/04222 | S11: 8 | T11: 15133.41 | W11: =SUM(E11,S11) -> 9 | X11: =SUM(F11,T11) -> 17633.41 | Z11: 852 | AA11: 9 ก.ค. 69
A12: 9 ก.ค. 69 | C12: ป2569/00193 | E12: 1 | F12: 200 | Q12: ป69/04223 | R12: ป69/04228 | S12: 6 | T12: 6772.26 | W12: =SUM(E12,S12) -> 7 | X12: =SUM(F12,T12) -> 6972.26 | Z12: 858 | AA12: 10 ก.ค. 69
A13: 10 - 12 ก.ค. 69 | C13: ป2569/00194 | E13: 1 | F13: 200 | Q13: ป69/04229 | R13: ป69/04236 | S13: 8 | T13: 9758.41 | W13: =SUM(E13,S13) -> 9 | X13: =SUM(F13,T13) -> 9958.41 | Z13: 865 | AA13: 13 ก.ค. 69
A14: 13 ก.ค. 69 | C14: - | D14: - | E14: - | F14: - | Q14: ป69/04237 | R14: ป69/04248 | S14: 12 | T14: 14460.22 | W14: =SUM(E14,S14) -> 12 | X14: =SUM(F14,T14) -> 14460.22 | Z14: 872 | AA14: 14 ก.ค. 69
A15: 14 ก.ค. 69 | C15: - | D15: - | E15: - | F15: - | Q15: ป69/04249 | R15: ป69/04256 | S15: 8 | T15: 10508.4 | W15: =SUM(E15,S15) -> 8 | X15: =SUM(F15,T15) -> 10508.4 | Z15: 879 | AA15: 15 ก.ค. 69
A16: 15 ก.ค. 69 | C16: - | D16: - | E16: - | F16: - | Q16: ป69/04257 | R16: ป69/04262 | S16: 6 | T16: 7527.12 | W16: =SUM(E16,S16) -> 6 | X16: =SUM(F16,T16) -> 7527.12 | Z16: 886 | AA16: 16 ก.ค. 69
A17: 16 ก.ค. 69 | C17: ป2569/00195 | D17: - | E17: 1 | F17: 200 | Q17: ป69/04263 | R17: ป69/04271 | S17: 9 | T17: 10939.32 | W17: =SUM(E17,S17) -> 10 | X17: =SUM(F17,T17) -> 11139.32 | Z17: 893 | AA17: 17 ก.ค. 69
A18: 17 - 19 ก.ค. 69 | C18: - | D18: - | E18: - | F18: - | Q18: ป69/04272 | R18: ป69/04281 | S18: 10 | T18: 12084.5 | W18: =SUM(E18,S18) -> 10 | X18: =SUM(F18,T18) -> 12084.5 | Z18: 897 | AA18: 20 ก.ค. 69
A19: 20 ก.ค. 69 | C19: - | D19: - | E19: - | F19: - | Q19: ป69/04282 | R19: ป69/04286 | S19: 5 | T19: 6056.75 | W19: =SUM(E19,S19) -> 5 | X19: =SUM(F19,T19) -> 6056.75 | Z19: 905 | AA19: 21 ก.ค. 69
A20: 21 ก.ค. 69 | C20: ป2569/00196 | D20: - | E20: 1 | F20: 200 | Q20: ป69/04287 | R20: ป69/04288 | S20: 2 | T20: 2280.64 | W20: =SUM(E20,S20) -> 3 | X20: =SUM(F20,T20) -> 2480.64 | Z20: 911 | AA20: 22 ก.ค. 69
A21: 22 ก.ค. 69 | C21: - | D21: - | E21: - | F21: - | Q21: ป69/04289 | R21: ป69/04296 | S21: 8 | T21: 9490.32 | W21: =SUM(E21,S21) -> 8 | X21: =SUM(F21,T21) -> 9490.32 | Z21: 916 | AA21: 23 ก.ค. 69
A22: 23 ก.ค. 69 | C22: - | D22: - | E22: - | F22: - | Q22: ป69/04297 | R22: ป69/04303 | S22: 7 | T22: 7995.82 | W22: =SUM(E22,S22) -> 7 | X22: =SUM(F22,T22) -> 7995.82 | Z22: 921 | AA22: 24 ก.ค. 69
A23: 24 - 26 ก.ค. 69 | C23: ป2569/00197 | D23: ป2569/00198 | E23: 2 | F23: 3100 | Q23: ป69/04304 | R23: ป69/04310 | S23: 7 | T23: 9076.68 | W23: =SUM(E23,S23) -> 9 | X23: =SUM(F23,T23) -> 12176.68 | Z23: 928 | AA23: 27 ก.ค. 69
A24: 27 - 30 ก.ค. 69 | C24: - | D24: - | E24: - | F24: - | Q24: ป69/04311 | R24: ป69/04314 | S24: 4 | T24: 5304.52 | W24: =SUM(E24,S24) -> 4 | X24: =SUM(F24,T24) -> 5304.52 | Z24: 936 | AA24: 31 ก.ค. 69
A25: รวม | E25: =SUM(E6:E24) -> 11 | F25: =SUM(F6:F24) -> 7200 | I25: รวม | Q25: รวม | S25: =SUM(S6:S24) -> 135 | T25: =SUM(T6:T24) -> 168439.22 | U25: =SUM(U6:U24) -> 0 | V25: =SUM(V6:V24) -> 0 | W25: =SUM(W6:W24) -> 146 | X25: =SUM(X6:X24) -> 175639.22

Sheet ส.ค.69
A1: รายงานการรับชำระค่าธรรมเนียมผ่านไปรษณีย์ เดือน สิงหาคม 2569
A3: วันที่ชำระ | B3: ข้อมูลกฎหมาย | C3: ระบบ Receipt (ใบเสร็จรับเงิน A4) | I3: ระบบ App (ใบเสร็จรับเงิน A5) | Q3: ระบบ Trade | W3: นำรายได้ ส่ง กค. พรบ.42 + พรบ.43 | Y3: หมายเหตุ | Z3: พน0401.1/ | AA3: วันที่ส่ง
B4: กฎหมาย | C4: จาก | D4: ถึง | E4: จำนวนใบเสร็จ | F4: จำนวนเงิน | G4: ยกเลิก/ใบเสร็จเสีย | I4: หมายเลขเล่ม | K4: จาก | L4: ถึง | M4: จำนวนใบเสร็จ | N4: จำนวนเงิน | O4: ยกเลิก/ใบเสร็จเสีย | Q4: จาก | R4: ถึง | S4: จำนวนใบเสร็จ | T4: จำนวนเงิน | U4: ยกเลิกใบเสร็จ | W4: รวมจำนวนใบเสร็จ | X4: รวมจำนวนเงิน
G5: จำนวนใบเสร็จ | H5: เลขที่ใบเสร็จ | O5: จำนวนใบเสร็จ | P5: เลขที่ใบเสร็จ | U5: จำนวนใบเสร็จ | V5: เลขที่ใบเสร็จ
A6: 31 ก.ค. - 2 ส.ค. 69 | C6: - | Q6: ป69/04315 | R6: ป69/04324 | S6: 10 | T6: 12110 | W6: =SUM(E6,S6) -> 10 | X6: =SUM(F6,T6) -> 12110 | Z6: 943 | AA6: 3 ส.ค. 69
A7: 3 ส.ค. 69 | C7: - | Q7: ป69/04325 | R7: ป69/04332 | S7: 8 | T7: 9583.2 | W7: =SUM(E7,S7) -> 8 | X7: =SUM(F7,T7) -> 9583.2 | Z7: 946 | AA7: 4 ส.ค. 69
A8: 4 ส.ค. 69 | C8: - | Q8: ป69/04333 | R8: - | S8: 1 | T8: 1153.87 | W8: =SUM(E8,S8) -> 1 | X8: =SUM(F8,T8) -> 1153.87 | Z8: 953 | AA8: 5 ส.ค. 69
A9: 5 ส.ค. 69 | C9: - | Q9: ป69/04334 | R9: ป69/04336 | S9: 3 | T9: 3824.52 | W9: =SUM(E9,S9) -> 3 | X9: =SUM(F9,T9) -> 3824.52 | Z9: 960 | AA9: 6 ส.ค. 69
A10: 6 ส.ค. 69 | C10: - | Q10: ป69/04337 | R10: ป69/04340 | S10: 4 | T10: 6287.43 | W10: =SUM(E10,S10) -> 4 | X10: =SUM(F10,T10) -> 6287.43 | Z10: 964 | AA10: 7 ส.ค. 69
A11: 7 - 9 ส.ค. 69 | C11: - | Q11: ป69/04341 | R11: ป69/04342 | S11: 2 | T11: 2673.54 | W11: =SUM(E11,S11) -> 2 | X11: =SUM(F11,T11) -> 2673.54 | Z11: 970 | AA11: 10 ส.ค. 69
A12: 10 ส.ค. 69 | C12: - | Q12: ป69/04343 | R12: ป69/04344 | S12: 2 | T12: 5798.39 | W12: =SUM(E12,S12) -> 2 | X12: =SUM(F12,T12) -> 5798.39 | Z12: 976 | AA12: 11 ส.ค. 69
A13: 11 - 12 ส.ค. 69 | C13: - | Q13: ป69/04345 | R13: ป69/04346 | S13: 2 | T13: 3041.3 | W13: =SUM(E13,S13) -> 2 | X13: =SUM(F13,T13) -> 3041.3 | Z13: 982 | AA13: 13 ส.ค. 69
A14: 13 ส.ค. 69 | C14: ป2569/00199 | D14: ป2569/00200 | E14: 2 | F14: 400 | Q14: ป69/04347 | R14: - | S14: 1 | T14: 1162.58 | W14: =SUM(E14,S14) -> 3 | X14: =SUM(F14,T14) -> 1562.58 | Z14: 989 | AA14: 14 ส.ค. 69
A15: 14 - 16 ส.ค. 69 | C15: ป2569/00201 | D15: ป2569/00202 | E15: 2 | F15: 400 | Q15: ป69/04348 | R15: ป69/04355 | S15: 8 | T15: 10948.3 | W15: =SUM(E15,S15) -> 10 | X15: =SUM(F15,T15) -> 11348.3 | Z15: 1000 | AA15: 17 ส.ค. 69
A16: 17 ส.ค. 69 | C16: ป2569/00203 | D16: - | E16: 1 | F16: 500 | Q16: ป69/04356 | R16: ป69/04360 | S16: 5 | T16: 8860.64 | W16: =SUM(E16,S16) -> 6 | X16: =SUM(F16,T16) -> 9360.64 | Z16: 1006 | AA16: 18 ส.ค. 69
A17: 18 ส.ค. 69 | C17: - | Q17: ป69/04361 | R17: ป69/04368 | S17: 8 | T17: 12373.3 | W17: =SUM(E17,S17) -> 8 | X17: =SUM(F17,T17) -> 12373.3 | Z17: 1011 | AA17: 19 ส.ค. 69
A18: 19 ส.ค. 69 | C18: ป2569/00204 | D18: ป2569/00205 | E18: 2 | F18: 400 | Q18: ป69/04369 | R18: ป69/04372 | S18: 4 | T18: 6893.49 | W18: =SUM(E18,S18) -> 6 | X18: =SUM(F18,T18) -> 7293.49 | Z18: 1017 | AA18: 20 ส.ค. 69
A19: 20 ส.ค. 69 | C19: - | Q19: ป69/04373 | R19: ป69/04378 | S19: 6 | T19: 8563.59 | W19: =SUM(E19,S19) -> 6 | X19: =SUM(F19,T19) -> 8563.59 | Z19: 1022 | AA19: 21 ส.ค. 69
A20: 21 - 23 ส.ค. 69 | C20: - | Q20: ป69/04379 | R20: ป69/04387 | S20: 9 | T20: 13307.34 | W20: =SUM(E20,S20) -> 9 | X20: =SUM(F20,T20) -> 13307.34 | Z20: 1030 | AA20: 24 ส.ค. 69
A21: 24 ส.ค. 69 | C21: - | Q21: ป69/04388 | R21: ป69/04400 | S21: 13 | T21: 16331.99 | W21: =SUM(E21,S21) -> 13 | X21: =SUM(F21,T21) -> 16331.99 | Z21: 1034 | AA21: 25 ส.ค. 69
A22: 25 ส.ค. 69 | C22: - | Q22: ป69/04401 | R22: ป69/04406 | S22: 6 | T22: 7045.14 | W22: =SUM(E22,S22) -> 6 | X22: =SUM(F22,T22) -> 7045.14 | Z22: 1046 | AA22: 26 ส.ค. 69
A23: 26 ส.ค. 69 | C23: ป2569/00206 | E23: 1 | F23: 720 | Q23: ป69/04407 | R23: ป69/04415 | S23: 9 | T23: 19170.03 | W23: =SUM(E23,S23) -> 10 | X23: =SUM(F23,T23) -> 19890.03 | Z23: 1052 | AA23: 27 ส.ค. 69
A24: 27 ส.ค. 69 | C24: ป2569/00207 | D24: ป2569/00208 | E24: 2 | F24: 2700 | Q24: ป69/04416 | R24: ป69/04419 | S24: 4 | T24: 4704.52 | W24: =SUM(E24,S24) -> 6 | X24: =SUM(F24,T24) -> 7404.52 | Z24: 1058 | AA24: 28 ส.ค. 69
A25: 28 - 30 ส.ค. 69 | C25: ป2569/00209 | D25: - | E25: 1 | F25: 500 | Q25: ป69/04420 | R25: ป69/04432 | S25: 13 | T25: 21910.66 | W25: =SUM(E25,S25) -> 14 | X25: =SUM(F25,T25) -> 22410.66 | Z25: 1065 | AA25: 31 ส.ค. 69
A26: 31 ส.ค. 69 | C26: ป2569/00210 | D26: - | E26: 1 | F26: 3400 | Q26: ป69/04433 | R26: ป69/04444 | S26: 12 | T26: 14874 | W26: =SUM(E26,S26) -> 13 | X26: =SUM(F26,T26) -> 18274 | Z26: 1072 | AA26: 1 ก.ย. 69
A27: รวม | E27: =SUM(E6:E26) -> 12 | F27: =SUM(F6:F26) -> 9020 | I27: รวม | Q27: รวม | S27: =SUM(S6:S26) -> 130 | T27: =SUM(T6:T26) -> 190617.83 | U27: =SUM(U6:U26) -> 0 | V27: =SUM(V6:V26) -> 0 | W27: =SUM(W6:W26) -> 142 | X27: =SUM(X6:X26) -> 199637.83

Sheet ก.ย.69
A1: รายงานการรับชำระค่าธรรมเนียมผ่านไปรษณีย์ เดือน กันยายน 2569
A3: วันที่ชำระ | B3: ข้อมูลกฎหมาย | C3: ระบบ Receipt (ใบเสร็จรับเงิน A4) | I3: ระบบ App (ใบเสร็จรับเงิน A5) | Q3: ระบบ Trade | W3: นำรายได้ ส่ง กค. พรบ.42 + พรบ.43 | Y3: หมายเหตุ | Z3: พน0401.1/ | AA3: วันที่ส่ง
B4: กฎหมาย | C4: จาก | D4: ถึง | E4: จำนวนใบเสร็จ | F4: จำนวนเงิน | G4: ยกเลิก/ใบเสร็จเสีย | I4: หมายเลขเล่ม | K4: จาก | L4: ถึง | M4: จำนวนใบเสร็จ | N4: จำนวนเงิน | O4: ยกเลิก/ใบเสร็จเสีย | Q4: จาก | R4: ถึง | S4: จำนวนใบเสร็จ | T4: จำนวนเงิน | U4: ยกเลิกใบเสร็จ | W4: รวมจำนวนใบเสร็จ | X4: รวมจำนวนเงิน
G5: จำนวนใบเสร็จ | H5: เลขที่ใบเสร็จ | O5: จำนวนใบเสร็จ | P5: เลขที่ใบเสร็จ | U5: จำนวนใบเสร็จ | V5: เลขที่ใบเสร็จ
A6: 1 ก.ย.. 69 | C6: ป2569/00211 | D6: - | E6: 1 | F6: 200 | Q6: ป69/04445 | R6: ป69/04455 | S6: 11 | T6: 15511 | W6: =SUM(E6,S6) -> 12 | X6: =SUM(F6,T6) -> 15711 | Z6: 1084 | AA6: 2 ก.ย. 69
A7: 2 ก.ย.. 69 | C7: - | Q7: ป69/04456 | R7: ป69/04459 | S7: 4 | T7: 4728 | W7: =SUM(E7,S7) -> 4 | X7: =SUM(F7,T7) -> 4728 | Z7: 1090 | AA7: 3 ก.ย. 69
A8: 3 ก.ย.. 69 | C8: ป2569/00212 | D8: ป2569/00213 | E8: 2 | F8: 1000 | Q8: ป69/04460 | R8: ป69/04462 | S8: 3 | T8: 2766 | W8: =SUM(E8,S8) -> 5 | X8: =SUM(F8,T8) -> 3766 | Z8: 1097 | AA8: 4 ก.ย. 69
A9: 4 - 6 ก.ย.. 69 | C9: ป2569/00214 | D9: - | E9: 1 | F9: 200 | Q9: ป69/04463 | R9: ป69/04469 | S9: 7 | T9: 8649 | W9: =SUM(E9,S9) -> 8 | X9: =SUM(F9,T9) -> 8849 | Z9: 1106 | AA9: 7 ก.ย. 69
A10: 7 ก.ย.. 69 | C10: - | Q10: ป69/04470 | R10: ป69/04471 | S10: 2 | T10: 2374 | W10: =SUM(E10,S10) -> 2 | X10: =SUM(F10,T10) -> 2374 | Z10: 1111 | AA10: 8 ก.ย. 69
A11: 8 ก.ย.. 69 | C11: - | Q11: ป69/04472 | R11: ป69/04475 | S11: 4 | T11: 5986.8 | W11: =SUM(E11,S11) -> 4 | X11: =SUM(F11,T11) -> 5986.8 | Z11: 1116 | AA11: 9 ก.ย. 69
A12: 9 ก.ย.. 69 | C12: - | Q12: ป69/04476 | R12: ป69/04477 | S12: 2 | T12: 3818 | W12: =SUM(E12,S12) -> 2 | X12: =SUM(F12,T12) -> 3818 | Z12: 1123 | AA12: 10 ก.ย. 69
A13: 10 ก.ย.. 69 | C13: ป2569/00215 | D13: ป2569/00218 | E13: 4 | F13: 8200 | Q13: ป69/04478 | R13: ป69/04482 | S13: 5 | T13: 9523 | W13: =SUM(E13,S13) -> 9 | X13: =SUM(F13,T13) -> 17723 | Z13: 1129 | AA13: 11 ก.ย. 69
A14: 11 - 13 ก.ย.. 69 | C14: - | Q14: - | W14: =SUM(E14,S14) -> 0 | X14: =SUM(F14,T14) -> 0 | Z14: 1139 | AA14: 14 ก.ย. 69
A15: 14 ก.ย.. 69 | W15: =SUM(E15,S15) -> 0 | X15: =SUM(F15,T15) -> 0
A16: 15 ก.ย.. 69 | W16: =SUM(E16,S16) -> 0 | X16: =SUM(F16,T16) -> 0
A17: 16 ก.ย.. 69 | W17: =SUM(E17,S17) -> 0 | X17: =SUM(F17,T17) -> 0
A18: 17 ก.ย.. 69 | W18: =SUM(E18,S18) -> 0 | X18: =SUM(F18,T18) -> 0
A19: 18 - 20 ก.ย.. 69 | W19: =SUM(E19,S19) -> 0 | X19: =SUM(F19,T19) -> 0
A20: 21 ก.ย.. 69 | W20: =SUM(E20,S20) -> 0 | X20: =SUM(F20,T20) -> 0
A21: 22 ก.ย.. 69 | W21: =SUM(E21,S21) -> 0 | X21: =SUM(F21,T21) -> 0
A22: 23 ก.ย.. 69 | W22: =SUM(E22,S22) -> 0 | X22: =SUM(F22,T22) -> 0
A23: 24 ก.ย.. 69 | W23: =SUM(E23,S23) -> 0 | X23: =SUM(F23,T23) -> 0
A24: 25 - 27 ก.ย.. 69 | W24: =SUM(E24,S24) -> 0 | X24: =SUM(F24,T24) -> 0
A25: 28 ก.ย.. 69 | W25: =SUM(E25,S25) -> 0 | X25: =SUM(F25,T25) -> 0
A26: 29 ก.ย.. 69 | W26: =SUM(E26,S26) -> 0 | X26: =SUM(F26,T26) -> 0
A27: 30 ก.ย.. 69 | W27: =SUM(E27,S27) -> 0 | X27: =SUM(F27,T27) -> 0
A28: รวม | E28: =SUM(E6:E27) -> 8 | F28: =SUM(F6:F27) -> 9600 | I28: รวม | Q28: รวม | S28: =SUM(S6:S27) -> 38 | T28: =SUM(T6:T27) -> 53355.8 | U28: =SUM(U6:U27) -> 0 | V28: =SUM(V6:V27) -> 0 | W28: =SUM(W6:W27) -> 46 | X28: =SUM(X6:X27) -> 62955.8

Sheet สรุปยอด
A1: รายงานการรับชำระค่าธรรมเนียมผ่านไปรษณีย์ 2569
A3: เดือน | B3: ระบบ Safety | D3: ระบบ Receipt | F3: ระบบ Trade | H3: รวม 2 ช่องทาง
B4: จำนวนใบเสร็จ | C4: จำนวนเงิน | D4: จำนวนใบเสร็จ | E4: จำนวนเงิน | F4: จำนวนใบเสร็จ | G4: จำนวนเงิน | H4: จำนวนใบเสร็จ | I4: จำนวนเงิน
A5: ต.ค.68 | D5: ='ต.ค.68'!D26 -> 30 | E5: ='ต.ค.68'!E26 -> 17100 | F5: ='ต.ค.68'!R26 -> 47 | G5: ='ต.ค.68'!S26 -> 79460.86 | H5: =SUM(B5,D5,F5) -> 77 | I5: =SUM(C5,E5,G5) -> 96560.86
A6: พ.ย.68 | D6: ='พ.ย.68'!D27 -> 34 | E6: ='พ.ย.68'!E27 -> 19630 | F6: ='พ.ย.68'!R27 -> 31 | G6: ='พ.ย.68'!S27 -> 44979.7 | H6: =SUM(B6,D6,F6) -> 65 | I6: =SUM(C6,E6,G6) -> 64609.7
A7: ธ.ค.68 | D7: ='ธ.ค. 68'!D25 -> 35 | E7: ='ธ.ค. 68'!E25 -> 33350 | F7: ='ธ.ค. 68'!R25 -> 842 | G7: ='ธ.ค. 68'!S25 -> 1159370.6 | H7: =SUM(B7,D7,F7) -> 877 | I7: =SUM(C7,E7,G7) -> 1192720.6
A8: ม.ค.69 | D8: ='ม.ค. 69'!D26 -> 28 | E8: ='ม.ค. 69'!E26 -> 25380 | F8: ='ม.ค. 69'!R26 -> 1000 | G8: ='ม.ค. 69'!S26 -> 1376658.1 | H8: =SUM(B8,D8,F8) -> 1028 | I8: =SUM(C8,E8,G8) -> 1402038.1
A9: ก.พ.69 | D9: ='ก.พ. 69'!D26 -> 14 | E9: ='ก.พ. 69'!E26 -> 4950 | F9: ='ก.พ. 69'!R26 -> 849 | G9: ='ก.พ. 69'!S26 -> 1131272.6 | H9: =SUM(B9,D9,F9) -> 863 | I9: =SUM(C9,E9,G9) -> 1136222.6
A10: มี.ค.69 | D10: ='มี.ค. 69'!D28 -> 12 | E10: ='มี.ค. 69'!E28 -> 4250 | F10: ='มี.ค. 69'!R28 -> 480 | G10: ='มี.ค. 69'!S28 -> 632665.06 | H10: =SUM(B10,D10,F10) -> 492 | I10: =SUM(C10,E10,G10) -> 636915.06
A11: เม.ย.69 | D11: ='เม.ย. 69'!D24 -> 11 | E11: ='เม.ย. 69'!E24 -> 7800 | F11: ='เม.ย. 69'!R24 -> 390 | G11: ='เม.ย. 69'!S24 -> 483442.3 | H11: =SUM(B11,D11,F11) -> 401 | I11: =SUM(C11,E11,G11) -> 491242.3
A12: พ.ค.69 | D12: ='พ.ค.69'!D24 -> 5 | E12: ='พ.ค.69'!E24 -> 2400 | F12: ='พ.ค.69'!R24 -> 342 | G12: ='พ.ค.69'!S24 -> 444003.56 | H12: =SUM(B12,D12,F12) -> 347 | I12: =SUM(C12,E12,G12) -> 446403.56
