Workbook

Sheet ต้นฉบับ
A1: รายงานการรับชำระค่าธรรมเนียมผ่านธนาคาร เดือน ตุลาคม 2568
A3: วันที่ชำระ | B3: ข้อมูลกฎหมาย | C3: ระบบ Safety | G3: ระบบ Receipt (ใบเสร็จรับเงิน A4) | M3: รวมพรบ.42 (Safety + Receipt) | O3: ระบบ Trade | U3: รวมพรบ.2543 (Trade) | W3: นำรายได้ ส่ง คพ. พรบ.42 + พรบ.43 | Y3: หมายเหตุ | Z3: พน0401.1/ | AA3: EDC | AB3: วันที่ส่ง
B4: กฎหมาย | C4: จำนวนใบเสร็จ | D4: จำนวนเงิน | E4: ยกเลิกใบเสร็จ | G4: จาก | H4: ถึง | I4: จำนวนใบเสร็จ | J4: จำนวนเงิน | K4: ยกเลิก/ใบเสร็จเสีย | M4: รวมจำนวนใบเสร็จ | N4: รวมจำนวนเงิน | O4: จาก | P4: ถึง | Q4: จำนวนใบเสร็จ | R4: จำนวนเงิน | S4: ยกเลิกใบเสร็จ | U4: รวมจำนวนใบเสร็จ | V4: รวมจำนวนเงิน | W4: รวมจำนวนใบเสร็จ | X4: รวมจำนวนเงิน | AA4: พน0401.1/
E5: จำนวนใบเสร็จ | F5: เลขที่ใบเสร็จ | K5: จำนวนใบเสร็จ | L5: เลขที่ใบเสร็จ | S5: จำนวนใบเสร็จ | T5: เลขที่ใบเสร็จ
C6: - | M6: =SUM(C6,I6) -> 0 | N6: =SUM(D6,J6) -> 0 | U6: =#REF! -> #REF! | V6: =R6 -> 0 | W6: =SUM(M6,Q6) -> 0 | X6: =SUM(N6,R6) -> 0
C7: - | M7: =SUM(C7,I7) -> 0 | N7: =SUM(D7,J7) -> 0 | U7: =#REF! -> #REF! | V7: =R7 -> 0 | W7: =SUM(M7,Q7) -> 0 | X7: =SUM(N7,R7) -> 0
M8: =SUM(C8,I8) -> 0 | N8: =SUM(D8,J8) -> 0 | U8: =#REF! -> #REF! | V8: =R8 -> 0 | W8: =SUM(M8,Q8) -> 0 | X8: =SUM(N8,R8) -> 0
M9: =SUM(C9,I9) -> 0 | N9: =SUM(D9,J9) -> 0 | U9: =#REF! -> #REF! | V9: =R9 -> 0 | W9: =SUM(M9,Q9) -> 0 | X9: =SUM(N9,R9) -> 0
M10: =SUM(C10,I10) -> 0 | N10: =SUM(D10,J10) -> 0 | U10: =#REF! -> #REF! | V10: =R10 -> 0 | W10: =SUM(M10,Q10) -> 0 | X10: =SUM(N10,R10) -> 0
M11: =SUM(C11,I11) -> 0 | N11: =SUM(D11,J11) -> 0 | U11: =#REF! -> #REF! | V11: =R11 -> 0 | W11: =SUM(M11,Q11) -> 0 | X11: =SUM(N11,R11) -> 0
M12: =SUM(C12,I12) -> 0 | N12: =SUM(D12,J12) -> 0 | U12: =#REF! -> #REF! | V12: =R12 -> 0 | W12: =SUM(M12,Q12) -> 0 | X12: =SUM(N12,R12) -> 0
M13: =SUM(C13,I13) -> 0 | N13: =SUM(D13,J13) -> 0 | U13: =#REF! -> #REF! | V13: =R13 -> 0 | W13: =SUM(M13,Q13) -> 0 | X13: =SUM(N13,R13) -> 0
M14: =SUM(C14,I14) -> 0 | N14: =SUM(D14,J14) -> 0 | U14: =#REF! -> #REF! | V14: =R14 -> 0 | W14: =SUM(M14,Q14) -> 0 | X14: =SUM(N14,R14) -> 0
M15: =SUM(C15,I15) -> 0 | N15: =SUM(D15,J15) -> 0 | U15: =#REF! -> #REF! | V15: =R15 -> 0 | W15: =SUM(M15,Q15) -> 0 | X15: =SUM(N15,R15) -> 0
M16: =SUM(C16,I16) -> 0 | N16: =SUM(D16,J16) -> 0
M17: =SUM(C17,I17) -> 0 | N17: =SUM(D17,J17) -> 0
M18: =SUM(C18,I18) -> 0 | N18: =SUM(D18,J18) -> 0
M19: =SUM(C19,I19) -> 0 | N19: =SUM(D19,J19) -> 0
M20: =SUM(C20,I20) -> 0 | N20: =SUM(D20,J20) -> 0
M21: =SUM(C21,I21) -> 0 | N21: =SUM(D21,J21) -> 0
M22: =SUM(C22,I22) -> 0 | N22: =SUM(D22,J22) -> 0
M23: =SUM(C23,I23) -> 0 | N23: =SUM(D23,J23) -> 0
M24: =SUM(C24,I24) -> 0 | N24: =SUM(D24,J24) -> 0
M25: =SUM(C25,I25) -> 0 | N25: =SUM(D25,J25) -> 0
M26: =SUM(C26,I26) -> 0 | N26: =SUM(D26,J26) -> 0 | U26: =#REF! -> #REF! | V26: =R26 -> 0 | W26: =SUM(M26,Q26) -> 0 | X26: =SUM(N26,R26) -> 0
M27: =SUM(C27,I27) -> 0 | N27: =SUM(D27,J27) -> 0 | U27: =#REF! -> #REF! | V27: =R27 -> 0 | W27: =SUM(M27,Q27) -> 0 | X27: =SUM(N27,R27) -> 0
M28: =SUM(C28,I28) -> 0 | N28: =SUM(D28,J28) -> 0 | U28: =#REF! -> #REF! | V28: =R28 -> 0 | W28: =SUM(M28,Q28) -> 0 | X28: =SUM(N28,R28) -> 0
M29: =SUM(C29,I29) -> 0 | N29: =SUM(D29,J29) -> 0 | U29: =#REF! -> #REF! | V29: =R29 -> 0 | W29: =SUM(M29,Q29) -> 0 | X29: =SUM(N29,R29) -> 0
M30: =SUM(C30,I30) -> 0 | N30: =SUM(D30,J30) -> 0 | U30: =#REF! -> #REF! | V30: =R30 -> 0 | W30: =SUM(M30,Q30) -> 0 | X30: =SUM(N30,R30) -> 0
M31: =SUM(C31,I31) -> 0 | N31: =SUM(D31,J31) -> 0 | U31: =#REF! -> #REF! | V31: =R31 -> 0 | W31: =SUM(M31,Q31) -> 0 | X31: =SUM(N31,R31) -> 0
M32: =SUM(C32,I32) -> 0 | N32: =SUM(D32,J32) -> 0 | U32: =#REF! -> #REF! | V32: =R32 -> 0 | W32: =SUM(M32,Q32) -> 0 | X32: =SUM(N32,R32) -> 0
M33: =SUM(C33,I33) -> 0 | N33: =SUM(D33,J33) -> 0 | U33: =#REF! -> #REF! | V33: =R33 -> 0 | W33: =SUM(M33,Q33) -> 0 | X33: =SUM(N33,R33) -> 0
M34: =SUM(C34,I34) -> 0 | N34: =SUM(D34,J34) -> 0 | U34: =#REF! -> #REF! | V34: =R34 -> 0 | W34: =SUM(M34,Q34) -> 0 | X34: =SUM(N34,R34) -> 0
M35: =SUM(C35,I35) -> 0 | N35: =SUM(D35,J35) -> 0
M36: =SUM(C36,I36) -> 0 | N36: =SUM(D36,J36) -> 0 | U36: =#REF! -> #REF! | V36: =R36 -> 0 | W36: =SUM(M36,Q36) -> 0 | X36: =SUM(N36,R36) -> 0
A37: รวม | C37: =SUM(C6:C36) -> 0 | D37: =SUM(D6:D36) -> 0 | E37: =SUM(E6:E36) -> 0 | F37: =SUM(F6:F36) -> 0 | G37: รวม | I37: =SUM(I6:I36) -> 0 | J37: =SUM(J6:J36) -> 0 | K37: =SUM(K6:K36) -> 0 | L37: =SUM(L6:L36) -> 0 | M37: =SUM(M6:M36) -> 0 | N37: =SUM(N6:N36) -> 0 | O37: รวม | Q37: =SUM(Q6:Q36) -> 0 | R37: =SUM(R6:R36) -> 0 | S37: =SUM(S6:S36) -> 0 | T37: =SUM(T6:T36) -> 0 | U37: =SUM(U6:U36) -> #REF! | V37: =SUM(V6:V36) -> 0 | W37: =SUM(W6:W36) -> 0 | X37: =SUM(X6:X36) -> 0

Sheet ต.ค.68
A1: รายงานการรับชำระค่าธรรมเนียมผ่านธนาคาร เดือน ตุลาคม 2568
A3: วันที่ชำระ | B3: ข้อมูลกฎหมาย | C3: ระบบ Safety | G3: ระบบ Receipt (ใบเสร็จรับเงิน A4) | M3: รวมพรบ.42 (Safety + Receipt) | O3: ระบบ Trade | U3: รวมพรบ.2543 (Trade) | W3: นำรายได้ ส่ง คพ. พรบ.42 + พรบ.43 | Y3: หมายเหตุ | Z3: พน0401.1/ | AA3: EDC | AB3: วันที่ส่ง
B4: กฎหมาย | C4: จำนวนใบเสร็จ | D4: จำนวนเงิน | E4: ยกเลิกใบเสร็จ | G4: จาก | H4: ถึง | I4: จำนวนใบเสร็จ | J4: จำนวนเงิน | K4: ยกเลิก/ใบเสร็จเสีย | M4: รวมจำนวนใบเสร็จ | N4: รวมจำนวนเงิน | O4: จาก | P4: ถึง | Q4: จำนวนใบเสร็จ | R4: จำนวนเงิน | S4: ยกเลิกใบเสร็จ | U4: รวมจำนวนใบเสร็จ | V4: รวมจำนวนเงิน | W4: รวมจำนวนใบเสร็จ | X4: รวมจำนวนเงิน | AA4: พน0401.1/
E5: จำนวนใบเสร็จ | F5: เลขที่ใบเสร็จ | K5: จำนวนใบเสร็จ | L5: เลขที่ใบเสร็จ | S5: จำนวนใบเสร็จ | T5: เลขที่ใบเสร็จ
A6: 1 ต.ค. 68 | C6: - | G6: - | M6: =SUM(C6,I6) -> 0 | N6: =SUM(D6,J6) -> 0 | O6: - | U6: =#REF! -> #REF! | V6: =R6 -> 0 | W6: =SUM(M6,Q6) -> 0 | X6: =SUM(N6,R6) -> 0 | Z6: 1693 | AB6: 1 ต.ค. 68
A7: 2 ต.ค. 68 | C7: - | G7: ศ2569/00001 | H7: - | I7: 1 | J7: 500 | M7: =SUM(C7,I7) -> 1 | N7: =SUM(D7,J7) -> 500 | O7: - | U7: =#REF! -> #REF! | V7: =R7 -> 0 | W7: =SUM(M7,Q7) -> 1 | X7: =SUM(N7,R7) -> 500 | Z7: 1701 | AA7: 1702 | AB7: 2 ต.ค. 68
A8: 3 ต.ค. 68 | C8: 1 | D8: 1000 | G8: - | M8: =SUM(C8,I8) -> 1 | N8: =SUM(D8,J8) -> 1000 | O8: - | U8: =#REF! -> #REF! | V8: =R8 -> 0 | W8: =SUM(M8,Q8) -> 1 | X8: =SUM(N8,R8) -> 1000 | Z8: 1704 | AB8: 3 ต.ค. 68
A9: 6 ต.ค. 68 | C9: - | G9: ศ2569/00002 | H9: ศ2569/00004 | I9: 3 | J9: 600 | M9: =SUM(C9,I9) -> 3 | N9: =SUM(D9,J9) -> 600 | O9: - | U9: =#REF! -> #REF! | V9: =R9 -> 0 | W9: =SUM(M9,Q9) -> 3 | X9: =SUM(N9,R9) -> 600 | Z9: 1714 | AB9: 6 ต.ค. 68
A10: 7 ต.ค. 68 | C10: - | G10: - | M10: =SUM(C10,I10) -> 0 | N10: =SUM(D10,J10) -> 0 | O10: - | U10: =#REF! -> #REF! | V10: =R10 -> 0 | W10: =SUM(M10,Q10) -> 0 | X10: =SUM(N10,R10) -> 0 | Z10: 1720 | AB10: 7 ต.ค. 68
A11: 8 ต.ค. 68 | C11: - | G11: ศ2569/00005 | H11: - | I11: 1 | J11: 500 | M11: =SUM(C11,I11) -> 1 | N11: =SUM(D11,J11) -> 500 | O11: - | U11: =#REF! -> #REF! | V11: =R11 -> 0 | W11: =SUM(M11,Q11) -> 1 | X11: =SUM(N11,R11) -> 500 | Z11: 1726 | AB11: 8 ต.ค. 68
A12: 9 ต.ค. 68 | C12: - | G12: - | M12: =SUM(C12,I12) -> 0 | N12: =SUM(D12,J12) -> 0 | O12: - | U12: =#REF! -> #REF! | V12: =R12 -> 0 | W12: =SUM(M12,Q12) -> 0 | X12: =SUM(N12,R12) -> 0 | Z12: 1733 | AB12: 9 ต.ค. 68
A13: 10 ต.ค. 68 | C13: 12 | D13: 2400 | G13: ศ2569/00006 | H13: - | I13: 1 | J13: 500 | M13: =SUM(C13,I13) -> 13 | N13: =SUM(D13,J13) -> 2900 | O13: ศ69/00001 | P13: - | Q13: 1 | R13: 31100 | U13: =#REF! -> #REF! | V13: =R13 -> 31100 | W13: =SUM(M13,Q13) -> 14 | X13: =SUM(N13,R13) -> 34000 | Z13: 1739 | AA13: 1740 | AB13: 10 ต.ค. 68
A14: 14 ต.ค. 68 | C14: - | G14: ศ2569/00007 | H14: - | I14: 1 | J14: 200 | M14: =SUM(C14,I14) -> 1 | N14: =SUM(D14,J14) -> 200 | O14: - | U14: =#REF! -> #REF! | V14: =R14 -> 0 | W14: =SUM(M14,Q14) -> 1 | X14: =SUM(N14,R14) -> 200 | Z14: 1745
A15: 15 ต.ค. 68 | C15: - | G15: - | M15: =SUM(C15,I15) -> 0 | N15: =SUM(D15,J15) -> 0 | O15: - | U15: =#REF! -> #REF! | V15: =R15 -> 0 | W15: =SUM(M15,Q15) -> 0 | X15: =SUM(N15,R15) -> 0 | Z15: 1753 | AB15: 15 ต.ค. 68
A16: 16 ต.ค. 68 | C16: - | G16: - | M16: =SUM(C16,I16) -> 0 | N16: =SUM(D16,J16) -> 0 | O16: - | W16: =SUM(M16,Q16) -> 0 | X16: =SUM(N16,R16) -> 0 | Z16: 1760 | AB16: 16 ต.ค. 68
A17: 17 ต.ค. 68 | C17: - | G17: - | M17: =SUM(C17,I17) -> 0 | N17: =SUM(D17,J17) -> 0 | O17: ศ69/00002 | P17: - | Q17: 1 | R17: 31100 | W17: =SUM(M17,Q17) -> 1 | X17: =SUM(N17,R17) -> 31100 | Z17: 1767 | AB17: 17 ต.ค. 68
A18: 20 ต.ค. 68 | C18: - | G18: - | M18: =SUM(C18,I18) -> 0 | N18: =SUM(D18,J18) -> 0 | O18: - | W18: =SUM(M18,Q18) -> 0 | X18: =SUM(N18,R18) -> 0 | Z18: 1773 | AB18: 20 ต.ค. 68
A19: 21 ต.ค. 68 | C19: - | G19: ศ2569/00008 | H19: ศ2569/00011 | I19: 4 | J19: 6400 | M19: =SUM(C19,I19) -> 4 | N19: =SUM(D19,J19) -> 6400 | O19: - | W19: =SUM(M19,Q19) -> 4 | X19: =SUM(N19,R19) -> 6400 | Z19: 1779 | AB19: 21 ต.ค. 68
A20: 22 ต.ค. 68 | C20: - | G20: ศ2569/00012 | H20: - | I20: 1 | J20: 500 | M20: =SUM(C20,I20) -> 1 | N20: =SUM(D20,J20) -> 500 | O20: - | W20: =SUM(M20,Q20) -> 1 | X20: =SUM(N20,R20) -> 500 | Z20: 1786 | AB20: 22 ต.ค. 68
A21: 24 ต.ค. 68 | C21: - | G21: - | M21: =SUM(C21,I21) -> 0 | N21: =SUM(D21,J21) -> 0 | O21: - | W21: =SUM(M21,Q21) -> 0 | X21: =SUM(N21,R21) -> 0 | Z21: 1793 | AB21: 24 ต.ค. 68
A22: 27 ต.ค. 68 | C22: - | G22: - | M22: =SUM(C22,I22) -> 0 | N22: =SUM(D22,J22) -> 0 | O22: - | W22: =SUM(M22,Q22) -> 0 | X22: =SUM(N22,R22) -> 0 | Z22: 1801 | AB22: 27 ต.ค. 68
A23: 28 ต.ค. 68 | C23: - | G23: ศ2569/00013 | H23: - | I23: 1 | J23: 200 | M23: =SUM(C23,I23) -> 1 | N23: =SUM(D23,J23) -> 200 | O23: - | W23: =SUM(M23,Q23) -> 1 | X23: =SUM(N23,R23) -> 200 | Z23: 1807 | AB23: 28 ต.ค. 68
A24: 29 ต.ค. 68 | C24: - | G24: ศ2569/00014 | H24: - | I24: 1 | J24: 200 | M24: =SUM(C24,I24) -> 1 | N24: =SUM(D24,J24) -> 200 | O24: - | W24: =SUM(M24,Q24) -> 1 | X24: =SUM(N24,R24) -> 200 | Z24: 1814 | AB24: 29 ต.ค. 68
A25: 30 ต.ค. 68 | C25: - | G25: - | M25: =SUM(C25,I25) -> 0 | N25: =SUM(D25,J25) -> 0 | O25: - | W25: =SUM(M25,Q25) -> 0 | X25: =SUM(N25,R25) -> 0 | Z25: 1821 | AB25: 30 ต.ค. 68
A26: 31 ต.ค. 68 | C26: - | G26: ศ2569/00015 | H26: ศ2569/00016 | I26: 2 | J26: 900 | M26: =SUM(C26,I26) -> 2 | N26: =SUM(D26,J26) -> 900 | O26: ศ69/00003 | P26: ศ69/00004 | Q26: 2 | R26: 8000 | U26: =#REF! -> #REF! | V26: =R26 -> 8000 | W26: =SUM(M26,Q26) -> 4 | X26: =SUM(N26,R26) -> 8900 | Z26: 1828 | AA26: 2819 | AB26: 31 ต.ค. 68
A27: รวม | C27: =SUM(C6:C26) -> 13 | D27: =SUM(D6:D26) -> 3400 | E27: =SUM(E6:E26) -> 0 | F27: =SUM(F6:F26) -> 0 | G27: รวม | I27: =SUM(I6:I26) -> 16 | J27: =SUM(J6:J26) -> 10500 | K27: =SUM(K6:K26) -> 0 | L27: =SUM(L6:L26) -> 0 | M27: =SUM(M6:M26) -> 29 | N27: =SUM(N6:N26) -> 13900 | O27: รวม | Q27: =SUM(Q6:Q26) -> 4 | R27: =SUM(R6:R26) -> 70200 | S27: =SUM(S6:S26) -> 0 | T27: =SUM(T6:T26) -> 0 | U27: =SUM(U6:U26) -> #REF! | V27: =SUM(V6:V26) -> 39100 | W27: =SUM(W6:W26) -> 33 | X27: =SUM(X6:X26) -> 84100

Sheet พ.ย.68
A1: รายงานการรับชำระค่าธรรมเนียมผ่านธนาคาร เดือน พฤศจิกายน 2568
A3: วันที่ชำระ | B3: ข้อมูลกฎหมาย | C3: ระบบ Safety | G3: ระบบ Receipt (ใบเสร็จรับเงิน A4) | M3: รวมพรบ.42 (Safety + Receipt) | O3: ระบบ Trade | U3: รวมพรบ.2543 (Trade) | W3: นำรายได้ ส่ง คพ. พรบ.42 + พรบ.43 | Y3: หมายเหตุ | Z3: พน0401.1/ | AA3: EDC | AB3: วันที่ส่ง
B4: กฎหมาย | C4: จำนวนใบเสร็จ | D4: จำนวนเงิน | E4: ยกเลิกใบเสร็จ | G4: จาก | H4: ถึง | I4: จำนวนใบเสร็จ | J4: จำนวนเงิน | K4: ยกเลิก/ใบเสร็จเสีย | M4: รวมจำนวนใบเสร็จ | N4: รวมจำนวนเงิน | O4: จาก | P4: ถึง | Q4: จำนวนใบเสร็จ | R4: จำนวนเงิน | S4: ยกเลิกใบเสร็จ | U4: รวมจำนวนใบเสร็จ | V4: รวมจำนวนเงิน | W4: รวมจำนวนใบเสร็จ | X4: รวมจำนวนเงิน | AA4: พน0401.1/
E5: จำนวนใบเสร็จ | F5: เลขที่ใบเสร็จ | K5: จำนวนใบเสร็จ | L5: เลขที่ใบเสร็จ | S5: จำนวนใบเสร็จ | T5: เลขที่ใบเสร็จ
A6: 3 พ.ย. 68 | C6: - | G6: ศ2569/00017 | H6: - | I6: 1 | J6: 200 | M6: =SUM(C6,I6) -> 1 | N6: =SUM(D6,J6) -> 200 | O6: ศ69/00005 | P6: - | Q6: 1 | R6: 3600 | U6: =#REF! -> #REF! | V6: =R6 -> 3600 | W6: =SUM(M6,Q6) -> 2 | X6: =SUM(N6,R6) -> 3800 | Z6: 1838 | AB6: 3 พ.ย. 68
A7: 4 พ.ย. 68 | C7: 75 | D7: 224200 | G7: - | M7: =SUM(C7,I7) -> 75 | N7: =SUM(D7,J7) -> 224200 | O7: - | U7: =#REF! -> #REF! | V7: =R7 -> 0 | W7: =SUM(M7,Q7) -> 75 | X7: =SUM(N7,R7) -> 224200 | Z7: 1846 | AB7: 4 พ.ย. 68
A8: 5 พ.ย. 68 | C8: 170 | D8: 136300 | G8: - | M8: =SUM(C8,I8) -> 170 | N8: =SUM(D8,J8) -> 136300 | O8: - | U8: =#REF! -> #REF! | V8: =R8 -> 0 | W8: =SUM(M8,Q8) -> 170 | X8: =SUM(N8,R8) -> 136300 | Z8: 1854 | AB8: 5 พ.ย. 68
A9: 6 พ.ย. 68 | C9: 36 | D9: 100650 | G9: ศ2569/00018 | H9: - | I9: 1 | J9: 400 | M9: =SUM(C9,I9) -> 37 | N9: =SUM(D9,J9) -> 101050 | O9: - | U9: =#REF! -> #REF! | V9: =R9 -> 0 | W9: =SUM(M9,Q9) -> 37 | X9: =SUM(N9,R9) -> 101050 | Z9: 1859 | AA9: 1860 | AB9: 6 พ.ย. 68
A10: 7 พ.ย. 68 | C10: 31 | D10: 85200 | G10: ศ2569/00019 | H10: - | I10: 1 | J10: 3400 | M10: =SUM(C10,I10) -> 32 | N10: =SUM(D10,J10) -> 88600 | O10: ศ69/00006 | P10: - | Q10: 1 | R10: 5000 | U10: =#REF! -> #REF! | V10: =R10 -> 5000 | W10: =SUM(M10,Q10) -> 33 | X10: =SUM(N10,R10) -> 93600 | Z10: 1865 | AB10: 7 พ.ย. 68
A11: 10 พ.ย. 68 | C11: 239 | D11: 1046220 | G11: - | M11: =SUM(C11,I11) -> 239 | N11: =SUM(D11,J11) -> 1046220 | O11: - | U11: =#REF! -> #REF! | V11: =R11 -> 0 | W11: =SUM(M11,Q11) -> 239 | X11: =SUM(N11,R11) -> 1046220 | Z11: 1875 | AB11: 10 พ.ย. 68
A12: 11 พ.ย. 68 | C12: 78 | D12: 42400 | G12: ศ2569/00020,00022 | H12: ศ2569/00024 | I12: 4 | J12: 2700 | K12: 1 | L12: ศ2569/00021 | M12: =SUM(C12,I12) -> 82 | N12: =SUM(D12,J12) -> 45100 | O12: - | U12: =#REF! -> #REF! | V12: =R12 -> 0 | W12: =SUM(M12,Q12) -> 82 | X12: =SUM(N12,R12) -> 45100 | Z12: 1882 | AB12: 11 พ.ย. 68
A13: 12 พ.ย. 68 | C13: 104 | D13: 203400 | G13: - | M13: =SUM(C13,I13) -> 104 | N13: =SUM(D13,J13) -> 203400 | O13: - | U13: =#REF! -> #REF! | V13: =R13 -> 0 | W13: =SUM(M13,Q13) -> 104 | X13: =SUM(N13,R13) -> 203400 | Z13: 1887 | AB13: 12 พ.ย. 68
A14: 13 พ.ย. 68 | C14: 15 | D14: 22100 | G14: - | M14: =SUM(C14,I14) -> 15 | N14: =SUM(D14,J14) -> 22100 | O14: - | U14: =#REF! -> #REF! | V14: =R14 -> 0 | W14: =SUM(M14,Q14) -> 15 | X14: =SUM(N14,R14) -> 22100 | Z14: 1897 | AB14: 13 พ.ย. 68
A15: 14 พ.ย. 68 | C15: 82 | D15: 129090 | G15: - | M15: =SUM(C15,I15) -> 82 | N15: =SUM(D15,J15) -> 129090 | O15: - | U15: =#REF! -> #REF! | V15: =R15 -> 0 | W15: =SUM(M15,Q15) -> 82 | X15: =SUM(N15,R15) -> 129090 | Z15: 1904 | AB15: 14 พ.ย. 68
A16: 17 พ.ย. 68 | C16: 13 | D16: 17750 | G16: ศ2569/00025 | H16: ศ2569/00026 | I16: 2 | J16: 400 | M16: =SUM(C16,I16) -> 15 | N16: =SUM(D16,J16) -> 18150 | O16: - | U16: =#REF! -> #REF! | V16: =R16 -> 0 | W16: =SUM(M16,Q16) -> 15 | X16: =SUM(N16,R16) -> 18150 | Z16: 1907 | AB16: 17 พ.ย. 68
A17: 18 พ.ย. 68 | C17: 24 | D17: 23200 | G17: ศ2569/00027 | H17: ศ2569/00028 | I17: 2 | J17: 700 | M17: =SUM(C17,I17) -> 26 | N17: =SUM(D17,J17) -> 23900 | O17: - | U17: =#REF! -> #REF! | V17: =R17 -> 0 | W17: =SUM(M17,Q17) -> 26 | X17: =SUM(N17,R17) -> 23900 | Z17: 1916 | AB17: 18 พ.ย. 68
A18: 19 พ.ย. 68 | C18: 11 | D18: 122040 | G18: - | M18: =SUM(C18,I18) -> 11 | N18: =SUM(D18,J18) -> 122040 | O18: - | U18: =#REF! -> #REF! | V18: =R18 -> 0 | W18: =SUM(M18,Q18) -> 11 | X18: =SUM(N18,R18) -> 122040 | Z18: 1924 | AB18: 19 พ.ย. 68
A19: 20 พ.ย. 68 | C19: 1 | D19: 10160 | G19: - | M19: =SUM(C19,I19) -> 1 | N19: =SUM(D19,J19) -> 10160 | O19: - | U19: =#REF! -> #REF! | V19: =R19 -> 0 | W19: =SUM(M19,Q19) -> 1 | X19: =SUM(N19,R19) -> 10160 | Z19: 1932 | AB19: 20 พ.ย. 68
A20: 21 พ.ย. 68 | C20: 50 | D20: 215800 | G20: ศ2569/00029 | H20: ศ2569/00030 | I20: 2 | J20: 400 | M20: =SUM(C20,I20) -> 52 | N20: =SUM(D20,J20) -> 216200 | O20: - | U20: =#REF! -> #REF! | V20: =R20 -> 0 | W20: =SUM(M20,Q20) -> 52 | X20: =SUM(N20,R20) -> 216200 | Z20: 1937 | AB20: 21 พ.ย. 68
A21: 24 พ.ย. 68 | C21: 34 | D21: 1997550 | G21: ศ2569/00031 | H21: - | I21: 1 | J21: 200 | M21: =SUM(C21,I21) -> 35 | N21: =SUM(D21,J21) -> 1997750 | O21: ศ69/00007 | P21: - | Q21: 1 | R21: 1000 | U21: =#REF! -> #REF! | V21: =R21 -> 1000 | W21: =SUM(M21,Q21) -> 36 | X21: =SUM(N21,R21) -> 1998750 | Z21: 1946 | AA21: 1947 | AB21: 24 พ.ย. 68
A22: 25 พ.ย. 68 | C22: 15 | D22: 340180 | G22: ศ2569/00032 | H22: - | I22: 1 | J22: 3400 | M22: =SUM(C22,I22) -> 16 | N22: =SUM(D22,J22) -> 343580 | O22: - | U22: =#REF! -> #REF! | V22: =R22 -> 0 | W22: =SUM(M22,Q22) -> 16 | X22: =SUM(N22,R22) -> 343580 | Z22: 1952 | AB22: 25 พ.ย. 68
A23: 26 พ.ย. 68 | C23: 4 | D23: 6200 | G23: ศ2569/00033 | H23: - | I23: 1 | J23: 500 | M23: =SUM(C23,I23) -> 5 | N23: =SUM(D23,J23) -> 6700 | O23: - | U23: =#REF! -> #REF! | V23: =R23 -> 0 | W23: =SUM(M23,Q23) -> 5 | X23: =SUM(N23,R23) -> 6700 | Z23: 1960 | AA23: 1961 | AB23: 26 พ.ย. 68
A24: 27 พ.ย. 68 | C24: 223 | D24: 529390 | G24: - | M24: =SUM(C24,I24) -> 223 | N24: =SUM(D24,J24) -> 529390 | O24: - | W24: =SUM(M24,Q24) -> 223 | X24: =SUM(N24,R24) -> 529390 | Z24: 1967 | AB24: 27 พ.ย. 68
A25: 28 พ.ย. 68 | C25: 248 | D25: 2350790 | G25: - | M25: =SUM(C25,I25) -> 248 | N25: =SUM(D25,J25) -> 2350790 | O25: - | W25: =SUM(M25,Q25) -> 248 | X25: =SUM(N25,R25) -> 2350790 | Z25: 1974 | AB25: 28 พ.ย. 68
A26: รวม | C26: =SUM(C6:C25) -> 1453 | D26: =SUM(D6:D25) -> 7602620 | E26: =SUM(E6:E23) -> 0 | F26: =SUM(F6:F23) -> 0 | G26: รวม | I26: =SUM(I6:I25) -> 16 | J26: =SUM(J6:J25) -> 12300 | K26: =SUM(K6:K23) -> 1 | L26: =SUM(L6:L23) -> 0 | M26: =SUM(M6:M23) -> 998 | N26: =SUM(N6:N23) -> 4734740 | O26: รวม | Q26: =SUM(Q6:Q25) -> 3 | R26: =SUM(R6:R25) -> 9600 | S26: =SUM(S6:S23) -> 0 | T26: =SUM(T6:T23) -> 0 | U26: =SUM(U6:U23) -> #REF! | V26: =SUM(V6:V23) -> 9600 | W26: =SUM(W6:W25) -> 1472 | X26: =SUM(X6:X25) -> 7624520

Sheet ธ.ค.68
A1: รายงานการรับชำระค่าธรรมเนียมผ่านธนาคาร เดือน ธันวาคม 2568
A3: วันที่ชำระ | B3: ข้อมูลกฎหมาย | C3: ระบบ Safety | G3: ระบบ Receipt (ใบเสร็จรับเงิน A4) | M3: รวมพรบ.42 (Safety + Receipt) | O3: ระบบ Trade | U3: รวมพรบ.2543 (Trade) | W3: นำรายได้ ส่ง คพ. พรบ.42 + พรบ.43 | Y3: หมายเหตุ | Z3: พน0401.1/ | AA3: EDC | AB3: วันที่ส่ง
B4: กฎหมาย | C4: จำนวนใบเสร็จ | D4: จำนวนเงิน | E4: ยกเลิกใบเสร็จ | G4: จาก | H4: ถึง | I4: จำนวนใบเสร็จ | J4: จำนวนเงิน | K4: ยกเลิก/ใบเสร็จเสีย | M4: รวมจำนวนใบเสร็จ | N4: รวมจำนวนเงิน | O4: จาก | P4: ถึง | Q4: จำนวนใบเสร็จ | R4: จำนวนเงิน | S4: ยกเลิกใบเสร็จ | U4: รวมจำนวนใบเสร็จ | V4: รวมจำนวนเงิน | W4: รวมจำนวนใบเสร็จ | X4: รวมจำนวนเงิน | AA4: พน0401.1/
E5: จำนวนใบเสร็จ | F5: เลขที่ใบเสร็จ | K5: จำนวนใบเสร็จ | L5: เลขที่ใบเสร็จ | S5: จำนวนใบเสร็จ | T5: เลขที่ใบเสร็จ
A6: 1 ธ.ค. 68 | C6: 327 | D6: 157350 | G6: - | M6: =SUM(C6,I6) -> 327 | N6: =SUM(D6,J6) -> 157350 | O6: - | U6: =SUM(Q6) -> 0 | V6: =SUM(R6) -> 0 | W6: =SUM(M6,Q6) -> 327 | X6: =SUM(N6,R6) -> 157350 | Z6: 1980 | AB6: 1 ธ.ค. 68
A7: 2 ธ.ค. 68 | C7: 118 | D7: 229750 | G7: ศ2569/00034 | H7: ศ2569/00035 | I7: 2 | J7: 1300 | M7: =SUM(C7,I7) -> 120 | N7: =SUM(D7,J7) -> 231050 | O7: - | S7: 2 | T7: ศ69/00008-00009 | U7: =SUM(Q7) -> 0 | V7: =SUM(R7) -> 0 | W7: =SUM(M7,Q7) -> 120 | X7: =SUM(N7,R7) -> 231050 | Z7: 1987 | AB7: 2 ธ.ค. 68
A8: 3 ธ.ค. 68 | C8: 20 | D8: 39750 | G8: - | M8: =SUM(C8,I8) -> 20 | N8: =SUM(D8,J8) -> 39750 | O8: ศ69/00010 | P8: ศ69/00014 | Q8: 5 | R8: 7800 | U8: =SUM(Q8) -> 5 | V8: =SUM(R8) -> 7800 | W8: =SUM(M8,Q8) -> 25 | X8: =SUM(N8,R8) -> 47550 | Z8: 19994 | AB8: 3 ธ.ค. 68
A9: 4 ธ.ค. 68 | C9: 54 | D9: 85200 | G9: ศ2569/00036 | H9: - | I9: 1 | J9: 79680 | M9: =SUM(C9,I9) -> 55 | N9: =SUM(D9,J9) -> 164880 | O9: ศ69/00015 | P9: - | Q9: 1 | R9: 5000 | U9: =SUM(Q9) -> 1 | V9: =SUM(R9) -> 5000 | W9: =SUM(M9,Q9) -> 56 | X9: =SUM(N9,R9) -> 169880 | Z9: 2006 | AB9: 4 ธ.ค. 68
A10: 8 ธ.ค. 68 | C10: 166 | D10: 131620 | G10: - | M10: =SUM(C10,I10) -> 166 | N10: =SUM(D10,J10) -> 131620 | O10: ศ69/00016 | P10: - | Q10: 1 | R10: 3700 | U10: =SUM(Q10) -> 1 | V10: =SUM(R10) -> 3700 | W10: =SUM(M10,Q10) -> 167 | X10: =SUM(N10,R10) -> 135320 | Z10: 2010 | AB10: 8 ธ.ค. 68
A11: 9 ธ.ค. 68 | C11: 264 | D11: 16372520 | G11: - | M11: =SUM(C11,I11) -> 264 | N11: =SUM(D11,J11) -> 16372520 | O11: ศ69/00017 | P11: - | Q11: 1 | R11: 1000 | U11: =SUM(Q11) -> 1 | V11: =SUM(R11) -> 1000 | W11: =SUM(M11,Q11) -> 265 | X11: =SUM(N11,R11) -> 16373520 | Z11: 2018 | AB11: 9 ธ.ค. 68
A12: 11 ธ.ค. 68 | C12: 67 | D12: 3899300 | G12: - | M12: =SUM(C12,I12) -> 67 | N12: =SUM(D12,J12) -> 3899300 | O12: ศ69/00018 | P12: ศ69/00023 | Q12: 6 | R12: 9800 | U12: =SUM(Q12) -> 6 | V12: =SUM(R12) -> 9800 | W12: =SUM(M12,Q12) -> 73 | X12: =SUM(N12,R12) -> 3909100 | Z12: 2020 | AB12: 11 ธ.ค. 68
A13: 12 ธ.ค. 68 | C13: 13 | D13: 33700 | G13: ศ2569/00037 | H13: ศ2569/00038 | I13: 2 | J13: 1200 | M13: =SUM(C13,I13) -> 15 | N13: =SUM(D13,J13) -> 34900 | O13: ศ69/00024 | P13: ศ69/00025 | Q13: 2 | R13: 9700 | U13: =SUM(Q13) -> 2 | V13: =SUM(R13) -> 9700 | W13: =SUM(M13,Q13) -> 17 | X13: =SUM(N13,R13) -> 44600 | Z13: 2030 | AB13: 12 ธ.ค. 68
A14: 15 ธ.ค. 68 | C14: 36 | D14: 24900 | G14: - | M14: =SUM(C14,I14) -> 36 | N14: =SUM(D14,J14) -> 24900 | O14: ศ69/00026 | P14: ศ69/00028 | Q14: 3 | R14: 7900 | U14: =SUM(Q14) -> 3 | V14: =SUM(R14) -> 7900 | W14: =SUM(M14,Q14) -> 39 | X14: =SUM(N14,R14) -> 32800 | Z14: 2037 | AA14: 2038 | AB14: 15 ธ.ค. 68
A15: 16 ธ.ค. 68 | C15: 18 | D15: 3570040 | G15: ศ2569/00039 | H15: - | I15: 1 | J15: 200 | M15: =SUM(C15,I15) -> 19 | N15: =SUM(D15,J15) -> 3570240 | O15: - | U15: =SUM(Q15) -> 0 | V15: =SUM(R15) -> 0 | W15: =SUM(M15,Q15) -> 19 | X15: =SUM(N15,R15) -> 3570240 | Z15: 2051 | AB15: 16 ธ.ค. 68
A16: 17 ธ.ค. 68 | C16: 52 | D16: 232890 | G16: - | M16: =SUM(C16,I16) -> 52 | N16: =SUM(D16,J16) -> 232890 | O16: ศ69/00029 | P16: ศ69/00033 | Q16: 5 | R16: 22300 | U16: =SUM(Q16) -> 5 | V16: =SUM(R16) -> 22300 | W16: =SUM(M16,Q16) -> 57 | X16: =SUM(N16,R16) -> 255190 | Z16: 2059 | AB16: 17 ธ.ค. 68
A17: 18 ธ.ค. 68 | C17: 28 | D17: 2974600 | G17: - | M17: =SUM(C17,I17) -> 28 | N17: =SUM(D17,J17) -> 2974600 | O17: ศ69/00034 | P17: - | Q17: 1 | R17: 4000 | U17: =SUM(Q17) -> 1 | V17: =SUM(R17) -> 4000 | W17: =SUM(M17,Q17) -> 29 | X17: =SUM(N17,R17) -> 2978600 | Z17: 2064 | AA17: 2065 | AB17: 18 ธ.ค. 68
A18: 19 ธ.ค. 68 | C18: 64 | D18: 1867320 | G18: ศ2569/00040 | H18: - | I18: 1 | J18: 79880 | M18: =SUM(C18,I18) -> 65 | N18: =SUM(D18,J18) -> 1947200 | O18: ศ69/00035 | P18: ศ69/00037 | Q18: 3 | R18: 39600 | U18: =SUM(Q18) -> 3 | V18: =SUM(R18) -> 39600 | W18: =SUM(M18,Q18) -> 68 | X18: =SUM(N18,R18) -> 1986800 | Z18: 2074 | AA18: 2075 | AB18: 19 ธ.ค. 68
A19: 22 ธ.ค. 68 | C19: 47 | D19: 5795780 | G19: ศ2569/00041 | H19: - | I19: 1 | J19: 800 | M19: =SUM(C19,I19) -> 48 | N19: =SUM(D19,J19) -> 5796580 | O19: - | U19: =SUM(Q19) -> 0 | V19: =SUM(R19) -> 0 | W19: =SUM(M19,Q19) -> 48 | X19: =SUM(N19,R19) -> 5796580 | Z19: 2080 | AB19: 22 ธ.ค. 68
A20: 23 ธ.ค. 68 | C20: 255 | D20: 15347660 | G20: - | M20: =SUM(C20,I20) -> 255 | N20: =SUM(D20,J20) -> 15347660 | O20: ศ69/00038 | P20: ศ69/00041 | Q20: 4 | R20: 14900 | U20: =SUM(Q20) -> 4 | V20: =SUM(R20) -> 14900 | W20: =SUM(M20,Q20) -> 259 | X20: =SUM(N20,R20) -> 15362560 | Z20: 2090 | AA20: 2091 | AB20: 23 ธ.ค. 68
A21: 24 ธ.ค. 68 | C21: 49 | D21: 7061840 | G21: ศ2569/00042 | H21: - | I21: 1 | J21: 200 | M21: =SUM(C21,I21) -> 50 | N21: =SUM(D21,J21) -> 7062040 | O21: ศ69/00042 | P21: - | Q21: 1 | R21: 3800 | U21: =SUM(Q21) -> 1 | V21: =SUM(R21) -> 3800 | W21: =SUM(M21,Q21) -> 51 | X21: =SUM(N21,R21) -> 7065840 | Z21: 2098 | AA21: 2099 | AB21: 24 ธ.ค. 68
A22: 25 ธ.ค. 68 | C22: 294 | D22: 588560 | G22: - | M22: =SUM(C22,I22) -> 294 | N22: =SUM(D22,J22) -> 588560 | O22: ศ69/00043 | P22: - | Q22: 1 | R22: 5000 | U22: =SUM(Q22) -> 1 | V22: =SUM(R22) -> 5000 | W22: =SUM(M22,Q22) -> 295 | X22: =SUM(N22,R22) -> 593560 | Z22: 2105 | AB22: 25 ธ.ค. 68
A23: 26 ธ.ค. 68 | C23: 368 | D23: 749220 | G23: ศ2569/00043 | H23: ศ2569/00050 | I23: 8 | J23: 4000 | M23: =SUM(C23,I23) -> 376 | N23: =SUM(D23,J23) -> 753220 | O23: - | U23: =SUM(Q23) -> 0 | V23: =SUM(R23) -> 0 | W23: =SUM(M23,Q23) -> 376 | X23: =SUM(N23,R23) -> 753220 | Z23: 2113 | AB23: 26 ธ.ค. 68
A24: 29 ธ.ค. 68 | C24: 36 | D24: 89660 | G24: ศ2569/00051 | H24: ศ2569/00061 | I24: 11 | J24: 11100 | K24: 1 | L24: ศ2569/00062 | M24: =SUM(C24,I24) -> 47 | N24: =SUM(D24,J24) -> 100760 | O24: - | W24: =SUM(M24,Q24) -> 47 | X24: =SUM(N24,R24) -> 100760 | Z24: 2122 | AB24: 29 ธ.ค. 68
A25: 30 ธ.ค. 68 | C25: - | G25: - | M25: =SUM(C25,I25) -> 0 | N25: =SUM(D25,J25) -> 0 | O25: - | U25: =SUM(Q25) -> 0 | V25: =SUM(R25) -> 0 | W25: =SUM(M25,Q25) -> 0 | X25: =SUM(N25,R25) -> 0 | Z25: 2133 | AB25: 30 ธ.ค. 68
A26: รวม | C26: =SUM(C6:C25) -> 2276 | D26: =SUM(D6:D25) -> 59251660 | E26: =SUM(E6:E23) -> 0 | F26: =SUM(F6:F23) -> 0 | G26: รวม | I26: =SUM(I6:I25) -> 28 | J26: =SUM(J6:J25) -> 178360 | K26: =SUM(K6:K23) -> 0 | L26: =SUM(L6:L23) -> 0 | M26: =SUM(M6:M23) -> 2257 | N26: =SUM(N6:N23) -> 59329260 | O26: รวม | Q26: =SUM(Q6:Q25) -> 34 | R26: =SUM(R6:R25) -> 134500 | S26: =SUM(S6:S23) -> 2 | T26: =SUM(T6:T23) -> 0 | U26: =SUM(U6:U23) -> 34 | V26: =SUM(V6:V23) -> 134500 | W26: =SUM(W6:W25) -> 2338 | X26: =SUM(X6:X25) -> 59564520
H29: 29/12/68 | I29: 1 | J29: ศ2569/00062 | K29: ยกเลิกนำเข้าผิดช่องทาง

Sheet ม.ค.69
A1: รายงานการรับชำระค่าธรรมเนียมผ่านธนาคาร เดือน มกราคม 2569
A3: วันที่ชำระ | B3: ข้อมูลกฎหมาย | C3: ระบบ Safety | G3: ระบบ Receipt (ใบเสร็จรับเงิน A4) | M3: รวมพรบ.42 (Safety + Receipt) | O3: ระบบ Trade | U3: รวมพรบ.2543 (Trade) | W3: นำรายได้ ส่ง คพ. พรบ.42 + พรบ.43 | Y3: หมายเหตุ | Z3: พน0401.1/ | AA3: EDC | AB3: วันที่ส่ง
B4: กฎหมาย | C4: จำนวนใบเสร็จ | D4: จำนวนเงิน | E4: ยกเลิกใบเสร็จ | G4: จาก | H4: ถึง | I4: จำนวนใบเสร็จ | J4: จำนวนเงิน | K4: ยกเลิก/ใบเสร็จเสีย | M4: รวมจำนวนใบเสร็จ | N4: รวมจำนวนเงิน | O4: จาก | P4: ถึง | Q4: จำนวนใบเสร็จ | R4: จำนวนเงิน | S4: ยกเลิกใบเสร็จ | U4: รวมจำนวนใบเสร็จ | V4: รวมจำนวนเงิน | W4: รวมจำนวนใบเสร็จ | X4: รวมจำนวนเงิน | AA4: พน0401.1/
E5: จำนวนใบเสร็จ | F5: เลขที่ใบเสร็จ | K5: จำนวนใบเสร็จ | L5: เลขที่ใบเสร็จ | S5: จำนวนใบเสร็จ | T5: เลขที่ใบเสร็จ
A6: 5 ม.ค. 69 | C6: - | M6: =SUM(C6,I6) -> 0 | N6: =SUM(D6,J6) -> 0 | U6: =SUM(Q6) -> 0 | V6: =SUM(R6) -> 0 | W6: =SUM(M6,Q6) -> 0 | X6: =SUM(N6,R6) -> 0 | AB6: 5 ม.ค. 69
A7: 6 ม.ค. 69 | C7: 1 | D7: 2600 | G7: - | H7: - | M7: =SUM(C7,I7) -> 1 | N7: =SUM(D7,J7) -> 2600 | O7: ศ69/00044 | P7: - | Q7: 1 | R7: 5000 | U7: =SUM(Q7) -> 1 | V7: =SUM(R7) -> 5000 | W7: =SUM(M7,Q7) -> 2 | X7: =SUM(N7,R7) -> 7600 | Z7: 11 | AA7: - | AB7: 6 ม.ค. 69
A8: 7 ม.ค. 69 | C8: - | G8: - | M8: =SUM(C8,I8) -> 0 | N8: =SUM(D8,J8) -> 0 | O8: ศ69/00045 | P8: ศ69/00047 | Q8: 3 | R8: 11000 | U8: =SUM(Q8) -> 3 | V8: =SUM(R8) -> 11000 | W8: =SUM(M8,Q8) -> 3 | X8: =SUM(N8,R8) -> 11000 | Z8: 16 | AA8: - | AB8: 7 ม.ค. 69
A9: 8 ม.ค. 69 | C9: - | G9: ศ2569/00063 | H9: - | I9: 1 | J9: 500 | M9: =SUM(C9,I9) -> 1 | N9: =SUM(D9,J9) -> 500 | O9: - | U9: =SUM(Q9) -> 0 | V9: =SUM(R9) -> 0 | W9: =SUM(M9,Q9) -> 1 | X9: =SUM(N9,R9) -> 500 | Z9: 23 | AA9: - | AB9: 8 ม.ค. 69
A10: 9 ม.ค. 69 | C10: - | G10: - | M10: =SUM(C10,I10) -> 0 | N10: =SUM(D10,J10) -> 0 | O10: ศ69/00048 | P10: ศ69/00059 | Q10: 12 | R10: 67400 | U10: =SUM(Q10) -> 12 | V10: =SUM(R10) -> 67400 | W10: =SUM(M10,Q10) -> 12 | X10: =SUM(N10,R10) -> 67400 | Z10: 29 | AA10: 30 | AB10: 9 ม.ค. 69
A11: 12 ม.ค. 69 | C11: 1 | D11: 1000 | G11: - | M11: =SUM(C11,I11) -> 1 | N11: =SUM(D11,J11) -> 1000 | O11: ศ69/00060 | P11: ศ69/00061 | Q11: 2 | R11: 32100 | U11: =SUM(Q11) -> 2 | V11: =SUM(R11) -> 32100 | W11: =SUM(M11,Q11) -> 3 | X11: =SUM(N11,R11) -> 33100 | Z11: 40 | AA11: 41 | AB11: 12 ม.ค. 69
A12: 13 ม.ค. 69 | C12: 2 | D12: 1000 | G12: ศ2569/00064 | H12: - | I12: 1 | J12: 200 | M12: =SUM(C12,I12) -> 3 | N12: =SUM(D12,J12) -> 1200 | O12: ศ69/0062 | P12: ศ69/00066 | Q12: 5 | R12: 105300 | U12: =SUM(Q12) -> 5 | V12: =SUM(R12) -> 105300 | W12: =SUM(M12,Q12) -> 8 | X12: =SUM(N12,R12) -> 106500 | Z12: 47 | AA12: - | AB12: 13 ม.ค. 69
A13: 14 ม.ค. 69 | C13: 5 | D13: 83280 | G13: ศ2569/00065 | H13: - | I13: 1 | J13: 200 | M13: =SUM(C13,I13) -> 6 | N13: =SUM(D13,J13) -> 83480 | O13: ศ69/00067 | P13: ศ69/00068 | Q13: 2 | R13: 190000 | U13: =SUM(Q13) -> 2 | V13: =SUM(R13) -> 190000 | W13: =SUM(M13,Q13) -> 8 | X13: =SUM(N13,R13) -> 273480 | Z13: 52 | AA13: 53 | AB13: 14 ม.ค. 69
A14: 15 ม.ค. 69 | C14: - | G14: ศ2569/00066 | H14: ศ2569/00067 | I14: 2 | J14: 3960 | M14: =SUM(C14,I14) -> 2 | N14: =SUM(D14,J14) -> 3960 | O14: ศ69/00069 | P14: ศ69/00070 | Q14: 2 | R14: 130000 | U14: =SUM(Q14) -> 2 | V14: =SUM(R14) -> 130000 | W14: =SUM(M14,Q14) -> 4 | X14: =SUM(N14,R14) -> 133960 | Z14: 60 | AA14: - | AB14: 15 ม.ค. 69
A15: 16 ม.ค. 69 | C15: 2 | D15: 134160 | G15: ศ2569/00068 | H15: - | I15: 1 | J15: 2600 | M15: =SUM(C15,I15) -> 3 | N15: =SUM(D15,J15) -> 136760 | O15: ศ69/00071 | P15: ศ69/00077 | Q15: 7 | R15: 222300 | U15: =SUM(Q15) -> 7 | V15: =SUM(R15) -> 222300 | W15: =SUM(M15,Q15) -> 10 | X15: =SUM(N15,R15) -> 359060 | Z15: 70 | AA15: 71 | AB15: 16 ม.ค. 69
A16: 19 ม.ค. 69 | C16: 5 | D16: 146840 | G16: - | H16: - | I16: - | J16: - | M16: =SUM(C16,I16) -> 5 | N16: =SUM(D16,J16) -> 146840 | O16: ศ69/00078 | P16: ศ69/00338 | Q16: 261 | R16: 669400 | U16: =SUM(Q16) -> 261 | V16: =SUM(R16) -> 669400 | W16: =SUM(M16,Q16) -> 266 | X16: =SUM(N16,R16) -> 816240 | Z16: 76 | AA16: - | AB16: 19 ม.ค. 69
A17: 20 ม.ค. 69 | C17: 31 | D17: 20500 | G17: ศ2569/00069 | H17: ศ2569/00070 | I17: 2 | J17: 2300 | M17: =SUM(C17,I17) -> 33 | N17: =SUM(D17,J17) -> 22800 | O17: ศ69/00339 | P17: ศ69/00536 | Q17: 198 | R17: 392900 | U17: =SUM(Q17) -> 198 | V17: =SUM(R17) -> 392900 | W17: =SUM(M17,Q17) -> 231 | X17: =SUM(N17,R17) -> 415700 | Z17: 84 | AA17: 85 | AB17: 20 ม.ค. 69
A18: 21 ม.ค. 69 | C18: 1 | D18: 800 | G18: ศ2569/00071 | H18: - | I18: 1 | J18: 1800 | M18: =SUM(C18,I18) -> 2 | N18: =SUM(D18,J18) -> 2600 | O18: ศ69/00537 | P18: ศ69/00930 | Q18: 394 | R18: 937300 | U18: =SUM(Q18) -> 394 | V18: =SUM(R18) -> 937300 | W18: =SUM(M18,Q18) -> 396 | X18: =SUM(N18,R18) -> 939900 | Z18: 89 | AA18: 90 | AB18: 21 ม.ค. 69
A19: 22 ม.ค. 69 | C19: 1 | D19: 800 | G19: ศ2569/00072 | H19: - | I19: 1 | J19: 2100 | M19: =SUM(C19,I19) -> 2 | N19: =SUM(D19,J19) -> 2900 | O19: ศ69/00931 | P19: ศ69/01298 | Q19: 368 | R19: 664800 | U19: =SUM(Q19) -> 368 | V19: =SUM(R19) -> 664800 | W19: =SUM(M19,Q19) -> 370 | X19: =SUM(N19,R19) -> 667700 | Z19: 99 | AB19: 22 ม.ค. 69
A20: 23 ม.ค. 69 | C20: 18 | D20: 124580 | G20: ศ2569/00073 | H20: - | I20: 1 | J20: 3400 | M20: =SUM(C20,I20) -> 19 | N20: =SUM(D20,J20) -> 127980 | O20: ศ69/01299 | P20: ศ69/01703 | Q20: 405 | R20: 938300 | U20: =SUM(Q20) -> 405 | V20: =SUM(R20) -> 938300 | W20: =SUM(M20,Q20) -> 424 | X20: =SUM(N20,R20) -> 1066280 | Z20: 106 | AA20: 107 | AB20: 23 ม.ค. 69
A21: 26 ม.ค. 69 | C21: 2 | D21: 583520 | G21: - | M21: =SUM(C21,I21) -> 2 | N21: =SUM(D21,J21) -> 583520 | O21: ศ69/01704 | P21: ศ69/01706 | Q21: 3 | R21: 194900 | U21: =SUM(Q21) -> 3 | V21: =SUM(R21) -> 194900 | W21: =SUM(M21,Q21) -> 5 | X21: =SUM(N21,R21) -> 778420 | Z21: 114 | AA21: 115 | AB21: 26 ม.ค. 69
A22: 27 ม.ค. 69 | C22: 2 | D22: 231360 | G22: - | M22: =SUM(C22,I22) -> 2 | N22: =SUM(D22,J22) -> 231360 | O22: ศ69/01707 | P22: ศ69/01714 | Q22: 8 | R22: 399600 | U22: =SUM(Q22) -> 8 | V22: =SUM(R22) -> 399600 | W22: =SUM(M22,Q22) -> 10 | X22: =SUM(N22,R22) -> 630960 | Z22: 126 | AB22: 27 ม.ค. 69
A23: 28 ม.ค. 69 | C23: - | G23: ศ2569/00074 | H23: - | I23: 1 | J23: 500 | M23: =SUM(C23,I23) -> 1 | N23: =SUM(D23,J23) -> 500 | O23: ศ69/01715 | P23: ศ69/01716 | Q23: 2 | R23: 34800 | U23: =SUM(Q23) -> 2 | V23: =SUM(R23) -> 34800 | W23: =SUM(M23,Q23) -> 3 | X23: =SUM(N23,R23) -> 35300 | Z23: 129 | AA23: 130 | AB23: 28 ม.ค. 69
A24: 29 ม.ค. 69 | C24: 13 | D24: 22400 | G24: - | M24: =SUM(C24,I24) -> 13 | N24: =SUM(D24,J24) -> 22400 | O24: ศ69/01717 | P24: - | Q24: 1 | R24: 5000 | W24: =SUM(M24,Q24) -> 14 | X24: =SUM(N24,R24) -> 27400 | Z24: 136 | AB24: 29 ม.ค. 69
A25: 30 ม.ค. 69 | C25: 2 | D25: 2260 | G25: ศ2569/00075 | H25: - | I25: 1 | J25: 500 | M25: =SUM(C25,I25) -> 3 | N25: =SUM(D25,J25) -> 2760 | O25: ศ69/01718 | P25: ศ69/01732 | Q25: 15 | R25: 166400 | W25: =SUM(M25,Q25) -> 18 | X25: =SUM(N25,R25) -> 169160 | Z25: 147 | AA25: 148 | AB25: 30 ม.ค. 69
A26: รวม | C26: =SUM(C6:C25) -> 86 | D26: =SUM(D6:D25) -> 1355100 | E26: =SUM(E6:E23) -> 0 | F26: =SUM(F6:F23) -> 0 | G26: รวม | I26: =SUM(I6:I25) -> 13 | J26: =SUM(J6:J25) -> 18060 | K26: =SUM(K6:K23) -> 0 | M26: =SUM(M6:M23) -> 83 | N26: =SUM(N6:N23) -> 1348000 | O26: รวม | Q26: =SUM(Q6:Q25) -> 1689 | R26: =SUM(R6:R25) -> 5166500 | S26: =SUM(S6:S23) -> 0 | T26: =SUM(T6:T23) -> 0 | U26: =SUM(U6:U23) -> 1673 | V26: =SUM(V6:V23) -> 4995100 | W26: =SUM(W6:W25) -> 1788 | X26: =SUM(X6:X25) -> 6539660

Sheet ก.พ.69
A1: รายงานการรับชำระค่าธรรมเนียมผ่านธนาคาร เดือน กุมภาพันธ์ 2569
A3: วันที่ชำระ | B3: ข้อมูลกฎหมาย | C3: ระบบ Safety | G3: ระบบ Receipt (ใบเสร็จรับเงิน A4) | M3: รวมพรบ.42 (Safety + Receipt) | O3: ระบบ Trade | U3: รวมพรบ.2543 (Trade) | W3: นำรายได้ ส่ง คพ. พรบ.42 + พรบ.43 | Y3: หมายเหตุ | Z3: พน0401.1/ | AA3: EDC | AB3: วันที่ส่ง
B4: กฎหมาย | C4: จำนวนใบเสร็จ | D4: จำนวนเงิน | E4: ยกเลิกใบเสร็จ | G4: จาก | H4: ถึง | I4: จำนวนใบเสร็จ | J4: จำนวนเงิน | K4: ยกเลิก/ใบเสร็จเสีย | M4: รวมจำนวนใบเสร็จ | N4: รวมจำนวนเงิน | O4: จาก | P4: ถึง | Q4: จำนวนใบเสร็จ | R4: จำนวนเงิน | S4: ยกเลิกใบเสร็จ | U4: รวมจำนวนใบเสร็จ | V4: รวมจำนวนเงิน | W4: รวมจำนวนใบเสร็จ | X4: รวมจำนวนเงิน | AA4: พน0401.1/
E5: จำนวนใบเสร็จ | F5: เลขที่ใบเสร็จ | K5: จำนวนใบเสร็จ | L5: เลขที่ใบเสร็จ | S5: จำนวนใบเสร็จ | T5: เลขที่ใบเสร็จ
A6: 2 ก.พ. 69 | C6: 1 | D6: 71320 | G6: - | M6: =SUM(C6,I6) -> 1 | N6: =SUM(D6,J6) -> 71320 | O6: ศ69/01733 | P6: ศ69/01735 | Q6: 3 | R6: 210000 | U6: =SUM(Q6) -> 3 | V6: =SUM(R6) -> 210000 | W6: =SUM(M6,Q6) -> 4 | X6: =SUM(N6,R6) -> 281320 | Z6: 155 | AB6: 2 ก.พ. 69
A7: 3 ก.พ. 69 | C7: 1 | D7: 1675160 | G7: - | M7: =SUM(C7,I7) -> 1 | N7: =SUM(D7,J7) -> 1675160 | O7: ศ69/01736 | P7: ศ69/01739 | Q7: 4 | R7: 310000 | U7: =SUM(Q7) -> 4 | V7: =SUM(R7) -> 310000 | W7: =SUM(M7,Q7) -> 5 | X7: =SUM(N7,R7) -> 1985160 | Z7: 163 | AB7: 3 ก.พ. 69
A8: 4 ก.พ. 69 | C8: 2 | D8: 8646020 | G8: - | M8: =SUM(C8,I8) -> 2 | N8: =SUM(D8,J8) -> 8646020 | O8: ศ69/01740 | P8: ศ69/01741 | Q8: 2 | R8: 7700 | U8: =SUM(Q8) -> 2 | V8: =SUM(R8) -> 7700 | W8: =SUM(M8,Q8) -> 4 | X8: =SUM(N8,R8) -> 8653720 | Z8: 168 | AB8: 4 ก.พ. 69
A9: 5 ก.พ. 69 | C9: 2 | D9: 312820 | G9: - | M9: =SUM(C9,I9) -> 2 | N9: =SUM(D9,J9) -> 312820 | O9: ศ69/01742 | P9: ศ69/01765 | Q9: 24 | R9: 403800 | U9: =SUM(Q9) -> 24 | V9: =SUM(R9) -> 403800 | W9: =SUM(M9,Q9) -> 26 | X9: =SUM(N9,R9) -> 716620 | Z9: 178 | AA9: 179 | AB9: 5 ก.พ. 69
A10: 6 ก.พ. 69 | C10: 3 | D10: 124120 | G10: ศ2569/00076 | H10: - | I10: 1 | J10: 500 | M10: =SUM(C10,I10) -> 4 | N10: =SUM(D10,J10) -> 124620 | O10: ศ69/01766 | P10: ศ69/01782 | Q10: 17 | R10: 375600 | U10: =SUM(Q10) -> 17 | V10: =SUM(R10) -> 375600 | W10: =SUM(M10,Q10) -> 21 | X10: =SUM(N10,R10) -> 500220 | Z10: 184 | AB10: 6 ก.พ. 69
A11: 9 ก.พ. 69 | C11: 1 | D11: 1700 | G11: - | M11: =SUM(C11,I11) -> 1 | N11: =SUM(D11,J11) -> 1700 | O11: ศ69/01783 | P11: - | Q11: 1 | R11: 30000 | U11: =SUM(Q11) -> 1 | V11: =SUM(R11) -> 30000 | W11: =SUM(M11,Q11) -> 2 | X11: =SUM(N11,R11) -> 31700 | Z11: 192 | AB11: 9 ก.พ. 69
A12: 10 ก.พ. 69 | C12: 3 | D12: 12600 | G12: ศ2569/00077 | H12: - | I12: 1 | J12: 1800 | M12: =SUM(C12,I12) -> 4 | N12: =SUM(D12,J12) -> 14400 | O12: ศ69/01784 | P12: ศ69/01790 | Q12: 7 | R12: 252000 | U12: =SUM(Q12) -> 7 | V12: =SUM(R12) -> 252000 | W12: =SUM(M12,Q12) -> 11 | X12: =SUM(N12,R12) -> 266400 | Z12: 203 | AA12: 204 | AB12: 10 ก.พ. 69
A13: 11 ก.พ. 69 | C13: 41 | D13: 73000 | G13: ศ2569/00078 | H13: ศ2569/00080 | I13: 3 | J13: 600 | M13: =SUM(C13,I13) -> 44 | N13: =SUM(D13,J13) -> 73600 | O13: ศ69/01791 | P13: ศ69/01792 | Q13: 2 | R13: 81000 | U13: =SUM(Q13) -> 2 | V13: =SUM(R13) -> 81000 | W13: =SUM(M13,Q13) -> 46 | X13: =SUM(N13,R13) -> 154600 | Z13: 212 | AB13: 11 ก.พ 69
A14: 12 ก.พ. 69 | C14: - | G14: - | M14: =SUM(C14,I14) -> 0 | N14: =SUM(D14,J14) -> 0 | O14: ศ69/01793 | P14: ศ69/01795 | Q14: 3 | R14: 100000 | U14: =SUM(Q14) -> 3 | V14: =SUM(R14) -> 100000 | W14: =SUM(M14,Q14) -> 3 | X14: =SUM(N14,R14) -> 100000 | Z14: 215 | AB14: 12 ก.พ. 69
A15: 13 ก.พ. 69 | C15: 38 | D15: 68800 | G15: - | M15: =SUM(C15,I15) -> 38 | N15: =SUM(D15,J15) -> 68800 | O15: ศ69/01796 | P15: ศ69/01801 | Q15: 6 | R15: 185100 | U15: =SUM(Q15) -> 6 | V15: =SUM(R15) -> 185100 | W15: =SUM(M15,Q15) -> 44 | X15: =SUM(N15,R15) -> 253900 | Z15: 223 | AB15: 13 ก.พ. 69
A16: 16 ก.พ. 69 | C16: 2 | D16: 1000 | G16: ศ2569/00081 | H16: - | I16: 1 | J16: 500 | M16: =SUM(C16,I16) -> 3 | N16: =SUM(D16,J16) -> 1500 | O16: ศ69/01802 | P16: ศ69/01805 | Q16: 4 | R16: 35500 | U16: =SUM(Q16) -> 4 | V16: =SUM(R16) -> 35500 | W16: =SUM(M16,Q16) -> 7 | X16: =SUM(N16,R16) -> 37000 | Z16: 228 | AB16: 16 ก.พ. 69
A17: 17 ก.พ. 69 | C17: 1 | D17: 200 | G17: - | M17: =SUM(C17,I17) -> 1 | N17: =SUM(D17,J17) -> 200 | O17: ศ69/01806 | P17: - | Q17: 1 | R17: 90000 | U17: =SUM(Q17) -> 1 | V17: =SUM(R17) -> 90000 | W17: =SUM(M17,Q17) -> 2 | X17: =SUM(N17,R17) -> 90200 | Z17: 237 | AB17: 17 ก.พ. 69
A18: 18 ก.พ. 69 | C18: 3 | D18: 75800 | G18: ศ2569/00082 | H18: ศ2569/00083 | I18: 2 | J18: 1000 | M18: =SUM(C18,I18) -> 5 | N18: =SUM(D18,J18) -> 76800 | O18: ศ69/01807 | P18: ศ69/01808 | Q18: 2 | R18: 93400 | U18: =SUM(Q18) -> 2 | V18: =SUM(R18) -> 93400 | W18: =SUM(M18,Q18) -> 7 | X18: =SUM(N18,R18) -> 170200 | Z18: 243 | AA18: 244 | AB18: 18 ก.พ. 69
A19: 19 ก.พ. 69 | C19: - | G19: ศ2569/00084 | H19: - | I19: 1 | J19: 500 | M19: =SUM(C19,I19) -> 1 | N19: =SUM(D19,J19) -> 500 | O19: ศ69/01809 | P19: ศ69/01812 | Q19: 4 | R19: 37000 | U19: =SUM(Q19) -> 4 | V19: =SUM(R19) -> 37000 | W19: =SUM(M19,Q19) -> 5 | X19: =SUM(N19,R19) -> 37500 | Z19: 249 | AA19: 250 | AB19: 19 ก.พ. 69
A20: 20 ก.พ. 69 | C20: 6 | D20: 1236830 | G20: - | M20: =SUM(C20,I20) -> 6 | N20: =SUM(D20,J20) -> 1236830 | O20: ศ69/01813 | P20: ศ69/01912 | Q20: 100 | R20: 844500 | U20: =SUM(Q20) -> 100 | V20: =SUM(R20) -> 844500 | W20: =SUM(M20,Q20) -> 106 | X20: =SUM(N20,R20) -> 2081330 | Z20: 260 | AB20: 20 ก.พ. 69
A21: 23 ก.พ. 69 | C21: 1 | D21: 500 | G21: - | M21: =SUM(C21,I21) -> 1 | N21: =SUM(D21,J21) -> 500 | O21: ศ69/01917 | P21: ศ69/02147 | Q21: 231 | R21: 778000 | S21: 4 | T21: ศ69/01913-01916 | U21: =SUM(Q21) -> 231 | V21: =SUM(R21) -> 778000 | W21: =SUM(M21,Q21) -> 232 | X21: =SUM(N21,R21) -> 778500 | Z21: 267 | AB21: 23 ก.พ. 69
A22: 24 ก.พ. 69 | C22: - | G22: ศ2569/00085 | H22: - | I22: 1 | J22: 200 | M22: =SUM(C22,I22) -> 1 | N22: =SUM(D22,J22) -> 200 | O22: ศ69/02148 | P22: ศ69/02214 | Q22: 67 | R22: 234600 | U22: =SUM(Q22) -> 67 | V22: =SUM(R22) -> 234600 | W22: =SUM(M22,Q22) -> 68 | X22: =SUM(N22,R22) -> 234800 | Z22: 274 | AA22: 275 | AB22: 24 ก.พ. 69
A23: 25 ก.พ. 69 | C23: - | G23: - | M23: =SUM(C23,I23) -> 0 | N23: =SUM(D23,J23) -> 0 | O23: ศ69/02215 | P23: ศ69/02461 | Q23: 247 | R23: 590500 | U23: =SUM(Q23) -> 247 | V23: =SUM(R23) -> 590500 | W23: =SUM(M23,Q23) -> 247 | X23: =SUM(N23,R23) -> 590500 | Z23: 284 | AB23: 25 ก.พ. 69
A24: 26 ก.พ. 69 | C24: 333 | D24: 149850 | G24: - | M24: =SUM(C24,I24) -> 333 | N24: =SUM(D24,J24) -> 149850 | O24: ศ69/02462 | P24: ศ69/02466 | Q24: 5 | R24: 101100 | W24: =SUM(M24,Q24) -> 338 | X24: =SUM(N24,R24) -> 250950 | Z24: 288 | AB24: 26 ก.พ. 69
A25: 27 ก.พ. 69 | C25: 1 | D25: 540420 | G25: ศ2569/00086 | H25: ศ2569/00087 | I25: 2 | J25: 900 | M25: =SUM(C25,I25) -> 3 | N25: =SUM(D25,J25) -> 541320 | O25: ศ69/02467 | P25: ศ69/02469 | Q25: 3 | R25: 12100 | W25: =SUM(M25,Q25) -> 6 | X25: =SUM(N25,R25) -> 553420 | Z25: 295 | AA25: 296 | AB25: 27 ก.พ. 69
A26: 30 มี.ค. 69 | M26: =SUM(C26,I26) -> 0 | N26: =SUM(D26,J26) -> 0 | W26: =SUM(M26,Q26) -> 0 | X26: =SUM(N26,R26) -> 0
A27: รวม | C27: =SUM(C6:C26) -> 439 | D27: =SUM(D6:D26) -> 12990140 | E27: =SUM(E6:E23) -> 0 | F27: =SUM(F6:F23) -> 0 | G27: รวม | I27: =SUM(I6:I26) -> 12 | J27: =SUM(J6:J26) -> 6000 | K27: =SUM(K6:K23) -> 0 | M27: =SUM(M6:M23) -> 115 | N27: =SUM(N6:N23) -> 12304970 | O27: รวม | Q27: =SUM(Q6:Q26) -> 733 | R27: =SUM(R6:R26) -> 4771900 | S27: =SUM(S6:S23) -> 4 | T27: =SUM(T6:T23) -> 0 | U27: =SUM(U6:U23) -> 725 | V27: =SUM(V6:V23) -> 4658700 | W27: =SUM(W6:W26) -> 1184 | X27: =SUM(X6:X26) -> 17768040

Sheet มี.ค.69
A1: รายงานการรับชำระค่าธรรมเนียมผ่านธนาคาร เดือน มีนาคม 2569
A3: วันที่ชำระ | B3: ข้อมูลกฎหมาย | C3: ระบบ Safety | G3: ระบบ Receipt (ใบเสร็จรับเงิน A4) | M3: รวมพรบ.42 (Safety + Receipt) | O3: ระบบ Trade | U3: รวมพรบ.2543 (Trade) | W3: นำรายได้ ส่ง คพ. พรบ.42 + พรบ.43 | Y3: หมายเหตุ | Z3: พน0401.1/ | AA3: EDC | AB3: วันที่ส่ง
B4: กฎหมาย | C4: จำนวนใบเสร็จ | D4: จำนวนเงิน | E4: ยกเลิกใบเสร็จ | G4: จาก | H4: ถึง | I4: จำนวนใบเสร็จ | J4: จำนวนเงิน | K4: ยกเลิก/ใบเสร็จเสีย | M4: รวมจำนวนใบเสร็จ | N4: รวมจำนวนเงิน | O4: จาก | P4: ถึง | Q4: จำนวนใบเสร็จ | R4: จำนวนเงิน | S4: ยกเลิกใบเสร็จ | U4: รวมจำนวนใบเสร็จ | V4: รวมจำนวนเงิน | W4: รวมจำนวนใบเสร็จ | X4: รวมจำนวนเงิน | AA4: พน0401.1/
E5: จำนวนใบเสร็จ | F5: เลขที่ใบเสร็จ | K5: จำนวนใบเสร็จ | L5: เลขที่ใบเสร็จ | S5: จำนวนใบเสร็จ | T5: เลขที่ใบเสร็จ
A6: 2 มี.ค. 69 | C6: - | G6: - | M6: =SUM(C6,I6) -> 0 | N6: =SUM(D6,J6) -> 0 | O6: - | U6: =SUM(Q6) -> 0 | V6: =SUM(R6) -> 0 | W6: =SUM(M6,Q6) -> 0 | X6: =SUM(N6,R6) -> 0 | Z6: 302 | AB6: 2 มี.ค. 69
A7: 4 มี.ค. 69 | C7: 2 | D7: 1000 | G7: ศ2569/00088 | H7: - | I7: 1 | J7: 500 | M7: =SUM(C7,I7) -> 3 | N7: =SUM(D7,J7) -> 1500 | O7: ศ69/02470 | P7: ศ69/02471 | Q7: 2 | R7: 10038.7 | U7: =SUM(Q7) -> 2 | V7: =SUM(R7) -> 10038.7 | W7: =SUM(M7,Q7) -> 5 | X7: =SUM(N7,R7) -> 11538.7 | Z7: 307 | AA7: 308 | AB7: 4 มี.ค. 69
A8: 5 มี.ค. 69 | C8: 4 | D8: 2000 | G8: - | M8: =SUM(C8,I8) -> 4 | N8: =SUM(D8,J8) -> 2000 | O8: - | U8: =SUM(Q8) -> 0 | V8: =SUM(R8) -> 0 | W8: =SUM(M8,Q8) -> 4 | X8: =SUM(N8,R8) -> 2000 | Z8: 317 | AB8: 5 มี.ค. 69
A9: 6 มี.ค. 69 | C9: 20 | D9: 9000 | G9: ศ2569/00089 | H9: - | I9: 1 | J9: 200 | M9: =SUM(C9,I9) -> 21 | N9: =SUM(D9,J9) -> 9200 | O9: - | U9: =SUM(Q9) -> 0 | V9: =SUM(R9) -> 0 | W9: =SUM(M9,Q9) -> 21 | X9: =SUM(N9,R9) -> 9200 | Z9: 323 | AB9: 6 มี.ค. 69
A10: 9 มี.ค. 69 | C10: - | G10: - | M10: =SUM(C10,I10) -> 0 | N10: =SUM(D10,J10) -> 0 | O10: - | U10: =SUM(Q10) -> 0 | V10: =SUM(R10) -> 0 | W10: =SUM(M10,Q10) -> 0 | X10: =SUM(N10,R10) -> 0 | Z10: 329 | AB10: 9 มี.ค. 69
A11: 10 มี.ค. 69 | C11: 1 | D11: 1800 | G11: ศ2569/00090 | H11: - | I11: 1 | J11: 500 | M11: =SUM(C11,I11) -> 2 | N11: =SUM(D11,J11) -> 2300 | O11: - | U11: =SUM(Q11) -> 0 | V11: =SUM(R11) -> 0 | W11: =SUM(M11,Q11) -> 2 | X11: =SUM(N11,R11) -> 2300 | Z11: 339 | AB11: 10 มี.ค. 69
A12: 11 มี.ค. 69 | C12: - | G12: - | M12: =SUM(C12,I12) -> 0 | N12: =SUM(D12,J12) -> 0 | O12: - | U12: =SUM(Q12) -> 0 | V12: =SUM(R12) -> 0 | W12: =SUM(M12,Q12) -> 0 | X12: =SUM(N12,R12) -> 0 | Z12: 343 | AB12: 11 มี.ค. 69
A13: 12 มี.ค. 69 | C13: - | G13: - | M13: =SUM(C13,I13) -> 0 | N13: =SUM(D13,J13) -> 0 | O13: - | U13: =SUM(Q13) -> 0 | V13: =SUM(R13) -> 0 | W13: =SUM(M13,Q13) -> 0 | X13: =SUM(N13,R13) -> 0 | Z13: 349 | AB13: 12 มี.ค. 69
A14: 13 มี.ค. 69 | C14: 1 | D14: 8920 | G14: - | M14: =SUM(C14,I14) -> 1 | N14: =SUM(D14,J14) -> 8920 | O14: - | U14: =SUM(Q14) -> 0 | V14: =SUM(R14) -> 0 | W14: =SUM(M14,Q14) -> 1 | X14: =SUM(N14,R14) -> 8920 | Z14: 354 | AB14: 13 มี.ค. 69
A15: 16 มี.ค. 69 | C15: 2 | D15: 633180 | G15: - | M15: =SUM(C15,I15) -> 2 | N15: =SUM(D15,J15) -> 633180 | O15: - | U15: =SUM(Q15) -> 0 | V15: =SUM(R15) -> 0 | W15: =SUM(M15,Q15) -> 2 | X15: =SUM(N15,R15) -> 633180 | Z15: 360 | AB15: 16 มี.ค. 69
A16: 17 มี.ค. 69 | C16: 5 | D16: 1000 | G16: - | M16: =SUM(C16,I16) -> 5 | N16: =SUM(D16,J16) -> 1000 | O16: - | U16: =SUM(Q16) -> 0 | V16: =SUM(R16) -> 0 | W16: =SUM(M16,Q16) -> 5 | X16: =SUM(N16,R16) -> 1000 | Z16: 369 | AB16: 17 มี.ค. 69
A17: 18 มี.ค. 69 | C17: 1 | D17: 400 | G17: - | M17: =SUM(C17,I17) -> 1 | N17: =SUM(D17,J17) -> 400 | O17: - | U17: =SUM(Q17) -> 0 | V17: =SUM(R17) -> 0 | W17: =SUM(M17,Q17) -> 1 | X17: =SUM(N17,R17) -> 400 | Z17: 376 | AB17: 18 มี.ค. 69
A18: 19 มี.ค. 69 | C18: 2 | D18: 638500 | G18: - | M18: =SUM(C18,I18) -> 2 | N18: =SUM(D18,J18) -> 638500 | O18: - | U18: =SUM(Q18) -> 0 | V18: =SUM(R18) -> 0 | W18: =SUM(M18,Q18) -> 2 | X18: =SUM(N18,R18) -> 638500 | Z18: 382 | AB18: 19 มี.ค. 69
A19: 20 มี.ค. 69 | C19: 2 | D19: 5307300 | G19: - | M19: =SUM(C19,I19) -> 2 | N19: =SUM(D19,J19) -> 5307300 | O19: - | U19: =SUM(Q19) -> 0 | V19: =SUM(R19) -> 0 | W19: =SUM(M19,Q19) -> 2 | X19: =SUM(N19,R19) -> 5307300 | Z19: 390 | AB19: 20 มี.ค. 69
A20: 23 มี.ค. 69 | C20: 2 | D20: 94320 | G20: - | M20: =SUM(C20,I20) -> 2 | N20: =SUM(D20,J20) -> 94320 | O20: - | U20: =SUM(Q20) -> 0 | V20: =SUM(R20) -> 0 | W20: =SUM(M20,Q20) -> 2 | X20: =SUM(N20,R20) -> 94320 | Z20: 397 | AB20: 23 มี.ค. 69
A21: 24 มี.ค. 69 | C21: - | G21: - | M21: =SUM(C21,I21) -> 0 | N21: =SUM(D21,J21) -> 0 | O21: - | U21: =SUM(Q21) -> 0 | V21: =SUM(R21) -> 0 | W21: =SUM(M21,Q21) -> 0 | X21: =SUM(N21,R21) -> 0 | Z21: 401 | AB21: 24 มี.ค. 69
A22: 25 มี.ค. 69 | C22: - | G22: - | M22: =SUM(C22,I22) -> 0 | N22: =SUM(D22,J22) -> 0 | O22: - | U22: =SUM(Q22) -> 0 | V22: =SUM(R22) -> 0 | W22: =SUM(M22,Q22) -> 0 | X22: =SUM(N22,R22) -> 0 | Z22: 408 | AB22: 25 มี.ค. 69
A23: 26 มี.ค. 69 | C23: 7 | D23: 499880 | G23: - | M23: =SUM(C23,I23) -> 7 | N23: =SUM(D23,J23) -> 499880 | O23: - | U23: =SUM(Q23) -> 0 | V23: =SUM(R23) -> 0 | W23: =SUM(M23,Q23) -> 7 | X23: =SUM(N23,R23) -> 499880 | Z23: 415 | AB23: 26 มี.ค. 69
A24: 27 มี.ค. 69 | C24: - | G24: - | M24: =SUM(C24,I24) -> 0 | N24: =SUM(D24,J24) -> 0 | O24: - | W24: =SUM(M24,Q24) -> 0 | X24: =SUM(N24,R24) -> 0 | Z24: 418 | AB24: 27 มี.ค. 69
A25: 30 มี.ค. 69 | C25: 1 | D25: 2200 | G25: - | M25: =SUM(C25,I25) -> 1 | N25: =SUM(D25,J25) -> 2200 | O25: - | W25: =SUM(M25,Q25) -> 1 | X25: =SUM(N25,R25) -> 2200 | Z25: 426 | AB25: 30 มี.ค. 69
A26: 31 มี.ค. 69 | C26: - | G26: - | M26: =SUM(C26,I26) -> 0 | N26: =SUM(D26,J26) -> 0 | O26: - | W26: =SUM(M26,Q26) -> 0 | X26: =SUM(N26,R26) -> 0 | Z26: 432 | AB26: 31 มี.ค. 69
A27: รวม | C27: =SUM(C6:C26) -> 50 | D27: =SUM(D6:D26) -> 7199500 | E27: =SUM(E6:E23) -> 0 | F27: =SUM(F6:F23) -> 0 | G27: รวม | I27: =SUM(I6:I26) -> 3 | J27: =SUM(J6:J26) -> 1200 | K27: =SUM(K6:K23) -> 0 | M27: =SUM(M6:M26) -> 53 | N27: =SUM(N6:N26) -> 7200700 | O27: รวม | Q27: =SUM(Q6:Q26) -> 2 | R27: =SUM(R6:R26) -> 10038.7 | S27: =SUM(S6:S23) -> 0 | T27: =SUM(T6:T23) -> 0 | U27: =SUM(U6:U23) -> 2 | V27: =SUM(V6:V23) -> 10038.7 | W27: =SUM(W6:W26) -> 55 | X27: =SUM(X6:X26) -> 7210738.7

Sheet เม.ย.69
A1: รายงานการรับชำระค่าธรรมเนียมผ่านธนาคาร เดือน เมษายน 2569
A3: วันที่ชำระ | B3: ข้อมูลกฎหมาย | C3: ระบบ Safety | G3: ระบบ Receipt (ใบเสร็จรับเงิน A4) | M3: รวมพรบ.42 (Safety + Receipt) | O3: ระบบ Trade | U3: รวมพรบ.2543 (Trade) | W3: นำรายได้ ส่ง คพ. พรบ.42 + พรบ.43 | Y3: หมายเหตุ | Z3: พน0401.1/ | AA3: EDC | AB3: วันที่ส่ง
B4: กฎหมาย | C4: จำนวนใบเสร็จ | D4: จำนวนเงิน | E4: ยกเลิกใบเสร็จ | G4: จาก | H4: ถึง | I4: จำนวนใบเสร็จ | J4: จำนวนเงิน | K4: ยกเลิก/ใบเสร็จเสีย | M4: รวมจำนวนใบเสร็จ | N4: รวมจำนวนเงิน | O4: จาก | P4: ถึง | Q4: จำนวนใบเสร็จ | R4: จำนวนเงิน | S4: ยกเลิกใบเสร็จ | U4: รวมจำนวนใบเสร็จ | V4: รวมจำนวนเงิน | W4: รวมจำนวนใบเสร็จ | X4: รวมจำนวนเงิน | AA4: พน0401.1/
E5: จำนวนใบเสร็จ | F5: เลขที่ใบเสร็จ | K5: จำนวนใบเสร็จ | L5: เลขที่ใบเสร็จ | S5: จำนวนใบเสร็จ | T5: เลขที่ใบเสร็จ
A6: 1 เม.ย. 69 | C6: 1 | D6: 3200 | G6: - | M6: =SUM(C6,I6) -> 1 | N6: =SUM(D6,J6) -> 3200 | O6: - | U6: =SUM(Q6) -> 0 | V6: =SUM(R6) -> 0 | W6: =SUM(M6,Q6) -> 1 | X6: =SUM(N6,R6) -> 3200 | Z6: 439 | AB6: 1 เม.ย. 69
A7: 2 เม.ย. 69 | C7: - | G7: - | M7: =SUM(C7,I7) -> 0 | N7: =SUM(D7,J7) -> 0 | O7: - | U7: =SUM(Q7) -> 0 | V7: =SUM(R7) -> 0 | W7: =SUM(M7,Q7) -> 0 | X7: =SUM(N7,R7) -> 0 | Z7: 446 | AB7: 2 เม.ย. 69
A8: 3 เม.ย. 69 | C8: - | G8: - | M8: =SUM(C8,I8) -> 0 | N8: =SUM(D8,J8) -> 0 | O8: - | U8: =SUM(Q8) -> 0 | V8: =SUM(R8) -> 0 | W8: =SUM(M8,Q8) -> 0 | X8: =SUM(N8,R8) -> 0 | Z8: 452 | AB8: 3 เม.ย. 69
A9: 7 เม.ย. 69 | C9: - | G9: - | M9: =SUM(C9,I9) -> 0 | N9: =SUM(D9,J9) -> 0 | O9: - | U9: =SUM(Q9) -> 0 | V9: =SUM(R9) -> 0 | W9: =SUM(M9,Q9) -> 0 | X9: =SUM(N9,R9) -> 0 | Z9: 458 | AB9: 7 เม.ย. 69
A10: 8 เม.ย. 69 | C10: 23 | D10: 432520 | G10: - | M10: =SUM(C10,I10) -> 23 | N10: =SUM(D10,J10) -> 432520 | O10: - | U10: =SUM(Q10) -> 0 | V10: =SUM(R10) -> 0 | W10: =SUM(M10,Q10) -> 23 | X10: =SUM(N10,R10) -> 432520 | Z10: 465 | AB10: 8 เม.ย. 69
A11: 9 เม.ย. 69 | C11: 2 | D11: 89000 | G11: - | M11: =SUM(C11,I11) -> 2 | N11: =SUM(D11,J11) -> 89000 | O11: ศ69/02472 | P11: - | Q11: 1 | R11: 1000 | U11: =SUM(Q11) -> 1 | V11: =SUM(R11) -> 1000 | W11: =SUM(M11,Q11) -> 3 | X11: =SUM(N11,R11) -> 90000 | Z11: 470 | AA11: 471 | AB11: 9 เม.ย. 69
A12: 10 เม.ย. 69 | C12: 1 | D12: 2200 | G12: - | M12: =SUM(C12,I12) -> 1 | N12: =SUM(D12,J12) -> 2200 | O12: ศ69/02473 | P12: - | Q12: 1 | R12: 800 | U12: =SUM(Q12) -> 1 | V12: =SUM(R12) -> 800 | W12: =SUM(M12,Q12) -> 2 | X12: =SUM(N12,R12) -> 3000 | Z12: 482 | AA12: 483 | AB12: 10 เม.ย. 69
A13: 16 เม.ย. 69 | C13: - | G13: - | M13: =SUM(C13,I13) -> 0 | N13: =SUM(D13,J13) -> 0 | O13: ศ69/02474 | P13: - | Q13: 1 | R13: 31100 | U13: =SUM(Q13) -> 1 | V13: =SUM(R13) -> 31100 | W13: =SUM(M13,Q13) -> 1 | X13: =SUM(N13,R13) -> 31100 | Z13: 487 | AB13: 16 เม.ย. 69
A14: 17 เม.ย. 69 | C14: 41 | D14: 289840 | G14: - | M14: =SUM(C14,I14) -> 41 | N14: =SUM(D14,J14) -> 289840 | O14: - | U14: =SUM(Q14) -> 0 | V14: =SUM(R14) -> 0 | W14: =SUM(M14,Q14) -> 41 | X14: =SUM(N14,R14) -> 289840 | Z14: 496 | AB14: 17 เม.ย. 69
A15: 20 เม.ย. 69 | C15: 93 | D15: 220740 | G15: - | M15: =SUM(C15,I15) -> 93 | N15: =SUM(D15,J15) -> 220740 | O15: ศ69/02475 | P15: - | Q15: 1 | R15: 1050 | U15: =SUM(Q15) -> 1 | V15: =SUM(R15) -> 1050 | W15: =SUM(M15,Q15) -> 94 | X15: =SUM(N15,R15) -> 221790 | Z15: 502 | AB15: 20 เม.ย. 69
A16: 21 เม.ย. 69 | C16: - | G16: - | M16: =SUM(C16,I16) -> 0 | N16: =SUM(D16,J16) -> 0 | O16: - | U16: =SUM(Q16) -> 0 | V16: =SUM(R16) -> 0 | W16: =SUM(M16,Q16) -> 0 | X16: =SUM(N16,R16) -> 0 | Z16: 507 | AB16: 21 เม.ย. 69
A17: 22 เม.ย. 69 | C17: 7 | D17: 21400 | G17: - | M17: =SUM(C17,I17) -> 7 | N17: =SUM(D17,J17) -> 21400 | O17: - | U17: =SUM(Q17) -> 0 | V17: =SUM(R17) -> 0 | W17: =SUM(M17,Q17) -> 7 | X17: =SUM(N17,R17) -> 21400 | Z17: 513 | AB17: 22 เม.ย. 69
A18: 23 เม.ย. 69 | C18: 4 | D18: 20800 | G18: - | M18: =SUM(C18,I18) -> 4 | N18: =SUM(D18,J18) -> 20800 | O18: ศ69/02476 | P18: - | Q18: 1 | R18: 42390 | U18: =SUM(Q18) -> 1 | V18: =SUM(R18) -> 42390 | W18: =SUM(M18,Q18) -> 5 | X18: =SUM(N18,R18) -> 63190 | Z18: 519 | AA18: 520 | AB18: 23 เม.ย. 69
A19: 24 เม.ย. 69 | C19: 38 | D19: 3847680 | G19: - | M19: =SUM(C19,I19) -> 38 | N19: =SUM(D19,J19) -> 3847680 | O19: ศ69/02477 | P19: - | Q19: 1 | R19: 1370.2 | U19: =SUM(Q19) -> 1 | V19: =SUM(R19) -> 1370.2 | W19: =SUM(M19,Q19) -> 39 | X19: =SUM(N19,R19) -> 3849050.2 | Z19: 526 | AA19: 527 | AB19: 24 เม.ย. 69
A20: 27 เม.ย. 69 | C20: 2 | D20: 4265120 | G20: ศ2569/00091 | H20: - | I20: 1 | J20: 200 | M20: =SUM(C20,I20) -> 3 | N20: =SUM(D20,J20) -> 4265320 | O20: ศ69/02478 | P20: - | Q20: 1 | R20: 1585.5 | U20: =SUM(Q20) -> 1 | V20: =SUM(R20) -> 1585.5 | W20: =SUM(M20,Q20) -> 4 | X20: =SUM(N20,R20) -> 4266905.5 | Z20: 533 | AB20: 27 เม.ย. 69
A21: 28 เม.ย. 69 | C21: 2 | D21: 658740 | G21: - | M21: =SUM(C21,I21) -> 2 | N21: =SUM(D21,J21) -> 658740 | O21: - | U21: =SUM(Q21) -> 0 | V21: =SUM(R21) -> 0 | W21: =SUM(M21,Q21) -> 2 | X21: =SUM(N21,R21) -> 658740 | Z21: 538 | AB21: 28 เม.ย. 69
A22: 29 เม.ย. 69 | C22: - | G22: - | M22: =SUM(C22,I22) -> 0 | N22: =SUM(D22,J22) -> 0 | O22: - | U22: =SUM(Q22) -> 0 | V22: =SUM(R22) -> 0 | W22: =SUM(M22,Q22) -> 0 | X22: =SUM(N22,R22) -> 0 | Z22: 544 | AB22: 29 เม.ย. 69
A23: 30 เม.ย. 69 | C23: 1 | D23: 8200 | G23: ศ2569/00092 | H23: - | I23: 1 | J23: 500 | M23: =SUM(C23,I23) -> 2 | N23: =SUM(D23,J23) -> 8700 | O23: ศ69/02479 | P23: ศ69/02481 | Q23: 3 | R23: 34556 | U23: =SUM(Q23) -> 3 | V23: =SUM(R23) -> 34556 | W23: =SUM(M23,Q23) -> 5 | X23: =SUM(N23,R23) -> 43256 | Z23: 553 | AB23: 30 เม.ย. 69
A24: รวม | C24: =SUM(C6:C23) -> 215 | D24: =SUM(D6:D23) -> 9859440 | E24: =SUM(E6:E23) -> 0 | F24: =SUM(F6:F23) -> 0 | G24: รวม | I24: =SUM(I6:I23) -> 2 | J24: =SUM(J6:J23) -> 700 | K24: =SUM(K6:K23) -> 0 | M24: =SUM(M6:M23) -> 217 | N24: =SUM(N6:N23) -> 9860140 | O24: รวม | Q24: =SUM(Q6:Q23) -> 10 | R24: =SUM(R6:R23) -> 113851.7 | S24: =SUM(S6:S23) -> 0 | T24: =SUM(T6:T23) -> 0 | U24: =SUM(U6:U23) -> 10 | V24: =SUM(V6:V23) -> 113851.7 | W24: =SUM(W6:W23) -> 227 | X24: =SUM(X6:X23) -> 9973991.7

Sheet พ.ค.69
A1: รายงานการรับชำระค่าธรรมเนียมผ่านธนาคาร เดือน พฤษภาคม 2569
A3: วันที่ชำระ | B3: ข้อมูลกฎหมาย | C3: ระบบ Safety | G3: ระบบ Receipt (ใบเสร็จรับเงิน A4) | M3: รวมพรบ.42 (Safety + Receipt) | O3: ระบบ Trade | U3: รวมพรบ.2543 (Trade) | W3: นำรายได้ ส่ง คพ. พรบ.42 + พรบ.43 | Y3: หมายเหตุ | Z3: พน0401.1/ | AA3: EDC | AB3: วันที่ส่ง
B4: กฎหมาย | C4: จำนวนใบเสร็จ | D4: จำนวนเงิน | E4: ยกเลิกใบเสร็จ | G4: จาก | H4: ถึง | I4: จำนวนใบเสร็จ | J4: จำนวนเงิน | K4: ยกเลิก/ใบเสร็จเสีย | M4: รวมจำนวนใบเสร็จ | N4: รวมจำนวนเงิน | O4: จาก | P4: ถึง | Q4: จำนวนใบเสร็จ | R4: จำนวนเงิน | S4: ยกเลิกใบเสร็จ | U4: รวมจำนวนใบเสร็จ | V4: รวมจำนวนเงิน | W4: รวมจำนวนใบเสร็จ | X4: รวมจำนวนเงิน | AA4: พน0401.1/
E5: จำนวนใบเสร็จ | F5: เลขที่ใบเสร็จ | K5: จำนวนใบเสร็จ | L5: เลขที่ใบเสร็จ | S5: จำนวนใบเสร็จ | T5: เลขที่ใบเสร็จ
A6: 1 พ.ค. 69 | C6: - | G6: - | M6: =SUM(C6,I6) -> 0 | N6: =SUM(D6,J6) -> 0 | O6: - | U6: =SUM(Q6) -> 0 | V6: =SUM(R6) -> 0 | W6: =SUM(M6,Q6) -> 0 | X6: =SUM(N6,R6) -> 0 | Z6: 557 | AB6: 1 พ.ค. 69
A7: 5 พ.ค. 69 | C7: 2 | D7: 730400 | G7: - | M7: =SUM(C7,I7) -> 2 | N7: =SUM(D7,J7) -> 730400 | O7: - | U7: =SUM(Q7) -> 0 | V7: =SUM(R7) -> 0 | W7: =SUM(M7,Q7) -> 2 | X7: =SUM(N7,R7) -> 730400 | Z7: 563 | AB7: 5 พ.ค. 69
A8: 6 พ.ค. 69 | C8: 1 | D8: 1529340 | G8: ศ2569/00093 | H8: - | I8: 1 | J8: 500 | M8: =SUM(C8,I8) -> 2 | N8: =SUM(D8,J8) -> 1529840 | O8: - | U8: =SUM(Q8) -> 0 | V8: =SUM(R8) -> 0 | W8: =SUM(M8,Q8) -> 2 | X8: =SUM(N8,R8) -> 1529840 | Z8: 571 | AA8: 572 | AB8: 6 พ.ค. 69
A9: 7 พ.ค. 69 | C9: - | G9: ศ2569/00094 | H9: ศ2569/00095 | I9: 2 | J9: 1000 | M9: =SUM(C9,I9) -> 2 | N9: =SUM(D9,J9) -> 1000 | O9: ศ69/02482 | P9: ศ69/02483 | Q9: 2 | R9: 2346.9 | U9: =SUM(Q9) -> 2 | V9: =SUM(R9) -> 2346.9 | W9: =SUM(M9,Q9) -> 4 | X9: =SUM(N9,R9) -> 3346.9 | Z9: 579 | AA9: 580 | AB9: 7 พ.ค. 69
A10: 8 พ.ค. 69 | C10: 2 | D10: 548360 | G10: ศ2569/00096 | H10: - | I10: 1 | J10: 1200 | M10: =SUM(C10,I10) -> 3 | N10: =SUM(D10,J10) -> 549560 | O10: - | U10: =SUM(Q10) -> 0 | V10: =SUM(R10) -> 0 | W10: =SUM(M10,Q10) -> 3 | X10: =SUM(N10,R10) -> 549560 | Z10: 588 | AA10: 590 | AB10: 8 พ.ค. 69
A11: 11 พ.ค. 69 | C11: 5 | D11: 230000 | G11: - | M11: =SUM(C11,I11) -> 5 | N11: =SUM(D11,J11) -> 230000 | O11: - | U11: =SUM(Q11) -> 0 | V11: =SUM(R11) -> 0 | W11: =SUM(M11,Q11) -> 5 | X11: =SUM(N11,R11) -> 230000 | Z11: 594 | AB11: 11 พ.ค. 69
A12: 12 พ.ค. 69 | C12: - | G12: - | M12: =SUM(C12,I12) -> 0 | N12: =SUM(D12,J12) -> 0 | O12: - | U12: =SUM(Q12) -> 0 | V12: =SUM(R12) -> 0 | W12: =SUM(M12,Q12) -> 0 | X12: =SUM(N12,R12) -> 0 | Z12: 600 | AB12: 12 พ.ค. 69
A13: 14 พ.ค. 69 | C13: - | G13: - | M13: =SUM(C13,I13) -> 0 | N13: =SUM(D13,J13) -> 0 | O13: ศ69/02484 | P13: - | Q13: 1 | R13: 1395.61 | U13: =SUM(Q13) -> 1 | V13: =SUM(R13) -> 1395.61 | W13: =SUM(M13,Q13) -> 1 | X13: =SUM(N13,R13) -> 1395.61 | Z13: 605 | AA13: 606 | AB13: 14 พ.ค. 69
A14: 15 พ.ค. 69 | C14: - | G14: - | M14: =SUM(C14,I14) -> 0 | N14: =SUM(D14,J14) -> 0 | O14: - | U14: =SUM(Q14) -> 0 | V14: =SUM(R14) -> 0 | W14: =SUM(M14,Q14) -> 0 | X14: =SUM(N14,R14) -> 0 | Z14: 616 | AB14: 15 พ.ค. 69
A15: 18 พ.ค. 69 | C15: 1 | D15: 258960 | G15: - | M15: =SUM(C15,I15) -> 1 | N15: =SUM(D15,J15) -> 258960 | O15: - | U15: =SUM(Q15) -> 0 | V15: =SUM(R15) -> 0 | W15: =SUM(M15,Q15) -> 1 | X15: =SUM(N15,R15) -> 258960 | Z15: 620 | AB15: 18 พ.ค. 69
A16: 19 พ.ค. 69 | C16: 1 | D16: 200 | G16: - | M16: =SUM(C16,I16) -> 1 | N16: =SUM(D16,J16) -> 200 | O16: - | U16: =SUM(Q16) -> 0 | V16: =SUM(R16) -> 0 | W16: =SUM(M16,Q16) -> 1 | X16: =SUM(N16,R16) -> 200 | Z16: 626 | AB16: 19 พ.ค. 69
A17: 20 พ.ค. 69 | C17: 1 | D17: 7070220 | G17: ศ2569/00097 | H17: - | I17: 1 | J17: 1800 | M17: =SUM(C17,I17) -> 2 | N17: =SUM(D17,J17) -> 7072020 | O17: - | U17: =SUM(Q17) -> 0 | V17: =SUM(R17) -> 0 | W17: =SUM(M17,Q17) -> 2 | X17: =SUM(N17,R17) -> 7072020 | Z17: 633 | AA17: 634 | AB17: 20 พ.ค. 69
A18: 21 พ.ค. 69 | C18: - | G18: ศ2569/00098 | H18: - | I18: 1 | J18: 500 | M18: =SUM(C18,I18) -> 1 | N18: =SUM(D18,J18) -> 500 | O18: - | U18: =SUM(Q18) -> 0 | V18: =SUM(R18) -> 0 | W18: =SUM(M18,Q18) -> 1 | X18: =SUM(N18,R18) -> 500 | Z18: 640 | AB18: 21 พ.ค. 69
A19: 22 พ.ค. 69 | C19: - | G19: - | M19: =SUM(C19,I19) -> 0 | N19: =SUM(D19,J19) -> 0 | O19: - | U19: =SUM(Q19) -> 0 | V19: =SUM(R19) -> 0 | W19: =SUM(M19,Q19) -> 0 | X19: =SUM(N19,R19) -> 0 | Z19: 643 | AB19: 22 พ.ค. 69
A20: 25 พ.ค. 69 | C20: - | G20: - | M20: =SUM(C20,I20) -> 0 | N20: =SUM(D20,J20) -> 0 | O20: - | U20: =SUM(Q20) -> 0 | V20: =SUM(R20) -> 0 | W20: =SUM(M20,Q20) -> 0 | X20: =SUM(N20,R20) -> 0 | Z20: 652 | AB20: 25 พ.ค. 69
A21: 26 พ.ค. 69 | C21: - | G21: - | M21: =SUM(C21,I21) -> 0 | N21: =SUM(D21,J21) -> 0 | O21: - | W21: =SUM(M21,Q21) -> 0 | X21: =SUM(N21,R21) -> 0 | Z21: 655 | AB21: 26 พ.ค. 69
A22: 27 พ.ค. 69 | C22: - | G22: - | M22: =SUM(C22,I22) -> 0 | N22: =SUM(D22,J22) -> 0 | O22: - | U22: =SUM(Q22) -> 0 | V22: =SUM(R22) -> 0 | W22: =SUM(M22,Q22) -> 0 | X22: =SUM(N22,R22) -> 0 | Z22: 663 | AB22: 27 พ.ค. 69
A23: 28 พ.ค. 69 | C23: - | G23: - | M23: =SUM(C23,I23) -> 0 | N23: =SUM(D23,J23) -> 0 | O23: - | W23: =SUM(M23,Q23) -> 0 | X23: =SUM(N23,R23) -> 0 | Z23: 667 | AB23: 28 พ.ค. 69
A24: 29 พ.ค. 69 | C24: - | G24: - | M24: =SUM(C24,I24) -> 0 | N24: =SUM(D24,J24) -> 0 | O24: - | W24: =SUM(M24,Q24) -> 0 | X24: =SUM(N24,R24) -> 0 | Z24: 672 | AB24: 29 พ.ค. 69
A25: รวม | C25: =SUM(C6:C24) -> 13 | D25: =SUM(D6:D24) -> 10367480 | E25: =SUM(E6:E22) -> 0 | F25: =SUM(F6:F22) -> 0 | G25: รวม | I25: =SUM(I6:I24) -> 6 | J25: =SUM(J6:J24) -> 5000 | K25: =SUM(K6:K22) -> 0 | M25: =SUM(M6:M24) -> 19 | N25: =SUM(N6:N24) -> 10372480 | O25: รวม | Q25: =SUM(Q6:Q24) -> 3 | R25: =SUM(R6:R24) -> 3742.51 | S25: =SUM(S6:S22) -> 0 | T25: =SUM(T6:T22) -> 0 | U25: =SUM(U6:U22) -> 3 | V25: =SUM(V6:V22) -> 3742.51 | W25: =SUM(W6:W24) -> 22 | X25: =SUM(X6:X24) -> 10376223

Sheet มิ.ย.69
A1: รายงานการรับชำระค่าธรรมเนียมผ่านธนาคาร เดือน มิถุนายน 2569
A3: วันที่ชำระ | B3: ข้อมูลกฎหมาย | C3: ระบบ Safety | G3: ระบบ Receipt (ใบเสร็จรับเงิน A4) | M3: รวมพรบ.42 (Safety + Receipt) | O3: ระบบ Trade | U3: รวมพรบ.2543 (Trade) | W3: นำรายได้ ส่ง คพ. พรบ.42 + พรบ.43 | Y3: หมายเหตุ | Z3: พน0401.1/ | AA3: EDC | AB3: วันที่ส่ง
B4: กฎหมาย | C4: จำนวนใบเสร็จ | D4: จำนวนเงิน | E4: ยกเลิกใบเสร็จ | G4: จาก | H4: ถึง | I4: จำนวนใบเสร็จ | J4: จำนวนเงิน | K4: ยกเลิก/ใบเสร็จเสีย | M4: รวมจำนวนใบเสร็จ | N4: รวมจำนวนเงิน | O4: จาก | P4: ถึง | Q4: จำนวนใบเสร็จ | R4: จำนวนเงิน | S4: ยกเลิกใบเสร็จ | U4: รวมจำนวนใบเสร็จ | V4: รวมจำนวนเงิน | W4: รวมจำนวนใบเสร็จ | X4: รวมจำนวนเงิน | AA4: พน0401.1/
E5: จำนวนใบเสร็จ | F5: เลขที่ใบเสร็จ | K5: จำนวนใบเสร็จ | L5: เลขที่ใบเสร็จ | S5: จำนวนใบเสร็จ | T5: เลขที่ใบเสร็จ
A6: 2 มิ.ย. 69 | C6: - | G6: - | M6: =SUM(C6,I6) -> 0 | N6: =SUM(D6,J6) -> 0 | O6: - | U6: =SUM(Q6) -> 0 | V6: =SUM(R6) -> 0 | W6: =SUM(M6,Q6) -> 0 | X6: =SUM(N6,R6) -> 0 | Z6: 679 | AB6: 2 มิ.ย. 69
A7: 4 มิ.ย. 69 | C7: - | G7: - | M7: =SUM(C7,I7) -> 0 | N7: =SUM(D7,J7) -> 0 | O7: - | U7: =SUM(Q7) -> 0 | V7: =SUM(R7) -> 0 | W7: =SUM(M7,Q7) -> 0 | X7: =SUM(N7,R7) -> 0 | Z7: 685 | AB7: 4 มิ.ย. 69
A8: 5 มิ.ย. 69 | C8: 1 | D8: 12612860 | G8: - | M8: =SUM(C8,I8) -> 1 | N8: =SUM(D8,J8) -> 12612860 | O8: - | U8: =SUM(Q8) -> 0 | V8: =SUM(R8) -> 0 | W8: =SUM(M8,Q8) -> 1 | X8: =SUM(N8,R8) -> 12612860 | Z8: 691 | AB8: 5 มิ.ย. 69
A9: 8 มิ.ย. 69 | C9: - | G9: - | M9: =SUM(C9,I9) -> 0 | N9: =SUM(D9,J9) -> 0 | O9: - | U9: =SUM(Q9) -> 0 | V9: =SUM(R9) -> 0 | W9: =SUM(M9,Q9) -> 0 | X9: =SUM(N9,R9) -> 0 | Z9: 698 | AB9: 8 มิ.ย. 69
A10: 9 มิ.ย. 69 | C10: - | G10: - | M10: =SUM(C10,I10) -> 0 | N10: =SUM(D10,J10) -> 0 | O10: - | U10: =SUM(Q10) -> 0 | V10: =SUM(R10) -> 0 | W10: =SUM(M10,Q10) -> 0 | X10: =SUM(N10,R10) -> 0 | Z10: 704 | AB10: 9 มิ.ย. 69
A11: 10 มิ.ย. 69 | C11: - | G11: - | M11: =SUM(C11,I11) -> 0 | N11: =SUM(D11,J11) -> 0 | O11: - | U11: =SUM(Q11) -> 0 | V11: =SUM(R11) -> 0 | W11: =SUM(M11,Q11) -> 0 | X11: =SUM(N11,R11) -> 0 | Z11: 711 | AB11: 10 มิ.ย. 69
